Workbook
Name COD: [0]!COD
Name COD: #N/A
Name COD: Main!$J$14
Name COD: Main!$J$14
Name COD: #N/A
Name COD: #N/A

Sheet Main
B3: Holding Company | K3: الشركة القابضة
B4: Fayoum Drinking Water and Sanitation Company | I4: شركة مياه الشرب والصرف الصحى بالفيوم
B5: Lab. Department | I5: قطاع المعامل - الادارة العامة لمعامل محطات الصرف الصحى
A7: Tamiya Sanitation Plant laboratory | J7: معمل محطة معالجة طامية
A11: Sampling Date : | H11: Analysis Date : | N11: .
D13: Wastewater Results | H13: النتـــائـج
E14: pH | F14: Temp. | G14: TS | H14: TSS | I14: TDS | J14: COD | K14: DO | L14: S-2 (as H2S) | M14: O&G | N14: Residual Cl2
D15: Unit | F15: °c | G15: mg/l | H15: mg/l | I15: mg/l | J15: mg/l | K15: mg/l | L15: mg/l | M15: mg/l | N15: mg/l
A16: Influent الدخول | G16: ='TS & VS'!D21 | H16: =IFERROR(TSS!E27,"") | I16: =IFERROR(IF(TDS!F25=0,"",TDS!F25),"") | J16: =IFERROR(COD!$L$19,"") | L16: =Sulfide!$C$14 | M16: =IFERROR('O&G'!H23,"")
A17: Effluent السيب النهائى | D17: المعايير | E17: 6.5 - 9 | F17: 15-35 | H17: 50 | I17: <2000 | J17: <80 | K17: >4 | L17: <=1 | M17: <10 | N17: 0.5 - 1
D18: النتائج | G18: ='TS & VS'!E21 | H18: =IFERROR(TSS!H27,"") | I18: =IFERROR(IF(TDS!G25=0,"",TDS!G25),"") | J18: =IFERROR(COD!K19,"") | K18: =IFERROR(IF(AND(DO!$D$13=0,E18=""),"",IF(DO!$D$13=0,"NA",DO!$D$13)),"") | L18: =IFERROR(IF(AND(Sulfide!$D$14=0,E18=""),"",IF(Sulfide!$D$14=0,"NA",Sulfide!$D$14)),"") | M18: =IFERROR('O&G'!I23,"")
A19: Efficiency Removal % | H19: =Efficiency!H8 | J19: =Efficiency!J8
E20: Operation Test | H20: اختبارات التشغيل
E21: TSS | G21: SV30 | H21: SVI | I21: DO | J21: VSS | K21: Dry Sludge TS% | L21: Microscopic Examination
D22: Range | E22: 3000 - 5000 | G22: ml/l | H22: 80 - 120 ml/g | I22: 1-3 mg/l | J22: mg/l | L22: Microrganism | N22: Found | AJ22: Many | AK22: Ciliates
A23: Aeration tank 1 | D23: النتائج Results | I23: =IF(G23="متوقف","متوقف",IF(DO!$O$6=0,"",DO!$O$6)) | AJ23: Few | AK23: Stacked Ciliates
A24: Aeration tank 2 | I24: =IF(G24="متوقف","متوقف",IF(DO!$O$8=0,"",DO!$O$8)) | AJ24: Dominant | AK24: Flagellates
A25: Mixed Liquour مجمع حوض التهوية | E25: =TSS!F27 | H25: =IFERROR((G25*1000)/E25,"") | I25: =IF(G25="متوقف","متوقف",IF(DO!$D$16=0,"",DO!$D$16)) | J25: ='TS & VS'!G21 | AK25: Amoeba
A26: RAS الحمأة الراجعة | E26: =TSS!G27 | J26: ='TS & VS'!H21 | AK26: Rotifera
A27: Thickener مغلظ الحمأة | E27: ='TS & VS'!F21 | K27: =IFERROR('WC%'!E5,"") | AK27: Worm
AK28: Water Bear
C29: MCRT | D29: =IFERROR('BOD5'!D39,"") | G29: F/M | H29: =IFERROR('BOD5'!C32,"") | J29: ='BOD5'!B42 | K29: =IFERROR(ABS('BOD5'!C42),"") | L29: Ope Time | M29: =IFERROR(K29/504,"") | AK29: Filamentous
A30: Location مكان العينة | D30: Influent الدخول | H30: Treated Effluent السيب النهائى
A31: Parameter | D31: BOD5 | K31: Turbidity | M31: Total coliform
A32: Unit الوحدة | D32: mg/l | H32: mg/l | K32: NTU | M32: MPN/100ml
A33: Criteria المعايير | D33: 500 طبقا لتصميم المحطة | H33: <60 | K33: <10 | M33: =CONCATENATE("< ",5,"X",10,CHAR(179))
A34: Results النتائج | D34: =IFERROR('BOD5'!$J$29,"") | H34: =IFERROR('BOD5'!$L$29,"")
A35: Efficiency Removal % | H35: =Efficiency!L8
B36: نتائج مقاس عمود الحمأة | G36: Results interpretation
B37: =IF(ISBLANK(Observation!E6),"",Observation!E6)
B38: =IF(ISBLANK(Observation!E7),"",Observation!E7)
B39: =IF(OR(E16="",Observation!B3="بنية خفيفة"),"","برجاء")&" "&IF(OR(AND(TSS!G21>0.8,TSS!G21<>""),AND(OR(Observation!C6="حمأة متضخمة",Observation!C7="حمأة متضخمة"),'BOD5'!C32>0.4,'BOD5'!O38>23),Observation!D5="ترسيب سريع مع ندف في حجم رأس الدبوس في ماء عكر",Observation!B3="رمادية",'BOD5'!C32<0.05,AND('BOD5'!D39>30,'BOD5'!D39<>""),AND('BOD5'!C57>6,'BOD5'!C57<>"")),"زيادة معدل صرف الحمأة الزائدة حتى 10%","")&IF(OR(Observation!C6="حمأة متضخمة نتيجة بكتيريا خيطية ",Observation!C7="حمأة متضخمة نتيجة بكتيريا خيطية "),IF(AND(Main!E16<6.5,Main!E16<>""),"احتمال وجود صرف صناعى برجاء تفريغ المحطة من الحمأة و إبلاغ إدارة الصرف الصناعى"," مراجعة نسبة المغذيات فى دخول المحطة"),"")&IF(AND(Observation!F5="قبل ساعتين ",Observation!G5="قبل ساعتين "),IF('BOD5'!O38<23,"زيادة معدل الحمأة المنشطة الراجعة",""),IF(AND(Observation!F5="قبل ساعتين ",Observation!G5="أكثر من ساعتين")," قياس الزيوت و الشحوم في مياه السيب النهائى",""))&IF(OR(Observation!C6="حمأة متضخمة نتيجة بكتيريا خيطية ",Observation!C7="حمأة متضخمة نتيجة بكتيريا خيطية ",AND(OR(Main!K23>3,Main!K24>3,Main!K25>3,Main!K23<1,Main!K24<1,Main!K25<1),Main!K23<>"",Main!K24<>"",Main!K25<>"")),IF(OR(Main!K23<1,Main!K24<1,Main!K25<1)," رفع نسبة الأكسجين الذائب فى أحواض التهوية من 1 إلى 3 مجم/لتر"," ضبط نسبة الأكسجين الذائب فى أحواض التهوية من 1 إلى 2 مجم/لتر"),"")&IF(AND(Observation!C6="حمأة بنية مع حمأة سوداء",Observation!C7="حمأة بنية مع حمأة سوداء")," فحص عمل أحواض الترسيب النهائى",IF(OR(Observation!C6="حمأة بنية مع حمأة سوداء",Observation!C7="حمأة بنية مع حمأة سوداء")," فحص عمل " & INDEX(Observation!A6:'Observation'!E7,MATCH("حمأة بنية مع حمأة سوداء",Observation!C6:'Observation'!C7,0),1),""))
B40: =IF(Observation!F5="قبل ساعتين "," صعود الحمأة في المخبار قبل مرور الساعتين ","")
B41: =IF(OR(E27="",E27="متوقف"),""," برجاء ضخ الحمأة المغلظة لمدة " &ROUND('BOD5'!C75,0) & " ساعة")
B42: =IF(OR(B37="",B38=""),"",IF(ABS(Observation!E6-Observation!E7)>MIN(Observation!E6:'Observation'!E7)*0.2," احتمال وجود سدة بين " & INDEX(Observation!A6:'Observation'!E7,MATCH(MAX(Observation!E6:'Observation'!E7),Observation!E6:'Observation'!E7,0),1)& " و بيارة الحمأة ",""))
B43: =IF(OR(Observation!B3="سوداء",Observation!B4="سوداء"),"احتمال وجود صرف صناعى برجاء تفريغ المحطة من الحمأة و إبلاغ إدارة الصرف الصناعى ",IF(OR(Observation!B6="وجود رغوة بيضاء",Observation!B7="وجود رغوة بيضاء"),"احتمال دخول زيوت و شحوم ويتم إبلاغ إدارة الصرف الصناعى",""))
B44: =IFERROR(IF(OR(N18="متوقف",N18="Nil",IF(ISNUMBER(SEARCH("كلور",B46)),TRUE,FALSE)),"",IF(AND(Observation!C9="",OR(N18<0.5,N18>1),N18<>""),"برجاء ضبط الكلور حسب النسب المسموحة من 0.5 الى 1 مجم/لتر",IF(Observation!C9="","","برجاء إيقاف الكلور لوجود " & Observation!C9))),"")
B45: =IF(ISNUMBER(FIND("الأكسجين",$B$39)),"",IF(AND(OR(Main!K23>3,Main!K24>3,Main!K25>3,Main!K23<1,Main!K24<1,Main!K25<1),Main!K23<>"",Main!K24<>"",Main!K25<>""), " برجاء ضبط الأكسجين فى أحواض التهوية بين 2 و 3 مجم/لتر ", ""))
B48: Reviewed by | K48: Analyzed by
B125: D:\Plant\labratory folder\Plant\Daily Sheets\
...

Sheet COD
P1: الشركة القابضة لمياة الشرب و الصرف الصحى
P2: قطاع المعامل
P3: الأدارة العامة لمعامل الصرف الصحى
A5: Tamiya Sanitation Plant laboratory
A6: COD WORK SHEET | I6: SAMPLE DATE: | K6: =Main!D11 | M6: ANALYSIS DATE: | O6: =Main!K11
A7: 20th EDITION, of The Standard Method for the Examination of Water and Wastewater | I7: TIME: ....................................................................
A8: PROCEDURE NUMBER 5220 D CLOSED REFLUX, COLORIMETRIC | I8: ="ANALYST : Ch/" & Efficiency!D31
A9: (1) SAMPLE TYPE | C9: Influent | E9: Effluent | Q9: 10 | S9: 12
A10: (2) BOTTLE NUMBER | C10: 1 | D10: 2 | E10: 3 | F10: 4 | Q10: 13 | R10: 14 | S10: 15 | T10: 16
A11: (3) SAMPLE VOLUME, ml | C11: 2.5 | D11: 2.5 | E11: 2.5 | F11: 2.5 | Q11: 2.5 | R11: 2.5 | S11: 2.5 | T11: 2.5
A12: (4) DILUTION FACTOR = 2 / (3) | C12: 1 | D12: 1 | E12: 1 | F12: 1 | Q12: 1 | R12: 1 | S12: 1 | T12: 1
A13: (5) COLORIMETER READING mg/l
A14: (6) COD mg/l = (5) x (4) | C14: =IFERROR(IF(C13="","",C13*C12),"") | D14: =IFERROR(IF(D13="","",D13*D12),"") | E14: =IFERROR(IF(E13="","",E13*E12),"") | F14: =IFERROR(IF(F13="","",F13*F12),"") | G14: =IFERROR(IF(G13="","",G13*G12),"") | H14: =IFERROR(IF(H13="","",H13*H12),"") | I14: =IFERROR(IF(I13="","",I13*I12),"") | J14: =IFERROR(IF(J13="","",J13*J12),"") | ... T14: =IFERROR(IF(T13="","",T13*T12),"")
A15: Average | C15: =IFERROR(IF(C13="","",IF(AND(C14="",D14=""),"ND",AVERAGE(C14:D14))),"") | E15: =IFERROR(IF(E13="","",IF(AND(E14="",F14=""),"ND",AVERAGE(E14:F14))),"") | G15: =IFERROR(IF(G13="","",IF(AND(G14="",H14=""),"ND",AVERAGE(G14:H14))),"") | I15: =IFERROR(IF(I13="","",IF(AND(I14="",J14=""),"ND",AVERAGE(I14:J14))),"") | K15: =IFERROR(IF(K13="","",IF(AND(K14="",L14=""),"ND",AVERAGE(K14:L14))),"") | M15: =IFERROR(IF(M13="","",IF(AND(M14="",N14=""),"ND",AVERAGE(M14:N14))),"") | O15: =IFERROR(IF(O13="","",IF(AND(O14="",P14=""),"ND",AVERAGE(O14:P14))),"") | Q15: =IFERROR(IF(Q13="","",IF(AND(Q14="",R14=""),"ND",AVERAGE(Q14:R14))),"") | S15: =IFERROR(IF(S13="","",IF(AND(S14="",T14=""),"ND",AVERAGE(S14:T14))),"")
A16: R | C16: =IFERROR(IF(C13="","",IF(AND(C14="",D14=""),"ND",ABS(C13-D13))),"") | E16: =IFERROR(IF(E13="","",IF(AND(E14="",F14=""),"ND",ABS(E13-F13))),"") | G16: =IFERROR(IF(G13="","",IF(AND(G14="",H14=""),"ND",ABS(G13-H13))),"") | I16: =IFERROR(IF(I13="","",IF(AND(I14="",J14=""),"ND",ABS(I13-J13))),"") | K16: =IFERROR(IF(K13="","",IF(AND(K14="",L14=""),"ND",ABS(K13-L13))),"") | M16: =IFERROR(IF(M13="","",IF(AND(M14="",N14=""),"ND",ABS(M13-N13))),"") | O16: =IFERROR(IF(O13="","",IF(AND(O14="",P14=""),"ND",ABS(O13-P13))),"") | Q16: =IFERROR(IF(Q13="","",IF(AND(Q14="",R14=""),"ND",ABS(Q13-R13))),"") | S16: =IFERROR(IF(S13="","",IF(AND(S14="",T14=""),"ND",ABS(S13-T13))),"")
A17: RPD | C17: =IFERROR(C16/AVERAGE(C13:D13),"") | E17: =IFERROR(E16/AVERAGE(E13:F13),"") | G17: =IFERROR(G16/AVERAGE(G13:H13),"") | I17: =IFERROR(I16/AVERAGE(I13:J13),"") | K17: =IFERROR(K16/AVERAGE(K13:L13),"") | M17: =IFERROR(M16/AVERAGE(M13:N13),"") | O17: =IFERROR(O16/AVERAGE(O13:P13),"") | Q17: =IFERROR(Q16/AVERAGE(Q13:R13),"") | S17: =IFERROR(S16/AVERAGE(S13:T13),"")
K18: LR | L18: HR
K19: =IFERROR(IF(E15="",IF(C31="",IF(E31="",C78,E31),C31),E15),"") | L19: =IFERROR(IF(C15="",IF(AND(B31="",D31=""),IF(B78="",D78,AVERAGE(B78,D78)),IF(B31="",D31,AVERAGE(B31,D31))),C15),"")
A22: تسجيل التجربة
K23: التخفيف
E24: REAGENT
B25: Influent HR | C25: Effluent ( 0 - 400 ) | D25: Influent LR | E25: Effluent ( 0 - 70 ) | G25: FAS | H25: Normality | AB25: Column1 | AC25: Ag2SO4 | AD25: H2SO4 | AE25: 1,10-phenanthroline monohydrate | AF25: FeSO4 7H2O | AG25: D.Water | AH25: Fe(NH4)2(SO4)2.6H2O | AI25: HgSO4 | AJ25: K2Cr2O7
A26: B | B26: 6.67 | C26: 2.65 | D26: =C26 | E26: 0.78 | H26: =(1.5/$C$26)*$X$72 | I26: =(1.5/$B$26)*$X$73 | J26: =(1.5/$E$26)*$X$76 | K26: العينة | L26: ماء مقطر | AB26: Sulfuric acid reagent | AC26: 5.5 g | AD26: 543.5 ml
A27: S1 | G27: V | H27: 2.5 | K27: 49 | M27: Influent HR | AB27: LR ( 0 - 400 ) 0.5 L | AD27: 83.5 | AG27: To 500 | AI27: 16.65 | AJ27: 2.4515 g
A28: COD | B28: =IF(B27="","",(IFERROR(((B26-B27)*$I$26*8000*$H$29)/$H$27,""))) | C28: =IF(C27="","",(IFERROR(((C26-C27)*$H$26*8000*$I$29)/$H$27,""))) | D28: =IF(D27="","",(IFERROR(((D26-D27)*$H$26*8000*$G$29)/H27,""))) | E28: =IF(E27="","",(IFERROR(((E26-E27)*$J$26*8000*$J$29)/$H$27,""))) | G28: Influent LR | H28: Influent HR | I28: effluent | J28: effluent | K28: 100 | M28: Effluent (0-400) | AB28: HR ( 100 - 900 ) 0.5 L | AD28: 83.5 | AG28: To 500 | AI28: 16.65 | AJ28: 5.108
A29: S2 | G29: =($L$29+$K$29)/$K$29 | H29: =($L$27+$K$27)/$K$27 | I29: =($L$28+$K$28)/$K$28 | J29: =($L$30+$K$30)/$K$30 | K29: 100 | M29: Influent LR | N29: 88.8879 | O29: 49 | P29: 1 | Q29: =N30 | AB29: LR ( 0 - 90 ) 0.5 L | AD29: 83.5 | AG29: To 500 | AI29: 16.65 | AJ29: 0.511
A30: COD | B30: =IF(B29="","",(IFERROR(((B26-B29)*$I$26*8000*$H$29)/$H$27,""))) | C30: =IF(C29="","",(IFERROR(((C26-C29)*$H$26*8000*$I$29)/$H$27,""))) | D30: =IF(D29="","",(IFERROR(((D26-D29)*$H$26*8000*$G$29)/$H$27,""))) | E30: =IF(E29="","",(IFERROR(((E26-E29)*$J$26*8000*$J$29)/$H$27,""))) | K30: 100 | M30: Effluent ( 0 - 70 ) | N30: =N29/O29 | P30: =P29/Q29*1000 | Q30: 1 | AB30: Ferroin indicator stock 100 ml | AE30: 1.485 g | AF30: 0.695 g | AG30: To 100
A31: Average | B31: =IF(B26="","",IF(OR(B30="",B30=0),IF(OR(B28="",B28=0),"",B28),AVERAGE(B28,B30))) | C31: =IF(C26="","",IF(OR(C30="",C30=0),IF(OR(C28="",C28=0),"",C28),AVERAGE(C28,C30))) | D31: =IF(D26="","",IF(OR(D30="",D30=0),IF(OR(D28="",D28=0),"",D28),AVERAGE(D28,D30))) | E31: =IF(E26="","",IF(OR(E30="",E30=0),IF(OR(E28="",E28=0),"",E28),AVERAGE(E28,E30))) | AB31: FAS 0.025 N | AD31: 2 ml | AG31: To 100 | AH31: 3.920 g
A32: STDV | B32: =IFERROR(STDEV(B28,B31),"") | C32: =IFERROR(STDEV(C28,C31),"") | D32: =IFERROR(STDEV(D28,D31),"") | E32: =IFERROR(STDEV(E28,E31),"") | AB32: FAS 0.0125 N | AD32: 2 ml | AG32: To 100 | AH32: 1.96 g
A33: r | B33: =IFERROR(2.8*B32,"") | C33: =IFERROR(2.8*C32,"") | D33: =IFERROR(2.8*D32,"") | E33: =IFERROR(2.8*E32,"") | AB33: FAS 0.025 N | AD33: 10 ml | AG33: To 500 | AH33: 19.6 g
A34: CV | B34: =IFERROR(B32/B31,"") | C34: =IFERROR(C32/C31,"") | D34: =IFERROR(D32/D31,"") | E34: =IFERROR(E32/E31,"") | M34: رجوع | V34: 425 | W34: 250 | AB34: FAS 0.0125 N | AD34: 10 ml | AG34: To 500 | AH34: 9.8 g
A35: RPD | B35: =IFERROR((ABS(B28-B30))/AVERAGE(B28,B30),"") | C35: =IFERROR((ABS(C28-C30))/AVERAGE(C28,C30),"") | D35: =IFERROR((ABS(D28-D30))/AVERAGE(D28,D30),"") | E35: =IFERROR((ABS(E28-E30))/AVERAGE(E28,E30),"") | V35: =V34*W35/W34 | W35: 100 | AD35: =167/2 | AJ35: BACK
A36: RPD | B36: =IFERROR((ABS(B27-B29))/AVERAGE(B27,B29),"") | C36: =IFERROR((ABS(C27-C29))/AVERAGE(C27,C29),"") | D36: =IFERROR((ABS(D27-D29))/AVERAGE(D27,D29),"") | E36: =IFERROR((ABS(E27-E29))/AVERAGE(E27,E29),"")
B37: Standard | C37: S1 | D37: S1R | E37: S2 | F37: S2R | G37: Mean | H37: STD | I37: r | J37: Precission
B38: 70 ( 0 - 70 ) | D38: =IF(C38="","",IFERROR((($E$26-C38)*$J$26*8000)/$H$27,"")) | F38: =IF(E38="","",IFERROR((($E$26-E38)*$J$26*8000)/$H$27,"")) | G38: =IFERROR(AVERAGE(D38,F38),"") | H38: =IFERROR(STDEV(D38,F38),"") | I38: =IFERROR(2.8*H38,"") | J38: =IFERROR(H38/G38,"")
A39: Standards | B39: 10 ( 0 - 70 ) | D39: =IF(C39="","",IFERROR((($E$26-C39)*$J$26*8000)/$H$27,"")) | F39: =IF(E39="","",IFERROR((($E$26-E39)*$J$26*8000)/$H$27,"")) | G39: =IFERROR(AVERAGE(D39,F39),"") | H39: =IFERROR(STDEV(D39,F39),"") | I39: =IFERROR(2.8*H39,"") | J39: =IFERROR(H39/G39,"")
B40: 50 ( 50 - 400 ) | D40: =IF(C40="","",IFERROR((($C$26-C40)*$H$26*8000)/$H$27,"")) | F40: =IF(E40="","",IFERROR((($C$26-E40)*$H$26*8000)/$H$27,"")) | G40: =IFERROR(AVERAGE(D40,F40),"") | H40: =IFERROR(STDEV(D40,F40),"") | I40: =IFERROR(2.8*H40,"") | J40: =IFERROR(H40/G40,"")
B41: 90 ( 0 - 70 ) | D41: =IF(C41="","",IFERROR((($E$26-C41)*$J$26*8000)/$H$27,"")) | F41: =IF(E41="","",IFERROR((($E$26-E41)*$J$26*8000)/$H$27,"")) | G41: =IFERROR(AVERAGE(D41,F41),"") | H41: =IFERROR(STDEV(D41,F41),"") | I41: =IFERROR(2.8*H41,"") | J41: =IFERROR(H41/G41,"")
B42: 90 ( 50 - 400 ) | D42: =IF(C42="","",IFERROR((($C$26-C42)*$H$26*8000)/$H$27,"")) | F42: =IF(E42="","",IFERROR((($C$26-E42)*$H$26*8000)/$H$27,"")) | G42: =IFERROR(AVERAGE(D42,F42),"") | H42: =IFERROR(STDEV(D42,F42),"") | I42: =IFERROR(2.8*H42,"") | J42: =IFERROR(H42/G42,"")
B43: 120 ( 50 - 400 ) | D43: =IF(C43="","",IFERROR((($C$26-C43)*$H$26*8000)/$H$27,"")) | F43: =IF(E43="","",IFERROR((($C$26-E43)*$H$26*8000)/$H$27,"")) | G43: =IFERROR(AVERAGE(D43,F43),"") | H43: =IFERROR(STDEV(D43,F43),"") | I43: =IFERROR(2.8*H43,"") | J43: =IFERROR(H43/G43,"") | M43: Spike | N43: LR | O43: Spike | P43: HR | V43: Spike v | W43: 50
...

Sheet Sulfide
A3: Holding Company | G3: الشركة القابضة
A4: Fayoum drinking Water and Sanitation Company | G4: شركة مياه الشرب والصرف الصحى بالفيوم
G5: قطاع المعامل - الادارة العامة لمعامل الصرف الصحى
A6: SULFIDE (S2-) WORK SHEET | D6: Plant: Tamiya | F6: FORM ID:
A7: 20th EDITION, of The Standard Method for the Examination of Water and Wastewater | D7: Lab ID: WWL03 | F7: SAMPLE DATE: | G7: =Main!D11
A8: PROCEDURE NUMBER 4500-S2- | D8: =COD!I8 | F8: ANALYSIS DATE: | G8: =Main!K11
A9: (1) SAMPLE TYPE/ ID | C9: Influent | D9: Effluent
A10: (2) Iodine VOLUME, ml | C10: 10 | D10: 10
A11: (3) SAMPLE VOLUME, ml | C11: 200 | D11: 200
A12: (4) Sodium Thiosulphate VOLUME, ml
A13: (5) Sodium Thiosulphate VOLUME, ml after correction | C13: =IFERROR(HLOOKUP($C$17,Dispenser[#Data],MATCH(ROUND(C12,0),Dispenser[[Column1]:[Column1]],0),FALSE)+C12,"") | D13: =IFERROR(HLOOKUP($C$17,Dispenser[#Data],MATCH(ROUND(D12,0),Dispenser[[Column1]:[Column1]],0),FALSE)+D12,"") | E13: =IFERROR(HLOOKUP($C$17,Dispenser[#Data],MATCH(ROUND(E12,0),Dispenser[[Column1]:[Column1]],0),FALSE)+E12,"") | F13: =IFERROR(HLOOKUP($C$17,Dispenser[#Data],MATCH(ROUND(F12,0),Dispenser[[Column1]:[Column1]],0),FALSE)+F12,"") | G13: =IFERROR(HLOOKUP($C$17,Dispenser[#Data],MATCH(ROUND(G12,0),Dispenser[[Column1]:[Column1]],0),FALSE)+G12,"") | H13: =IFERROR(HLOOKUP($C$17,Dispenser[#Data],MATCH(ROUND(H12,0),Dispenser[[Column1]:[Column1]],0),FALSE)+H12,"")
A14: (6) Sulfide S2- concentration | C14: =IFERROR(IF(C10="","",(C10*$C$23-C13*$D$23)*16000/C11),"") | D14: =IFERROR(IF(D10="","",(D10*$C$23-D13*$D$23)*16000/D11),"") | E14: =IFERROR(IF(E10="","",(E10*$C$23-E13*$D$23)*16000/E11),"") | F14: =IFERROR(IF(F10="","",(F10*$C$23-F13*$D$23)*16000/F11),"") | G14: =IFERROR(IF(G10="","",(G10*$C$23-G13*$D$23)*16000/G11),"") | H14: =IFERROR(IF(H10="","",(H10*$C$23-H13*$D$23)*16000/H11),"")
A16: Standardization
A17: Digital Burette | C17: 20G33740
A18: Trials | C18: I2 | D18: Na2S2O3 | E18: Trials | M18: Solution | N18: Na2S2O3.5H2O | O18: NaOH | P18: I2 | Q18: KI | R18: D.Water | S18: KH(IO3)2 | T18: HCl
A19: Iodine Volume | C19: 10 | D19: 10 | E19: KH(IO3)2 | M19: Sodium Thiosulfate 0.025 N | N19: 6.205 g | O19: 0.4 g | R19: 1000 ml
A20: 1st trial with standardized Na2S2O3 | C20: 10 | D20: 10 | E20: 1st trial with KH(IO3)2 | M20: KH(IO3)2 0.0021M | R20: 1000 ml | S20: 0.812 g
A21: 2nd trial with standardized Na2S2O3 | C21: 10 | D21: 10 | E21: 2nd trial with KH(IO3)2 | M21: Iodine 0.025 N | P21: 3.2 g | Q21: 25 g | R21: 1000 ml
A22: 3rd trial with standardized Na2S2O3 | C22: 10 | D22: 10 | E22: 3rd trial with KH(IO3)2 | M22: HCL 6 N | R22: 1000 ml | T22: 500 ml
A23: Iodine Normality | C23: =IFERROR((AVERAGE(C20:C22)+HLOOKUP($C$17,Dispenser[],MATCH(ROUND(AVERAGE(C20:C22),0),Dispenser[Column1],0),FALSE))*(D23/C19),"") | D23: =IFERROR((AVERAGE(D20:D22)+HLOOKUP($C$17,Dispenser[],MATCH(ROUND(AVERAGE(D20:D22),0),Dispenser[Column1],0),FALSE))*0.00025*D19,"") | E23: Na2S2O3 Normality
H24: رجوع

Sheet DO
B2: Winkler | J2: DO meter | P2: %
A5: الخروج | B5: DO | E5: حوض1 | F5: DO | I5: الخروج | J5: DO | M5: حوض1 | N5: DO
C6: =(C5*Sulfide!D23*8000)/200 | G6: =(G5*Sulfide!D23*8000)/200 | K6: =IFERROR(IF(P3>0,$K$5*$P$3,$K$5),"") | O6: =IFERROR(IF($P$3>0,$O$5*$P$3,$O$5),"")
B8: DO | E8: حوض2 | F8: DO | I8: المجمع | J8: DO | M8: حوض2 | N8: DO
C9: =(C8*Sulfide!D23*8000)/200 | G9: =(G8*Sulfide!D23*8000)/200 | K9: =IFERROR(IF($P$3>0,$K$8*$P$3,$K$8),"") | O9: =IFERROR(IF($P$3>0,$O$8*$P$3,$O$8),"")
B12: الخروج | C12: DO
D13: =IFERROR(IF($K$5<=0,$C$6,$K$6),"") | N13: رجوع
B15: المجمع | C15: DO
D16: =IFERROR(IF($K$8<=0,$C$9,$K$9),"")
F26: SV30 | G26: Correction
F27: =G27*0.78
B39: Specific Oxygen Uptake Rate
C42: DO1 | F42: DO2
C44: Time | D44: 15
C47: SOUR | D47: =IFERROR(($D$42-$G$42)*60/($D$44*('TS & VS'!$G$21/1000)),"") | E47: =CONCATENATE("𝑚𝑔𝑂",_xlfn.UNICHAR(8322)," ⁄𝑔𝑀𝐿𝑉𝑆𝑆 ⁄ ℎ𝑜𝑢𝑟")

Sheet WC%
A4: No | B4: Crucible W1 | C4: Sludge + Crucible W2 | D4: Dry + crucible W3 | E4: DC % | F4: WC %
A5: =IFERROR(IF(ISBLANK(T6),"",T6),"") | B5: =IFERROR(IF(W6=0,"",W6),"") | C5: =IFERROR(IF(Z6=0,"",Z6),"") | D5: =IFERROR(IF(AC6=0,"",AC6),"") | E5: =IFERROR(IF(OR(B5<1,C5<1,D5<1),"",((D5-B5)/(C5-B5)*100)),"") | F5: =IFERROR(IF(E5<1,"",100-E5),"") | T5: S.N. | U5: Crucible W1 | V5: Correcttion 1 | W5: Net weight 1 | X5: Sludge + Crucible W2 | Y5: Correcttion2 | Z5: Net weight2 | AA5: Dry + crucible W3 | AB5: Correcttion23 | AC5: Net weight24
E6: =IFERROR(IF(OR(D5<1,D6<1),"",((D6-B5)/(D5-B5)*100)),"") | F6: =IFERROR(IF(E6<1,"",100-E6),"") | V6: =_xlfn.IFNA(VLOOKUP(ROUND(Table1115[[#This Row],[Crucible W1]],0),Radwag[],3),"") | W6: =IFERROR(Table1115[[#This Row],[Crucible W1]]+Table1115[[#This Row],[Correcttion 1]],"") | Y6: =_xlfn.IFNA(VLOOKUP(ROUND(Table1115[[#This Row],[Sludge + Crucible W2]],0),Radwag[],3),"") | Z6: =IFERROR(Table1115[[#This Row],[Sludge + Crucible W2]]+Table1115[[#This Row],[Correcttion2]],"") | AB6: =_xlfn.IFNA(VLOOKUP(ROUND(Table1115[[#This Row],[Dry + crucible W3]],0),Radwag[],3),"") | AC6: =IFERROR(Table1115[[#This Row],[Dry + crucible W3]]+Table1115[[#This Row],[Correcttion23]],"")
E7: F | F7: V | V7: =_xlfn.IFNA(VLOOKUP(ROUND(Table1115[[#This Row],[Crucible W1]],0),Radwag[],3),"") | W7: =IFERROR(Table1115[[#This Row],[Crucible W1]]+Table1115[[#This Row],[Correcttion 1]],"") | Y7: =_xlfn.IFNA(VLOOKUP(ROUND(Table1115[[#This Row],[Sludge + Crucible W2]],0),Radwag[],3),"") | Z7: =IFERROR(Table1115[[#This Row],[Sludge + Crucible W2]]+Table1115[[#This Row],[Correcttion2]],"") | AB7: =_xlfn.IFNA(VLOOKUP(ROUND(Table1115[[#This Row],[Dry + crucible W3]],0),Radwag[],3),"") | AC7: =IFERROR(Table1115[[#This Row],[Dry + crucible W3]]+Table1115[[#This Row],[Correcttion23]],"")
V8: =_xlfn.IFNA(VLOOKUP(ROUND(Table1115[[#This Row],[Crucible W1]],0),Radwag[],3),"") | W8: =IFERROR(Table1115[[#This Row],[Crucible W1]]+Table1115[[#This Row],[Correcttion 1]],"") | Y8: =_xlfn.IFNA(VLOOKUP(ROUND(Table1115[[#This Row],[Sludge + Crucible W2]],0),Radwag[],3),"") | Z8: =IFERROR(Table1115[[#This Row],[Sludge + Crucible W2]]+Table1115[[#This Row],[Correcttion2]],"") | AB8: =_xlfn.IFNA(VLOOKUP(ROUND(Table1115[[#This Row],[Dry + crucible W3]],0),Radwag[],3),"") | AC8: =IFERROR(Table1115[[#This Row],[Dry + crucible W3]]+Table1115[[#This Row],[Correcttion23]],"")
V9: =_xlfn.IFNA(VLOOKUP(ROUND(Table1115[[#This Row],[Crucible W1]],0),Radwag[],3),"") | W9: =IFERROR(Table1115[[#This Row],[Crucible W1]]+Table1115[[#This Row],[Correcttion 1]],"") | Y9: =_xlfn.IFNA(VLOOKUP(ROUND(Table1115[[#This Row],[Sludge + Crucible W2]],0),Radwag[],3),"") | Z9: =IFERROR(Table1115[[#This Row],[Sludge + Crucible W2]]+Table1115[[#This Row],[Correcttion2]],"") | AB9: =_xlfn.IFNA(VLOOKUP(ROUND(Table1115[[#This Row],[Dry + crucible W3]],0),Radwag[],3),"") | AC9: =IFERROR(Table1115[[#This Row],[Dry + crucible W3]]+Table1115[[#This Row],[Correcttion23]],"")
V10: =_xlfn.IFNA(VLOOKUP(ROUND(Table1115[[#This Row],[Crucible W1]],0),Radwag[],3),"") | W10: =IFERROR(Table1115[[#This Row],[Crucible W1]]+Table1115[[#This Row],[Correcttion 1]],"") | Y10: =_xlfn.IFNA(VLOOKUP(ROUND(Table1115[[#This Row],[Sludge + Crucible W2]],0),Radwag[],3),"") | Z10: =IFERROR(Table1115[[#This Row],[Sludge + Crucible W2]]+Table1115[[#This Row],[Correcttion2]],"") | AB10: =_xlfn.IFNA(VLOOKUP(ROUND(Table1115[[#This Row],[Dry + crucible W3]],0),Radwag[],3),"") | AC10: =IFERROR(Table1115[[#This Row],[Dry + crucible W3]]+Table1115[[#This Row],[Correcttion23]],"")
V11: =_xlfn.IFNA(VLOOKUP(ROUND(Table1115[[#This Row],[Crucible W1]],0),Radwag[],3),"") | W11: =IFERROR(Table1115[[#This Row],[Crucible W1]]+Table1115[[#This Row],[Correcttion 1]],"") | Y11: =_xlfn.IFNA(VLOOKUP(ROUND(Table1115[[#This Row],[Sludge + Crucible W2]],0),Radwag[],3),"") | Z11: =IFERROR(Table1115[[#This Row],[Sludge + Crucible W2]]+Table1115[[#This Row],[Correcttion2]],"") | AB11: =_xlfn.IFNA(VLOOKUP(ROUND(Table1115[[#This Row],[Dry + crucible W3]],0),Radwag[],3),"") | AC11: =IFERROR(Table1115[[#This Row],[Dry + crucible W3]]+Table1115[[#This Row],[Correcttion23]],"")
V12: =_xlfn.IFNA(VLOOKUP(ROUND(Table1115[[#This Row],[Crucible W1]],0),Radwag[],3),"") | W12: =IFERROR(Table1115[[#This Row],[Crucible W1]]+Table1115[[#This Row],[Correcttion 1]],"") | Y12: =_xlfn.IFNA(VLOOKUP(ROUND(Table1115[[#This Row],[Sludge + Crucible W2]],0),Radwag[],3),"") | Z12: =IFERROR(Table1115[[#This Row],[Sludge + Crucible W2]]+Table1115[[#This Row],[Correcttion2]],"") | AB12: =_xlfn.IFNA(VLOOKUP(ROUND(Table1115[[#This Row],[Dry + crucible W3]],0),Radwag[],3),"") | AC12: =IFERROR(Table1115[[#This Row],[Dry + crucible W3]]+Table1115[[#This Row],[Correcttion23]],"")
N13: رجوع
H14: =E5

Sheet Efficiency
J1: الشركة القابضة لمياة الشرب و الصرف الصحى
I2: قطاع المعامل
J3: الأدارة العامة لمعامل الصرف الصحى
J4: =Main!J7
A5: Removal efficiency
A6: =Main!$H$11 | D6: =Main!$D$11
D7: Parameter | F7: S-- | H7: TSS | J7: COD | L7: BOD | N7: MLSS
D8: Removal | F8: =IFERROR((Main!$L$16-Main!$L$18)/Main!$L$16,"") | H8: =IFERROR((Main!$H$16-Main!$H$18)/Main!$H$16,"") | J8: =IFERROR((Main!$J$16-Main!$J$18)/Main!$J$16,"") | L8: =IFERROR((Main!$D$34-Main!$H$34)/Main!$D$34,"") | N8: =IFERROR(IF(Main!$H$18="","",(Main!$E$25-Main!$H$18)/Main!$E$25),"")
T13: رجوع
A31: Technical manager: | D31: Mohamad Alawamy

Sheet BOD5
P1: الشركة القابضة لمياة الشرب و الصرف الصحى
P2: قطاع المعامل
P3: الأدارة العامة لمعامل الصرف الصحى
A5: =COD!A5
A6: BOD5 WORK SHEET | H6: SAMPLE DATE: | J6: =IF(ISBLANK(Main!D11),"",Main!D11) | L6: ANALYSIS DATE: | N6: =IFERROR(J6+K7,"")
A7: 18th EDITION, of The Standard Method for the Examination of Water and Wastewater | H7: TIME: | K7: 0 | L7: 0 DAY DO DATE: | N7: =N6
A8: PROCEDURE NUMBER 5210 B | H8: TIME: | L8: 5 DAY DO DATE: | N8: =IFERROR(N7+5,"")
A9: =IF(ISBLANK(J7),"",CONCATENATE(TEXT($J$7,"H:MM:ss AM/PM")& " INCUBATOR TEMPERATURE, DO1 ")) | D9: V | H9: ANALYST: | J9: =Efficiency!D31 | R9: PH
A10: =IF(ISBLANK(J8),"",CONCATENATE(TEXT($J$8,"H:MM:ss AM/PM")& " INCUBATOR TEMPERATURE, DO5 ")) | D10: 300 | H10: W seeding | L10: Seeding | Q10: Influent | R10: =Main!E16
A11: (1) SAMPLE TYPE | B11: =IFERROR(IF(AVERAGE(B12:C12)<>0,"BLANK",""),"") | D11: =IFERROR(IF(AVERAGE(D12:E12)<>0,"Influent",""),"") | F11: =IFERROR(IF(AVERAGE(F12:G12)<>0,"Effluent",""),"") | H11: =IFERROR(IF(OR($P$17="",$H$12=""),"",CONCATENATE($F$11," ","+"," ",$P$17)),"") | J11: =IFERROR(IF(OR($P$17="",J12=""),"",CONCATENATE($D$11," ","+"," ",$P$17)),"") | L11: =IFERROR(IF(AVERAGE(L12:O12)<>0,"Seeding",""),"") | P11: Seeding | Q11: effluent | R11: =Main!E18
A12: (2) BOTTLE NUMBER
A13: (3) SAMPLE VOLUME, ml
A14: (4) DILUTION FACTOR = 300 / (3) | D14: =IFERROR($D$10/D13,"") | E14: =IFERROR($D$10/E13,"") | F14: =IFERROR($D$10/F13,"") | G14: =IFERROR($D$10/G13,"") | H14: =IFERROR($D$10/H13,"") | I14: =IFERROR($D$10/I13,"") | J14: =IFERROR($D$10/J13,"") | K14: =IFERROR($D$10/K13,"") | ... O14: =IFERROR($D$10/O13,"") | P14: =IFERROR(300/P13,"")
A15: (5) INITIAL DO, mg/l
A16: (6) 5- DAY DO, mg/l * | P16: V
A17: (7) DO DEPLETION, mg/l = (5) - (6) ** | B17: =IFERROR(IF(B16="","",IF(B15<B16,0,B15-B16)),"") | C17: =IFERROR(IF(C16="","",IF(C15<C16,0,C15-C16)),"") | D17: =IFERROR(IF(D16>=1,D15-D16,""),"") | E17: =IFERROR(IF(E16>=1,E15-E16,""),"") | F17: =IFERROR(IF(F16>=1,F15-F16,""),"") | G17: =IFERROR(IF(G16>=1,G15-G16,""),"") | H17: =IFERROR(IF(H16>=1,H15-H16,""),"") | I17: =IFERROR(IF(I16>=1,I15-I16,""),"") | J17: =IFERROR(IF(J16>=1,J15-J16,""),"") | K17: =IFERROR(IF(K16>=1,K15-K16,""),"") | ... O17: =IFERROR(IF(O16>=1,O15-O16,""),"")
A18: (8) BLANK DEPLETION CORRECTION, mg/l = (11) of Blank, mg/l X DW, ml / 300 | D18: =IFERROR(IF(D13>0,IF(OR($B$17>0.2,$C$17>0.2),AVERAGE($B$17:$C$17)*($D$10-D13)/$D$10,"0"),""),"") | E18: =IFERROR(IF(E13>0,IF(OR($B$17>0.2,$C$17>0.2),AVERAGE($B$17:$C$17)*($D$10-E13)/$D$10,"0"),""),"") | F18: =IFERROR(IF(F13>0,IF(OR($B$17>0.2,$C$17>0.2),AVERAGE($B$17:$C$17)*($D$10-F13)/$D$10,"0"),""),"") | G18: =IFERROR(IF(G13>0,IF(OR($B$17>0.2,$C$17>0.2),AVERAGE($B$17:$C$17)*($D$10-G13)/$D$10,"0"),""),"") | H18: =IFERROR(IF(H13>0,IF(OR($B$17>0.2,$C$17>0.2),AVERAGE($B$17:$C$17)*($D$10-H13)/$D$10,"0"),""),"") | I18: =IFERROR(IF(I13>0,IF(OR($B$17>0.2,$C$17>0.2),AVERAGE($B$17:$C$17)*($D$10-I13)/$D$10,"0"),""),"") | J18: =IFERROR(IF(J13>0,IF(OR($B$17>0.2,$C$17>0.2),AVERAGE($B$17:$C$17)*($D$10-J13)/$D$10,"0"),""),"") | K18: =IFERROR(IF(K13>0,IF(OR($B$17>0.2,$C$17>0.2),AVERAGE($B$17:$C$17)*($D$10-K13)/$D$10,"0"),""),"") | ... O18: =IFERROR(IF(O13>0,IF(OR($B$17>0.2,$C$17>0.2),AVERAGE($B$17:$C$17)*($D$10-O13)/$D$10,"0"),""),"") | P18: =$D$10
A19: (9) DO CORRECTION = (7) - (8) | D19: =IFERROR(IF(D12>0,D17-D18,""),"") | E19: =IFERROR(IF(E12>0,E17-E18,""),"") | F19: =IFERROR(IF(F12>0,F17-F18,""),"") | G19: =IFERROR(IF(G12>0,G17-G18,""),"") | H19: =IFERROR(H17-(H18+$P$19),"") | I19: =IFERROR(I17-(I18+$P$19),"") | J19: =IFERROR(J17-(J18+$P$19),"") | K19: =IFERROR(K17-(K18+$P$19),"") | L19: =IFERROR(IF(L12>0,L17-L18,""),"") | M19: =IFERROR(IF(M12>0,M17-M18,""),"") | N19: =IFERROR(IF(N12>0,N17-N18,""),"") | O19: =IFERROR(IF(O12>0,O17-O18,""),"") | P19: =IFERROR((IF(L21="","",L21*P17/P18)),"")
A20: (10) BOD5, mg/l = (9) X (4) | D20: =IFERROR(IF(D16>0,IF(D19>=2,D19*D14,""),""),"") | E20: =IFERROR(IF(E16>0,IF(E19>=2,E19*E14,""),""),"") | F20: =IFERROR(IF(F16>0,IF(F19>=2,F19*F14,""),""),"") | G20: =IFERROR(IF(G16>0,IF(G19>=2,G19*G14,""),""),"") | H20: =IFERROR(IF(H16>0,IF(H19>=2,H19*H14,""),""),"") | I20: =IFERROR(IF(I16>0,IF(I19>=2,I19*I14,""),""),"") | J20: =IFERROR(IF(J16>0,IF(J19>=2,J19*J14,""),""),"") | K20: =IFERROR(IF(K16>0,IF(K19>=2,K19*K14,""),""),"") | ... O20: =IFERROR(IF(O16>0,IF(O19>=2,O19*O14,""),""),"")
A21: (11) BOD5 AVERAGE | D21: =IFERROR(AVERAGE(D20:E20),"") | F21: =IFERROR(AVERAGE(F20:G20),"") | H21: =IFERROR(AVERAGE(H20:I20),"") | J21: =IFERROR(AVERAGE(J20:K20),"") | L21: =IFERROR(AVERAGE(L20:O20),"") | T21: Dilution Water
A22: (12) BOD5 Correction | D22: =IFERROR(IF(OR(D17="",D20=""),(IF(D12>0,(D15-D16-D18),""))*D14,""),"") | E22: =IFERROR(IF(OR(E17="",E20=""),(IF(E12>0,(E15-E16-E18),""))*E14,""),"") | F22: =IFERROR(IF(OR(F17="",F20=""),(IF(F12>0,(F15-F16-F18),""))*F14,""),"") | G22: =IFERROR(IF(OR(G17="",G20=""),(IF(G12>0,(G15-G16-G18),""))*G14,""),"") | H22: =IFERROR(IF(OR(H17="",H20=""),(IF(H12>0,(H15-H16-H18-$P$19),""))*H14,""),"") | I22: =IFERROR(IF(OR(I17="",I20=""),(IF(I12>0,(I15-I16-I18-$P$19),""))*I14,""),"") | J22: =IFERROR(IF(OR(J17="",J20=""),(IF(J12>0,(J15-J16-J18-$P$19),""))*J14,""),"") | K22: =IFERROR(IF(OR(K17="",K20=""),(IF(K12>0,(K15-K16-K18-$P$19),""))*K14,""),"") | L22: =IFERROR(IF(OR(L17="",L20=""),(IF(L12>0,(L15-L16-L18),""))*L14,""),"") | M22: =IFERROR(IF(OR(M17="",M20=""),(IF(M12>0,(M15-M16-M18),""))*M14,""),"") | N22: =IFERROR(IF(OR(N17="",N20=""),(IF(N12>0,(N15-N16-N18),""))*N14,""),"") | O22: =IFERROR(IF(OR(O17="",O20=""),(IF(O12>0,(O15-O16-O18),""))*O14,""),"") | P22: =IFERROR(IF(P16>0,IF(P19>=2,P19*P14,""),""),"") | T22: Column1 | U22: FeCl3.6H2O | V22: KH2PO4 | W22: K2HPO4 | X22: Na2HPO4.7H2O | Y22: D.Water | Z22: NH4Cl | AA22: MgSO4.7H2O | AB22: CaCl2 | AC22: glucose | AD22: glutamic acid | AE22: Na2HPO4 | AF22: C4H8N2s | AG22: conc H2SO4 | AH22: NaOH | AI22: Conc HCl
A23: SPIKE recovery | T23: Ferric chloride | U23: 0.125 g | Y23: To 500 | AI23: 3 drops
A24: RPD | D24: =IFERROR(ABS(D20-E20)/D21,"") | F24: =IFERROR(ABS(F20-G20)/F21,"") | H24: =IFERROR(ABS(H20-I20)/H21,"") | J24: =IFERROR(ABS(J20-K20)/J21,"") | L24: =IFERROR((MAX(L20:O20)-MIN(L20:O20))/L21,"")
A25: * The residual 5-day-DO must be at least 1mg/l | B25: If less | C25: The BOD is greater than the higest DO | Q25: D.Water | R25: 500 ml | T25: Phosphate buffer solution | V25: 0.85 g | W25: 2.175 g | X25: 3.34 g | Y25: To 100 | Z25: 0.17 g
A26: ** 5-day-DO uptake 2 mg/l or greater | B26: If less | C26: The BOD is less than the lowest Dilution | J26: Influent | L26: effluent | Q26: Glucose | R26: 75 | T26: Magnesium sulfate | Y26: To 100 | AA26: 2.25 g
A27: *** No depletion correction needed if DO depletion in the blank is less than 0.2 mg/l | J27: =$D$21 | L27: =IFERROR(IF($F$21="",$H$21,$F$21),"") | Q27: Glutamic | R27: 75 | T27: Calcium chloride | Y27: To 100 | AB27: 2.75 g
A28: DW = Dilution Water | I28: Manometric | T28: Glucose–glutamic acid at < 6°C | Y28: To 1000 | AC28: 0.15 g | AD28: 0.15 g
B29: Tanks V | C29: Flow | D29: MLSS | E29: VSS% | F29: Clarifier | J29: =IFERROR(IF(AND(D17<2,E17<2,J28=""),"ND",IF(J28="",J27,J28)),"") | L29: =IFERROR(IF(AND(F17<2,G17<2,H17<2,I17<2,L28=""),"ND",IF(L28="",L27,L28)),"") | T29: Acid solution 1 N | Y29: To 100 | AG29: 2.8 ml
B30: =IFERROR(8000*(B31/2),"") | C30: 15000 | D30: =IFERROR(IF(TSS!F27="",(Main!$E$25)*1.1,TSS!F27),"") | E30: =IFERROR(IF(TSS!G21="",0.7,TSS!G21),"") | F30: =IFERROR(B59*D59,"") | N30: رجوع | T30: Alkali solution 1 N | Y30: To 100 | AH30: 4 g
B31: =IFERROR(COUNT(Main!G23:H24),"") | I31: =IFERROR((J29-L29)*(D30/J29),"") | T31: Phosphate buffer solution | V31: 4.25 g | Y31: To 100 | Z31: 0.17
B32: F/M | C32: =IFERROR($J$29*$C$30/($B$30*(IF('TS & VS'!G21="",$D$30*$E$30,'TS & VS'!G21)+$F$30)),"") | D32: 0.05 / 0.15 | T32: Allylthiourea | Y32: 50 | AF32: 0.1 g
P33: Scale
C34: m3/h | D34: Operating | E34: m3/day | F34: SS | G34: Q*SS | H34: Qss % | L34: WAS on | M34: 1 | N34: =(M34/10)*P34 | O34: =24*60/(N34+N35) | P34: 60
B35: WAS | C35: 43.2 | D35: =TEXT(TRUNC($O$35,0)&":"&INT(($O$35-TRUNC($O$35,0))*60),"hh:mm") | E35: =C35*$O$35 | F35: =IFERROR(IF(TSS!G27="",(Main!E26)*1.1,TSS!G27),"") | G35: =IFERROR($E$35*$F$35/1000,"") | H35: =G35/(B51*O38) | L35: WAS off | M35: 10 | N35: =(M35/10)*P35 | O35: =(O34*N34)/60 | P35: 10
B36: Effluent | E36: =$C$30 | F36: =IF(Main!$H$18="",1,Main!$H$18) | G36: =IFERROR(E36*F36/1000,"") | L36: WAS/RAS | M36: =O35/O38 | N36: =IFERROR(IF(M36<15%,TRUE,FALSE),"") | AA36: رجوع
B37: Thick | C37: =36*2 | D37: =IFERROR(TEXT(TRUNC($O$40,0)&":"&INT(($O$40-TRUNC($O$40,0))*60),"hh:mm"),"") | E37: =IFERROR(C37*O40,"") | F37: =IFERROR(IF('TS & VS'!$F$21="",(Main!$E$27)*1.18,'TS & VS'!$F$21),"") | L37: RAS on | M37: 5 | N37: =(M37/10)*P37 | O37: =24*60/(N37+N38) | P37: 6
A38: Reagent | L38: RAS off | M38: 3 | N38: =(M38/10)*P38 | O38: =(O37*N37)/60 | P38: 2
C39: MCRT | D39: =IFERROR(($B$30+$F$30)*$D$30/(($G$35*IF('TS & VS'!H21="",F35,'TS & VS'!H21))+G36),"") | E39: 10 ; 30 | L39: Thick on | M39: 8 | N39: =M39*IF(P39="min",1,60) | O39: =24*60/(N39+N40) | P39: min
L40: Thick off | M40: 4 | N40: =M40*IF(P40="min",1,60) | O40: =IF(Main!E27="","",IF(Main!E27<=30000,20,IF(Main!E27<=40000,30,45))) | P40: hr
B42: Q (ras) | C42: =IFERROR($C$30/(((($D$30/10000)*Main!$G$25)-1)*0.01),"") | D42: ON | E42: =(C43/24)*10 | F42: OFF | G42: =24-C43 | H42: =(G42/24)*10
...

Sheet turbidity
A3: Holding Company | K3: الشركة القابضة
A4: Fayoum drinking Water and Sanitation Company | I4: شركة مياه الشرب والصرف الصحى بالفيوم
I5: قطاع المعامل - الادارة العامة لمعامل الصرف الصحى
A7: =Main!A7 | J7: =Main!J7
C9: Turbidity comparison
A11: Sampling Dat : | D11: =Main!D11 | H11: Analysis Date : | K11: =Main!K11
A13: Location مكان العينة | D13: Treated Effluent السيب النهائى | K13: Chlorinated Effluent
A14: Parameter | D14: BOD5 | H14: Turbidity | K14: TSS
A15: Unit الوحدة | D15: mg/l | H15: NTU | K15: mg/l
A16: Criteria المعايير | D16: <60 | H16: <10 | K16: <50
A17: Results النتائج | D17: =Main!H34 | H17: =Main!K34 | K17: =Main!H18
O28: رجوع
B39: Analyzed by | J39: Reviewed by

Sheet BreakPoint
D2: CL- M.Wt | E2: 35.45
C5: Cl- Power | D5: Na2S2O3 | F5: Blank | G5: Na2S2O3
B6: V | C6: 10 | D6: 5.5 | E6: V | F6: 250 | G6: 0
C7: =IFERROR((D6-$G$6)*Sulfide!D23*$E$2/C6,"")
D15: mg Cl2 ( Dose )
D16: ml of Cl2 in L | E16: =IFERROR(E15/$C$7,"") | F16: =IFERROR(F15/$C$7,"") | G16: =IFERROR(G15/$C$7,"") | H16: =IFERROR(H15/$C$7,"") | I16: =IFERROR(I15/$C$7,"") | J16: =IFERROR(J15/$C$7,"") | K16: =IFERROR(K15/$C$7,"") | L16: =IFERROR(L15/$C$7,"") | ... N16: =IFERROR(N15/$C$7,"")
D17: ml of Cl2 in 250 ml | E17: =IFERROR(E16/4,"") | F17: =IFERROR(F16/4,"") | G17: =IFERROR(G16/4,"") | H17: =IFERROR(H16/4,"") | I17: =IFERROR(I16/4,"") | J17: =IFERROR(J16/4,"") | K17: =IFERROR(K16/4,"") | L17: =IFERROR(L16/4,"") | ... N17: =IFERROR(N16/4,"")
D18: R Cl | Q18: رجوع
D19: Temp
D20: PH
D23: Contact time | E23: 20 min | K23: =E26*4
D24: Residual chlorine | E24: 0.16
D25: Chlorine demand | E25: 4.8
D26: Chlorine Requirement | E26: 6.5
I33: 0.6 | J33: 0.5 | K33: 0.6 | L33: 0.4 | M33: 0.3 | N33: 0.4 | O33: 0.41 | P33: 0.43 | Q33: 0.44 | R33: 0.3 | S33: 0.31
I34: =35.45*0.023*10
I35: =I33*$I$34 | J35: =J33*$I$34 | K35: =K33*$I$34 | L35: =L33*$I$34 | M35: =M33*$I$34 | N35: =N33*$I$34 | O35: =O33*$I$34 | P35: =P33*$I$34 | ... S35: =S33*$I$34

Sheet Break point report
A3: Holding Company | K3: الشركة القابضة
A4: Fayoum drinking Water and Sanitation Company | I4: شركة مياه الشرب والصرف الصحى بالفيوم
I5: قطاع المعامل - الادارة العامة لمعامل الصرف الصحى
A7: =Main!A7 | J7: =Main!J7
C9: BreakPoint
A11: Sampling Dat : | D11: =Main!$D$11 | H11: Analysis Date : | K11: =Main!$K$11
V13: عينة الصحة
B14: Scoope :
C16: * Determine Chlorine dose for Effluent disinfection .
C17: * Standardize chlorine solution by Iodometric titration.
C18: * Measuring Residual Chlorine by HACH Pocket Colorimeter II .
B20: Sampling :
C22: * Chlorine Solution is collected from chlorine injector system.
C23: * Effluent is collected from final sedemtation.
C24: Chlorine demand | D24: 4.8 | E24: mg/L
B25: Results :
C27: mg Cl2 ( Dose ) | D27: =BreakPoint!E15 | E27: =BreakPoint!F15 | F27: =BreakPoint!G15 | G27: =BreakPoint!H15 | H27: =BreakPoint!I15 | I27: =BreakPoint!J15 | J27: =BreakPoint!K15 | K27: =BreakPoint!L15 | ... M27: =BreakPoint!N15
C28: ml of Cl2 in L | D28: =BreakPoint!E16 | E28: =BreakPoint!F16 | F28: =BreakPoint!G16 | G28: =BreakPoint!H16 | H28: =BreakPoint!I16 | I28: =BreakPoint!J16 | J28: =BreakPoint!K16 | K28: =BreakPoint!L16 | ... M28: =BreakPoint!N16
C29: ml of Cl2 in 250 ml | D29: =BreakPoint!E17 | E29: =BreakPoint!F17 | F29: =BreakPoint!G17 | G29: =BreakPoint!H17 | H29: =BreakPoint!I17 | I29: =BreakPoint!J17 | J29: =BreakPoint!K17 | K29: =BreakPoint!L17 | ... M29: =BreakPoint!N17
C30: Total Cl | D30: =BreakPoint!E18 | E30: =BreakPoint!F18 | F30: =BreakPoint!G18 | G30: =BreakPoint!H18 | H30: =BreakPoint!I18 | I30: =BreakPoint!J18 | J30: =BreakPoint!K18 | K30: =BreakPoint!L18 | ... M30: =BreakPoint!N18
C31: Temp | D31: =BreakPoint!E19 | E31: =BreakPoint!F19 | F31: =BreakPoint!G19 | G31: =BreakPoint!H19 | H31: =BreakPoint!I19 | I31: =BreakPoint!J19 | J31: =BreakPoint!K19 | K31: =BreakPoint!L19 | ... M31: =BreakPoint!N19
C32: PH | D32: =BreakPoint!E20 | E32: =BreakPoint!F20 | F32: =BreakPoint!G20 | G32: =BreakPoint!H20 | H32: =BreakPoint!I20 | I32: =BreakPoint!J20 | J32: =BreakPoint!K20 | K32: =BreakPoint!L20 | ... M32: =BreakPoint!N20
C33: Contact Time | D33: 20 min
C34: Residual chlorine | D34: 0.14
C35: Chlorine demand | D35: =BreakPoint!E25
C36: Chlorine Requirement | D36: 6.5 | E36: Chlorine Dose
B52: Analyzed by | J52: Reviewed by

Sheet TS & VS
A3: Holding Company | G3: الشركة القابضة
A4: Fayoum drinking Water and Sanitation Company | G4: شركة مياه الشرب والصرف الصحى بالفيوم
G5: قطاع المعامل - الادارة العامة لمعامل الصرف الصحى
A6: TOTAL SUSPENDED SOLIDS ( TS & VS ) WORK SHEET | D6: =Sulfide!D6 | F6: FORM ID:
A7: 20th EDITION, of The Standard Method for the Examination of Water and Wastewater | D7: =Sulfide!D7 | F7: SAMPLE DATE: | G7: =Main!D11
A8: PROCEDURE NUMBER 2450 B & 2540 G | D8: =Sulfide!D8 | F8: ANALYSIS DATE: | G8: =Main!K11 | L8: S.N. | M8: WEIGHT 1 | N8: Correcttion 1 | O8: Net weight 1 | P8: WEIGHT2 | Q8: Correcttion2 | R8: Net weight 2 | S8: WEIGHT3 | T8: Correcttion3 | U8: Net weight3
A9: (1) SAMPLE TYPE/ ID | C9: Influent | D9: Effluent | E9: Thickenner | F9: Influent | G9: Mix | H9: Mix | N9: =IFERROR(IF(ISBLANK(Table11[[#This Row],[S.N.]]),"",VLOOKUP(ROUND(Table11[[#This Row],[WEIGHT 1]],0),Radwag[],3,Radwag[[#This Row],[Weigh]])),"") | O9: =IFERROR(Table11[[#This Row],[WEIGHT 1]]+Table11[[#This Row],[Correcttion 1]],"") | Q9: =IFERROR(IF(ISBLANK(Table11[[#This Row],[WEIGHT2]]),"",VLOOKUP(ROUND(Table11[[#This Row],[WEIGHT2]],0),Radwag[],3,Radwag[[#This Row],[Weigh]])),"") | R9: =IFERROR(Table11[[#This Row],[WEIGHT2]]+Table11[[#This Row],[Correcttion2]],"") | T9: =IFERROR(IF(ISBLANK(Table11[[#This Row],[WEIGHT3]]),"",VLOOKUP(ROUND(Table11[[#This Row],[WEIGHT3]],0),Radwag[],3,Radwag[[#This Row],[Weigh]])),"") | U9: =IFERROR(Table11[[#This Row],[WEIGHT3]]+Table11[[#This Row],[Correcttion3]],"")
A10: (2) CRUCIBLE NUMBER | C10: =IF(ISBLANK($L$9),"",$L$9) | D10: =IF(ISBLANK($L$10),"",$L$10) | E10: =IF(ISBLANK($L$11),"",$L$11) | F10: =IF(ISBLANK($L$12),"",$L$12) | G10: =IF(ISBLANK($L$13),"",$L$13) | H10: =IF(ISBLANK($L$14),"",$L$14) | N10: =IFERROR(IF(ISBLANK(Table11[[#This Row],[S.N.]]),"",VLOOKUP(ROUND(Table11[[#This Row],[WEIGHT 1]],0),Radwag[],3,Radwag[[#This Row],[Weigh]])),"") | O10: =IFERROR(Table11[[#This Row],[WEIGHT 1]]+Table11[[#This Row],[Correcttion 1]],"") | Q10: =IFERROR(IF(ISBLANK(Table11[[#This Row],[WEIGHT2]]),"",VLOOKUP(ROUND(Table11[[#This Row],[WEIGHT2]],0),Radwag[],3,Radwag[[#This Row],[Weigh]])),"") | R10: =IFERROR(Table11[[#This Row],[WEIGHT2]]+Table11[[#This Row],[Correcttion2]],"") | T10: =IFERROR(IF(ISBLANK(Table11[[#This Row],[WEIGHT3]]),"",VLOOKUP(ROUND(Table11[[#This Row],[WEIGHT3]],0),Radwag[],3,Radwag[[#This Row],[Weigh]])),"") | U10: =IFERROR(Table11[[#This Row],[WEIGHT3]]+Table11[[#This Row],[Correcttion3]],"")
A11: (3) SAMPLE VOLUME, ml | N11: =IFERROR(IF(ISBLANK(Table11[[#This Row],[S.N.]]),"",VLOOKUP(ROUND(Table11[[#This Row],[WEIGHT 1]],0),Radwag[],3,Radwag[[#This Row],[Weigh]])),"") | O11: =IFERROR(Table11[[#This Row],[WEIGHT 1]]+Table11[[#This Row],[Correcttion 1]],"") | Q11: =IFERROR(IF(ISBLANK(Table11[[#This Row],[WEIGHT2]]),"",VLOOKUP(ROUND(Table11[[#This Row],[WEIGHT2]],0),Radwag[],3,Radwag[[#This Row],[Weigh]])),"") | R11: =IFERROR(Table11[[#This Row],[WEIGHT2]]+Table11[[#This Row],[Correcttion2]],"") | T11: =IFERROR(IF(ISBLANK(Table11[[#This Row],[WEIGHT3]]),"",VLOOKUP(ROUND(Table11[[#This Row],[WEIGHT3]],0),Radwag[],3,Radwag[[#This Row],[Weigh]])),"") | U11: =IFERROR(Table11[[#This Row],[WEIGHT3]]+Table11[[#This Row],[Correcttion3]],"")
A12: (4) TARE WT. OF DRY CRUCIBLE /CRUCIBLE g | C12: =IF($C$10="","",IF(ISBLANK($O$9),"",$O$9)) | D12: =IF($D$10="","",IF(ISBLANK($O$10),"",$O$10)) | E12: =IF($E$10="","",IF(ISBLANK($O$11),"",$O$11)) | F12: =IF($F$10="","",IF(ISBLANK($O$12),"",$O$12)) | G12: =IF($G$10="","",IF(ISBLANK($O$13),"",$O$13)) | H12: =IF($H$10="","",IF(ISBLANK($O$14),"",$O$14)) | N12: =IFERROR(IF(ISBLANK(Table11[[#This Row],[S.N.]]),"",VLOOKUP(ROUND(Table11[[#This Row],[WEIGHT 1]],0),Radwag[],3,Radwag[[#This Row],[Weigh]])),"") | O12: =IFERROR(Table11[[#This Row],[WEIGHT 1]]+Table11[[#This Row],[Correcttion 1]],"") | Q12: =IFERROR(IF(ISBLANK(Table11[[#This Row],[WEIGHT2]]),"",VLOOKUP(ROUND(Table11[[#This Row],[WEIGHT2]],0),Radwag[],3,Radwag[[#This Row],[Weigh]])),"") | R12: =IFERROR(Table11[[#This Row],[WEIGHT2]]+Table11[[#This Row],[Correcttion2]],"") | T12: =IFERROR(IF(ISBLANK(Table11[[#This Row],[WEIGHT3]]),"",VLOOKUP(ROUND(Table11[[#This Row],[WEIGHT3]],0),Radwag[],3,Radwag[[#This Row],[Weigh]])),"") | U12: =IFERROR(Table11[[#This Row],[WEIGHT3]]+Table11[[#This Row],[Correcttion3]],"")
A13: (5) WT. OF DRY CRUCIBLE / ASH CRUCIBLE g | C13: =IF($C$10="","",IF(ISBLANK($U$9),"",$U$9)) | D13: =IF($D$10="","",IF(ISBLANK($U$10),"",$U$10)) | E13: =IF($E$10="","",IF(ISBLANK($U$11),"",$U$11)) | F13: =IF($F$10="","",IF(ISBLANK($U$12),"",$U$12)) | G13: =IF($G$10="","",IF(ISBLANK($U$13),"",$U$13)) | H13: =IF($H$10="","",IF(ISBLANK($U$14),"",$U$14)) | N13: =IFERROR(IF(ISBLANK(Table11[[#This Row],[S.N.]]),"",VLOOKUP(ROUND(Table11[[#This Row],[WEIGHT 1]],0),Radwag[],3,Radwag[[#This Row],[Weigh]])),"") | O13: =IFERROR(Table11[[#This Row],[WEIGHT 1]]+Table11[[#This Row],[Correcttion 1]],"") | Q13: =IFERROR(IF(ISBLANK(Table11[[#This Row],[WEIGHT2]]),"",VLOOKUP(ROUND(Table11[[#This Row],[WEIGHT2]],0),Radwag[],3,Radwag[[#This Row],[Weigh]])),"") | R13: =IFERROR(Table11[[#This Row],[WEIGHT2]]+Table11[[#This Row],[Correcttion2]],"") | T13: =IFERROR(IF(ISBLANK(Table11[[#This Row],[WEIGHT3]]),"",VLOOKUP(ROUND(Table11[[#This Row],[WEIGHT3]],0),Radwag[],3,Radwag[[#This Row],[Weigh]])),"") | U13: =IFERROR(Table11[[#This Row],[WEIGHT3]]+Table11[[#This Row],[Correcttion3]],"")
A14: (6) WT. OF DRY SOLIDS/ VOLATILE SOLIDS, g = (5) - ( 4) | C14: =IFERROR(IF(C13="","",C13-C12),"") | D14: =IFERROR(IF(D13="","",D13-D12),"") | E14: =IFERROR(IF(E13="","",E13-E12),"") | F14: =IFERROR(IF(F10="","",ABS(F13-F12)),"") | G14: =IFERROR(IF(G10="","",ABS(G13-G12)),"") | H14: =IFERROR(IF(H10="","",ABS(H13-H12)),"") | N14: =IFERROR(IF(ISBLANK(Table11[[#This Row],[S.N.]]),"",VLOOKUP(ROUND(Table11[[#This Row],[WEIGHT 1]],0),Radwag[],3,Radwag[[#This Row],[Weigh]])),"") | O14: =IFERROR(Table11[[#This Row],[WEIGHT 1]]+Table11[[#This Row],[Correcttion 1]],"") | Q14: =IFERROR(IF(ISBLANK(Table11[[#This Row],[WEIGHT2]]),"",VLOOKUP(ROUND(Table11[[#This Row],[WEIGHT2]],0),Radwag[],3,Radwag[[#This Row],[Weigh]])),"") | R14: =IFERROR(Table11[[#This Row],[WEIGHT2]]+Table11[[#This Row],[Correcttion2]],"") | T14: =IFERROR(IF(ISBLANK(Table11[[#This Row],[WEIGHT3]]),"",VLOOKUP(ROUND(Table11[[#This Row],[WEIGHT3]],0),Radwag[],3,Radwag[[#This Row],[Weigh]])),"") | U14: =IFERROR(Table11[[#This Row],[WEIGHT3]]+Table11[[#This Row],[Correcttion3]],"")
A15: (7) TS / VS = mg/l (6) X 1,000,000 / (3) | C15: =IFERROR(IF(C13="","",C14*1000000/C11),"") | D15: =IFERROR(IF(D13="","",D14*1000000/D11),"") | E15: =IFERROR(IF(E13="","",E14*1000000/E11),"") | F15: =IFERROR(IF(F12<2,"",F14*1000000/F11),"") | G15: =IFERROR(IF(G12<2,"",G14*1000000/G11),"") | H15: =IFERROR(IF(H13="","",H14*1000000/H11),"") | N15: =IFERROR(IF(ISBLANK(Table11[[#This Row],[S.N.]]),"",VLOOKUP(ROUND(Table11[[#This Row],[WEIGHT 1]],0),Radwag[],3,Radwag[[#This Row],[Weigh]])),"") | O15: =IFERROR(Table11[[#This Row],[WEIGHT 1]]+Table11[[#This Row],[Correcttion 1]],"") | Q15: =IFERROR(IF(ISBLANK(Table11[[#This Row],[WEIGHT2]]),"",VLOOKUP(ROUND(Table11[[#This Row],[WEIGHT2]],0),Radwag[],3,Radwag[[#This Row],[Weigh]])),"") | R15: =IFERROR(Table11[[#This Row],[WEIGHT2]]+Table11[[#This Row],[Correcttion2]],"") | T15: =IFERROR(IF(ISBLANK(Table11[[#This Row],[WEIGHT3]]),"",VLOOKUP(ROUND(Table11[[#This Row],[WEIGHT3]],0),Radwag[],3,Radwag[[#This Row],[Weigh]])),"") | U15: =IFERROR(Table11[[#This Row],[WEIGHT3]]+Table11[[#This Row],[Correcttion3]],"")
A16: (8) % VOLATILE = VS x 100 / TS | G16: =IFERROR(($G$15/TSS!G27),"") | H16: =IFERROR(($G$15/TSS!H27),"")
A17: (9)Thickenner TS% | E17: =IFERROR(IF(E13="","",(U11-O11)/(R11-O11)),"")
D18: Influent | E18: Effluent | F18: Thickenner | G18: Mix | H18: RAS
C19: Gravimetry | D19: =IF(C13>0,HLOOKUP(D18,$C$9:$H$15,7,FALSE),"") | E19: =IF(D13>0,HLOOKUP(E18,$C$9:$H$15,7,FALSE),"") | F19: =IF(E13>0,HLOOKUP(F18,$C$9:$H$15,7,FALSE),"") | G19: NO | H19: NO
C20: Centrifuge | G20: =IF(TSS!G21="","",IF(0.6<=TSS!G21,"True","False")) | H20: =IF(TSS!H21="","",IF(0.6<=TSS!H21,"True","False"))
D21: =IFERROR(IF(D20>0,D20,D19),"") | E21: =IFERROR(IF(E20>0,E20,E19),"") | F21: =IFERROR(IF(F20>0,F20,F19),"") | G21: =IFERROR(IF(G13="",TSS!G20,IF(G20>0,G20,G20)),"") | H21: =IFERROR(IF(G13="",TSS!H20,IF(H20>0,H20,H20)),"")
H24: رجوع

Sheet TSS
A6: Holding Company | G6: الشركة القابضة
A7: Fayoum drinking Water and Sanitation Company | G7: شركة مياه الشرب والصرف الصحى بالفيوم
G8: قطاع المعامل - الادارة العامة لمعامل الصرف الصحى
A10: WASTWATER TREATMENT PLANT LABORATORY
A11: TOTAL SUSPENDED SOLIDS ( TSS ) WORK SHEET | D11: =Sulfide!D6 | F11: FORM ID:
A12: 20th EDITION, of The Standard Method for the Examination of Water and Wastewater | D12: =Sulfide!D7 | F12: SAMPLE DATE: | G12: =Main!D11
A13: PROCEDURE NUMBER 2450 D | D13: =Sulfide!D8 | F13: ANALYSIS DATE: | G13: =Main!K11
A14: (1) SAMPLE TYPE/ ID | C14: Influent | D14: Mixed Liquor | E14: RAS | F14: Effluent | G14: =IF(G15="","",D14) | H14: =IF(H15="","",E14)
A15: (2) FILTER NUMBER | G15: =IFERROR(IF('TS & VS'!G19="YES",IF('TS & VS'!G15="",IF(D15="","",D15),""),""),"") | H15: =IFERROR(IF('TS & VS'!H19="YES",IF('TS & VS'!H15="",IF(E15="","",E15),""),""),"")
A16: (3) SAMPLE VOLUME, ml | G16: =IFERROR(IF(G15="","",IF(D16="","",D16)),"") | H16: =IFERROR(IF(H15="","",IF(E16="","",E16)),"")
A17: (4) TARE WT. OF FILTER, g | G17: =IFERROR(IF(G15="","",IF(D18="","",D18)),"") | H17: =IFERROR(IF(H15="","",IF(E18="","",E18)),"")
A18: (5) WT. OF DRY FILTER, g
A19: (6) WT. OF DRY SOLIDS, g = (5) - ( 4) | C19: =IFERROR(IF(C18="","",C18-C17),"") | D19: =IFERROR(IF(D18="","",D18-D17),"") | E19: =IFERROR(IF(E18="","",E18-E17),"") | F19: =IFERROR(IF(F18="","",F18-F17),"") | G19: =IFERROR(IF(G15="","",ABS(G18-G17)),"") | H19: =IFERROR(IF(H15="","",ABS(H18-H17)),"")
A20: (7) TSS = mg/l (6) X 1,000,000 / (3) | C20: =IFERROR(IF(C18="","",C19*1000000/C16),"") | D20: =IFERROR(IF(D18="","",D19*1000000/D16),"") | E20: =IFERROR(IF(E18="","",E19*1000000/E16),"") | F20: =IFERROR(IF(F18="","",F19*1000000/F16),"") | G20: =IFERROR(IF(G18="","",G19*1000000/G16),"") | H20: =IFERROR(IF(H18="","",H19*1000000/H16),"")
A21: (8) % VOLATILE = VS x 100 / TS | G21: =IFERROR(($G$20/TSS!F27),"") | H21: =IFERROR(($H$20/TSS!G27),"")
E24: Influent | F24: Mixed Liquor | G24: RAS | H24: Effluent
D25: Gravimetry | E25: =IF(C18>0,C20,"") | F25: =IF(D18>0,D20,"") | G25: =IF(E18>0,E20,"") | H25: =IF(F18>0,F20,"")
D26: Centrifuge
E27: =IFERROR(IF(E26>0,E26,E25),"") | F27: =IFERROR(IF(F26>0,F26,F25),"") | G27: =IFERROR(IF(G26>0,G26,G25),"") | H27: =IFERROR(IF(H26>0,H26,H25),"")
H30: رجوع

Sheet TDS
A6: Holding Company | G6: الشركة القابضة | J6: Original | K6: Supposed
A7: Fayoum drinking Water and Sanitation Company | G7: شركة مياه الشرب والصرف الصحى بالفيوم | J7: F | L7: Influent | M7: Effluent | P7: ACCEPTED RANGE | T7: Original | U7: Supposed
G8: قطاع المعامل - الادارة العامة لمعامل الصرف الصحى | I8: Influent Factor | J8: 0.75 | K8: =IFERROR(IF(F23=0,"",$F$23*$J$8/(J8*$F$24)),"") | L8: =IFERROR($F$24*$K$8/$J$8,"") | M8: =IFERROR($G$24*$K$8/$J$8,"") | P8: F | Q8: Influent | R8: Effluent | S8: Conductivity
A9: WASTWATER TREATMENT PLANT LABORATORY | I9: Effluent Factor | J9: 0.35 | K9: =IFERROR(IF(G24=0,"",$G$23*$J$9/(J9*$G$24)),"") | O9: From | P9: =IFERROR($J$8+($J$8*0.05),"") | Q9: =$F$24*$P$9/$J$8 | R9: =$G$24*$P$9/$J$8 | T9: 1208
A10: TOTAL SUSPENDED SOLIDS ( TDS ) WORK SHEET | D10: =Sulfide!D6 | F10: FORM ID: | I10: DW Factor | J10: 0.354 | O10: To | P10: =IFERROR($J$8-($J$8*0.05),"") | Q10: =$F$24*$P$10/$J$8 | R10: =$G$24*$P$10/$J$8
A11: 20th EDITION, of The Standard Method for the Examination of Water and Wastewater | D11: =Sulfide!D7 | F11: SAMPLE DATE: | G11: =Main!D11 | P11: =IFERROR(IF(K8="","",AND(IF((AVERAGE(J8:K8)-AVERAGE(J8:K8)*0.05)<=$K$8,TRUE,FALSE),IF($K$8<=(AVERAGE(J8:K8)+AVERAGE(J8:K8)*0.05),TRUE,FALSE))),"") | Q11: =IFERROR(IF(F25="","",AND(IF(F25<=Q9,TRUE,FALSE),IF(Q10<=F25,TRUE,FALSE))),"") | R11: =IFERROR(IF(G25="","",AND(IF(G25<=R9,TRUE,FALSE),IF(R10<=G25,TRUE,FALSE))),"")
A12: PROCEDURE NUMBER 2450 C | D12: =Sulfide!D8 | F12: ANALYSIS DATE: | G12: =Main!K11
A13: (1) SAMPLE TYPE/ ID | C13: influent | D13: effluent | E13: standard | F13: stanard | J13: S.N. | K13: WEIGHT 1 | L13: Correcttion 1 | M13: Net weight 1 | N13: WEIGHT2 | O13: Correcttion2 | P13: Net weight2
A14: (2)CRUCIBLE NUMBER | C14: =IF(ISBLANK($J$14),"",$J$14) | D14: =IF(ISBLANK($J$15),"",$J$15) | E14: =IF(ISBLANK($J$16),"",$J$16) | F14: =IF(ISBLANK($J$17),"",$J$17) | G14: =IF(ISBLANK($J$18),"",$J$18) | H14: =IF(ISBLANK($J$19),"",$J$19) | L14: =IFERROR(IF(ISBLANK(Table1113[[#This Row],[WEIGHT 1]]),"",VLOOKUP(ROUND(Table1113[[#This Row],[WEIGHT 1]],0),Radwag[],3,Radwag[[#This Row],[Weigh]])),"") | M14: =IFERROR(Table1113[[#This Row],[WEIGHT 1]]+Table1113[[#This Row],[Correcttion 1]],"") | O14: =IFERROR(IF(ISBLANK(Table1113[[#This Row],[WEIGHT2]]),"",VLOOKUP(ROUND(Table1113[[#This Row],[WEIGHT2]],0),Radwag[],3,Radwag[[#This Row],[Weigh]])),"") | P14: =IFERROR(Table1113[[#This Row],[WEIGHT2]]+Table1113[[#This Row],[Correcttion2]],"")
A15: (3) SAMPLE VOLUME, ml | L15: =IFERROR(IF(ISBLANK(Table1113[[#This Row],[WEIGHT 1]]),"",VLOOKUP(ROUND(Table1113[[#This Row],[WEIGHT 1]],0),Radwag[],3,Radwag[[#This Row],[Weigh]])),"") | M15: =IFERROR(Table1113[[#This Row],[WEIGHT 1]]+Table1113[[#This Row],[Correcttion 1]],"") | O15: =IFERROR(IF(ISBLANK(Table1113[[#This Row],[WEIGHT2]]),"",VLOOKUP(ROUND(Table1113[[#This Row],[WEIGHT2]],0),Radwag[],3,Radwag[[#This Row],[Weigh]])),"") | P15: =IFERROR(Table1113[[#This Row],[WEIGHT2]]+Table1113[[#This Row],[Correcttion2]],"")
A16: (4) TARE WT. OF CRUCIBLE g | C16: =IF($C$14="","",$M$14) | D16: =IF($D$14="","",$M$15) | E16: =IF($E$14="","",$M$16) | F16: =IF($F$14="","",$M$17) | G16: =IF($G$14="","",$M$18) | H16: =IF($H$14="","",$M$19) | L16: =IFERROR(IF(ISBLANK(Table1113[[#This Row],[WEIGHT 1]]),"",VLOOKUP(ROUND(Table1113[[#This Row],[WEIGHT 1]],0),Radwag[],3,Radwag[[#This Row],[Weigh]])),"") | M16: =IFERROR(Table1113[[#This Row],[WEIGHT 1]]+Table1113[[#This Row],[Correcttion 1]],"") | O16: =IFERROR(IF(ISBLANK(Table1113[[#This Row],[WEIGHT2]]),"",VLOOKUP(ROUND(Table1113[[#This Row],[WEIGHT2]],0),Radwag[],3,Radwag[[#This Row],[Weigh]])),"") | P16: =IFERROR(Table1113[[#This Row],[WEIGHT2]]+Table1113[[#This Row],[Correcttion2]],"")
A17: (5) WT. OF DRY DISH g | C17: =IF($C$14="","",$P$14) | D17: =IF($D$14="","",$P$15) | E17: =IF($E$14="","",$P$16) | F17: =IF($F$14="","",$P$17) | G17: =IF($G$14="","",$P$18) | H17: =IF($H$14="","",$P$19) | L17: =IFERROR(IF(ISBLANK(Table1113[[#This Row],[WEIGHT 1]]),"",VLOOKUP(ROUND(Table1113[[#This Row],[WEIGHT 1]],0),Radwag[],3,Radwag[[#This Row],[Weigh]])),"") | M17: =IFERROR(Table1113[[#This Row],[WEIGHT 1]]+Table1113[[#This Row],[Correcttion 1]],"") | O17: =IFERROR(IF(ISBLANK(Table1113[[#This Row],[WEIGHT2]]),"",VLOOKUP(ROUND(Table1113[[#This Row],[WEIGHT2]],0),Radwag[],3,Radwag[[#This Row],[Weigh]])),"") | P17: =IFERROR(Table1113[[#This Row],[WEIGHT2]]+Table1113[[#This Row],[Correcttion2]],"")
A18: (6) WT. OF DRY SOLIDS, g = (5) - ( 4) | C18: =IFERROR(IF(C17="","",C17-C16),"") | D18: =IFERROR(IF(D17="","",D17-D16),"") | E18: =IFERROR(IF(E17="","",E17-E16),"") | F18: =IFERROR(IF(F17="","",F17-F16),"") | G18: =IFERROR(IF(G17="","",G17-G16),"") | H18: =IFERROR(IF(H17="","",H17-H16),"") | L18: =IFERROR(IF(ISBLANK(Table1113[[#This Row],[WEIGHT 1]]),"",VLOOKUP(ROUND(Table1113[[#This Row],[WEIGHT 1]],0),Radwag[],3,Radwag[[#This Row],[Weigh]])),"") | M18: =IFERROR(Table1113[[#This Row],[WEIGHT 1]]+Table1113[[#This Row],[Correcttion 1]],"") | O18: =IFERROR(IF(ISBLANK(Table1113[[#This Row],[WEIGHT2]]),"",VLOOKUP(ROUND(Table1113[[#This Row],[WEIGHT2]],0),Radwag[],3,Radwag[[#This Row],[Weigh]])),"") | P18: =IFERROR(Table1113[[#This Row],[WEIGHT2]]+Table1113[[#This Row],[Correcttion2]],"")
A19: (7) TDS = mg/l (6) X 1,000,000 / (3) | C19: =IFERROR(IF(C17="","",C18*1000000/C15),"") | D19: =IFERROR(IF(D17="","",D18*1000000/D15),"") | E19: =IFERROR(IF(E17="","",E18*1000000/E15)-IF($I$24="",$I$23,$I$24),"") | F19: =IFERROR(IF(F17="","",F18*1000000/F15)-IF($I$24="",$I$23,$I$24),"") | G19: =IFERROR(IF(G17="","",G18*1000000/G15),"") | H19: =IFERROR(IF(H17="","",H18*1000000/H15),"") | L19: =IFERROR(IF(ISBLANK(Table1113[[#This Row],[WEIGHT 1]]),"",VLOOKUP(ROUND(Table1113[[#This Row],[WEIGHT 1]],0),Radwag[],3,Radwag[[#This Row],[Weigh]])),"") | M19: =IFERROR(Table1113[[#This Row],[WEIGHT 1]]+Table1113[[#This Row],[Correcttion 1]],"") | O19: =IFERROR(IF(ISBLANK(Table1113[[#This Row],[WEIGHT2]]),"",VLOOKUP(ROUND(Table1113[[#This Row],[WEIGHT2]],0),Radwag[],3,Radwag[[#This Row],[Weigh]])),"") | P19: =IFERROR(Table1113[[#This Row],[WEIGHT2]]+Table1113[[#This Row],[Correcttion2]],"")
E20: =IFERROR(E19/($H$23*1000),"") | F20: =IFERROR(F19/($H$23*1000),"") | L20: =IFERROR(IF(ISBLANK(Table1113[[#This Row],[WEIGHT 1]]),"",VLOOKUP(ROUND(Table1113[[#This Row],[WEIGHT 1]],0),Radwag[],3,Radwag[[#This Row],[Weigh]])),"") | M20: =IFERROR(Table1113[[#This Row],[WEIGHT 1]]+Table1113[[#This Row],[Correcttion 1]],"") | O20: =IFERROR(IF(ISBLANK(Table1113[[#This Row],[WEIGHT2]]),"",VLOOKUP(ROUND(Table1113[[#This Row],[WEIGHT2]],0),Radwag[],3,Radwag[[#This Row],[Weigh]])),"") | P20: =IFERROR(Table1113[[#This Row],[WEIGHT2]]+Table1113[[#This Row],[Correcttion2]],"")
F22: Influent | G22: Effluent | H22: Standard | I22: DW
E23: TDS oven 180 | F23: =IF(C17>0,C19,"") | G23: =IF(D17>0,D19,"") | H23: 0.0679 | I23: =IFERROR(HLOOKUP($I$22,$C$13:$H$19,7,FALSE),"")
E24: Conductivity
E25: TDS | F25: =IFERROR(IF(AND(F23="",C14=""),$F$24*$J$8,F23)," ") | G25: =IFERROR(IF(AND(G23="",D14=""),$G$24*$J$9,G23)," ") | I25: =IFERROR(IF(AND(I23="",G14=""),$I$24*$J$10,I23)," ")
E26: Cond Efficiency | F26: =IFERROR(IF(F23="","",(J8*F24)/F25),"") | G26: =IFERROR(IF(G23="","",(J9*G24)/G25),"") | I26: =IFERROR(IF(I23="","",(J10*I24)/I25),"")
AZ27: Column1 | BA27: 15 | BB27: 16 | BC27: 17 | BD27: 18 | BE27: 19 | BF27: 20 | BG27: 21 | BH27: 22 | BI27: 23 | BJ27: 24 | BK27: 25 | BL27: 26 | BM27: 27 | BN27: 28 | BO27: 29 | BP27: 30
G28: رجوع | BA28: 15 | BB28: 16 | BC28: 17 | BD28: 18 | BE28: 19 | BF28: 20 | BG28: 21 | BH28: 22 | BI28: 23 | BJ28: 24 | BK28: 25 | BL28: 26 | BM28: 27 | BN28: 28 | BO28: 29 | BP28: 30
AZ29: 0 | BA29: 1147 | BB29: 1173 | BC29: 1199 | BD29: 1225 | BE29: 1251 | BF29: 1278 | BG29: 1305 | BH29: 1332 | BI29: 1359 | BJ29: 1386 | BK29: 1413 | BL29: 1440 | BM29: 1467 | BN29: 1494 | BO29: 1522 | BP29: 1549
AZ30: 0.1 | BA30: 1149.6 | BB30: 1175.6 | BC30: 1201.6 | BD30: 1227.6 | BE30: 1253.7 | BF30: 1280.7 | BG30: 1307.7 | BH30: 1334.7 | BI30: 1361.7 | BJ30: 1388.7 | BK30: 1415.7 | BL30: 1442.7 | BM30: 1469.7 | BN30: 1496.8 | BO30: 1524.7 | BP30: 1551.7
AZ31: 0.2 | BA31: 1152.2 | BB31: 1178.2 | BC31: 1204.2 | BD31: 1230.2 | BE31: 1256.4 | BF31: 1283.4 | BG31: 1310.4 | BH31: 1337.4 | BI31: 1364.4 | BJ31: 1391.4 | BK31: 1418.4 | BL31: 1445.4 | BM31: 1472.4 | BN31: 1499.6 | BO31: 1527.4 | BP31: 1554.4
AZ32: 0.3 | BA32: 1154.8 | BB32: 1180.8 | BC32: 1206.8 | BD32: 1232.8 | BE32: 1259.1 | BF32: 1286.1 | BG32: 1313.1 | BH32: 1340.1 | BI32: 1367.1 | BJ32: 1394.1 | BK32: 1421.1 | BL32: 1448.1 | BM32: 1475.1 | BN32: 1502.4 | BO32: 1530.1 | BP32: 1557.1
AZ33: 0.4 | BA33: 1157.4 | BB33: 1183.4 | BC33: 1209.4 | BD33: 1235.4 | BE33: 1261.8 | BF33: 1288.8 | BG33: 1315.8 | BH33: 1342.8 | BI33: 1369.8 | BJ33: 1396.8 | BK33: 1423.8 | BL33: 1450.8 | BM33: 1477.8 | BN33: 1505.2 | BO33: 1532.8 | BP33: 1559.8
AZ34: 0.5 | BA34: 1160 | BB34: 1186 | BC34: 1212 | BD34: 1238 | BE34: 1264.5 | BF34: 1291.5 | BG34: 1318.5 | BH34: 1345.5 | BI34: 1372.5 | BJ34: 1399.5 | BK34: 1426.5 | BL34: 1453.5 | BM34: 1480.5 | BN34: 1508 | BO34: 1535.5 | BP34: 1562.5
AZ35: 0.6 | BA35: 1162.6 | BB35: 1188.6 | BC35: 1214.6 | BD35: 1240.6 | BE35: 1267.2 | BF35: 1294.2 | BG35: 1321.2 | BH35: 1348.2 | BI35: 1375.2 | BJ35: 1402.2 | BK35: 1429.2 | BL35: 1456.2 | BM35: 1483.2 | BN35: 1510.8 | BO35: 1538.2 | BP35: 1565.2
AZ36: 0.7 | BA36: 1165.2 | BB36: 1191.2 | BC36: 1217.2 | BD36: 1243.2 | BE36: 1269.9 | BF36: 1296.9 | BG36: 1323.9 | BH36: 1350.9 | BI36: 1377.9 | BJ36: 1404.9 | BK36: 1431.9 | BL36: 1458.9 | BM36: 1485.9 | BN36: 1513.6 | BO36: 1540.9 | BP36: 1567.9
AZ37: 0.8 | BA37: 1167.8 | BB37: 1193.8 | BC37: 1219.8 | BD37: 1245.8 | BE37: 1272.6 | BF37: 1299.6 | BG37: 1326.6 | BH37: 1353.6 | BI37: 1380.6 | BJ37: 1407.6 | BK37: 1434.6 | BL37: 1461.6 | BM37: 1488.6 | BN37: 1516.4 | BO37: 1543.6 | BP37: 1570.6
AZ38: 0.9 | BA38: 1170.4 | BB38: 1196.4 | BC38: 1222.4 | BD38: 1248.4 | BE38: 1275.3 | BF38: 1302.3 | BG38: 1329.3 | BH38: 1356.3 | BI38: 1383.3 | BJ38: 1410.3 | BK38: 1437.3 | BL38: 1464.3 | BM38: 1491.3 | BN38: 1519.2 | BO38: 1546.3 | BP38: 1573.3
C39: Date | D39: Equipment | E39: Temp °c | F39: uS/cm | G39: Found uS/cm | H39: Re-read | I39: Remark
C40: =IF(Table9[[#This Row],[Temp °c]]="","",Main!$D$11) | D40: HACH | F40: =IFERROR(INDEX(conductivity[[15]:[30]],MATCH(ROUND(Table9[[#This Row],[Temp °c]]-TRUNC(Table9[[#This Row],[Temp °c]]),1),conductivity[Column1],0),MATCH(TRUNC(Table9[[#This Row],[Temp °c]]),$BA$28:$BP$28,0)),"") | I40: =IFERROR(IF(Table9[[#This Row],[Re-read]]="","",IF(ABS(Table9[[#This Row],[Re-read]]-Table9[[#This Row],[uS/cm]])>(0.08*Table9[[#This Row],[uS/cm]]),"Rejected","ACC")),"")
C41: =IF(Table9[[#This Row],[Temp °c]]="","",Main!$D$11) | D41: ORION | F41: =IFERROR(INDEX(conductivity[[15]:[30]],MATCH(ROUND(Table9[[#This Row],[Temp °c]]-TRUNC(Table9[[#This Row],[Temp °c]]),1),conductivity[Column1],0),MATCH(TRUNC(Table9[[#This Row],[Temp °c]]),$BA$28:$BP$28,0)),"") | I41: =IFERROR(IF(Table9[[#This Row],[Re-read]]="","",IF(ABS(Table9[[#This Row],[Re-read]]-Table9[[#This Row],[uS/cm]])>(0.08*Table9[[#This Row],[uS/cm]]),"Rejected","ACC")),"")
