Workbook
Name COD: #N/A
Name COD: #N/A

Sheet Main
B1: Holding Company | J1: الشركة القابضة
A3: Lab. Department | C3: Tamia sanitation plant | I3: قطاع المعامل - الادارة العامة لمعامل محطات الصرف الصحى
A6: Sampling Date | E6: Analysis Date
A9: Date | B9: PH | C9: Temp | D9: DO | E9: TS | F9: TDS | G9: TSS | H9: BOD | I9: COD | J9: S-2 | K9: O&G | L9: R.Cl
A10: influent | E10: =IFERROR(TS!D21,"") | F10: =IFERROR(E10-G10,"") | G10: =IFERROR(TSS!E27,"") | H10: =IFERROR(IF(BOD!D15<1,"NA",BOD!J29),"") | I10: =IFERROR(COD!L19,"") | J10: =IFERROR(Sulfide!C14,"") | K10: =IFERROR('O&G'!D21,"")
A11: Effluent | E11: =IFERROR(TS!E21,"") | F11: =IFERROR(E11-G11,"") | G11: =IFERROR(TSS!F27,"") | H11: =IFERROR(IF(BOD!D16<1,"NA",BOD!L29),"") | I11: =IFERROR(COD!K19,"") | J11: =IFERROR(Sulfide!D14,"") | K11: =IFERROR('O&G'!E21,"")
A12: MLSS | G12: =IFERROR(TSS!G27,"")
A14: Reviewed by | G14: Analyzed by

Sheet COD
P1: الشركة القابضة لمياة الشرب و الصرف الصحى
P2: قطاع المعامل
P3: الأدارة العامة لمعامل الصرف الصحى
A5: WASTWATER TREATMENT PLANT LABORATORY
A6: COD WORK SHEET | I6: SAMPLE DATE: | K6: =IFERROR(Main!B6,"") | M6: ANALYSIS DATE: | O6: =IFERROR(Main!G6,"")
A7: 20th EDITION, of The Standard Method for the Examination of Water and Wastewater | I7: TIME: ....................................................................
A8: PROCEDURE NUMBER 5220 D CLOSED REFLUX, COLORIMETRIC | I8: ANALYST : Ch/ Mohammad S. Alawamy
A9: (1) SAMPLE TYPE | C9: Influent | E9: Effluent
A10: (2) BOTTLE NUMBER | C10: 2 | D10: 3 | E10: 4 | F10: 5
A11: (3) SAMPLE VOLUME, ml | C11: 2.5 | D11: 2.5 | E11: 2.5 | F11: 2.5
A12: (4) DILUTION FACTOR = 2 / (3) | C12: 1 | D12: 1 | E12: 1 | F12: 1
A13: (5) COLORIMETER READING mg/l
A14: (6) COD mg/l = (5) x (4) | C14: =IFERROR(IF(C13="","",C13*C12),"") | D14: =IFERROR(IF(D13="","",D13*D12),"") | E14: =IFERROR(IF(E13="","",E13*E12),"") | F14: =IFERROR(IF(F13="","",F13*F12),"") | G14: =IFERROR(IF(G13="","",G13*G12),"") | H14: =IFERROR(IF(H13="","",H13*H12),"") | I14: =IFERROR(IF(I13="","",I13*I12),"") | J14: =IFERROR(IF(J13="","",J13*J12),"") | ... T14: =IFERROR(IF(T13="","",T13*T12),"")
A15: Average | C15: =IFERROR(IF(C13="","",IF(AND(C14="",D14=""),"ND",AVERAGE(C14:D14))),"") | E15: =IFERROR(IF(E13="","",IF(AND(E14="",F14=""),"ND",AVERAGE(E14:F14))),"") | G15: =IFERROR(IF(G13="","",IF(AND(G14="",H14=""),"ND",AVERAGE(G14:H14))),"") | I15: =IFERROR(IF(I13="","",IF(AND(I14="",J14=""),"ND",AVERAGE(I14:J14))),"") | K15: =IFERROR(IF(K13="","",IF(AND(K14="",L14=""),"ND",AVERAGE(K14:L14))),"") | M15: =IFERROR(IF(M13="","",IF(AND(M14="",N14=""),"ND",AVERAGE(M14:N14))),"") | O15: =IFERROR(IF(O13="","",IF(AND(O14="",P14=""),"ND",AVERAGE(O14:P14))),"") | Q15: =IFERROR(IF(Q13="","",IF(AND(Q14="",R14=""),"ND",AVERAGE(Q14:R14))),"") | S15: =IFERROR(IF(S13="","",IF(AND(S14="",T14=""),"ND",AVERAGE(S14:T14))),"")
A16: R | C16: =IFERROR(IF(C13="","",IF(AND(C14="",D14=""),"ND",ABS(C13-D13))),"") | E16: =IFERROR(IF(E13="","",IF(AND(E14="",F14=""),"ND",ABS(E13-F13))),"") | G16: =IFERROR(IF(G13="","",IF(AND(G14="",H14=""),"ND",ABS(G13-H13))),"") | I16: =IFERROR(IF(I13="","",IF(AND(I14="",J14=""),"ND",ABS(I13-J13))),"") | K16: =IFERROR(IF(K13="","",IF(AND(K14="",L14=""),"ND",ABS(K13-L13))),"") | M16: =IFERROR(IF(M13="","",IF(AND(M14="",N14=""),"ND",ABS(M13-N13))),"") | O16: =IFERROR(IF(O13="","",IF(AND(O14="",P14=""),"ND",ABS(O13-P13))),"") | Q16: =IFERROR(IF(Q13="","",IF(AND(Q14="",R14=""),"ND",ABS(Q13-R13))),"") | S16: =IFERROR(IF(S13="","",IF(AND(S14="",T14=""),"ND",ABS(S13-T13))),"")
A17: RPD | C17: =IFERROR(C16/AVERAGE(C13:D13),"") | E17: =IFERROR(E16/AVERAGE(E13:F13),"") | G17: =IFERROR(G16/AVERAGE(G13:H13),"") | I17: =IFERROR(I16/AVERAGE(I13:J13),"") | K17: =IFERROR(K16/AVERAGE(K13:L13),"") | M17: =IFERROR(M16/AVERAGE(M13:N13),"") | O17: =IFERROR(O16/AVERAGE(O13:P13),"") | Q17: =IFERROR(Q16/AVERAGE(Q13:R13),"") | S17: =IFERROR(S16/AVERAGE(S13:T13),"")
K18: LR | L18: HR
K19: =IFERROR(IF(E15="",IF(C31="",IF(E31="",C78,E31),C31),E15),"") | L19: =IFERROR(IF(C15="",IF(AND(B31="",D31=""),IF(B78="",D78,AVERAGE(B78,D78)),IF(B31="",D31,AVERAGE(B31,D31))),C15),"")
A22: تسجيل التجربة
K23: التخفيف
E24: REAGENT
B25: Influent HR | C25: Effluent ( 0 - 400 ) | D25: Influent LR | E25: Effluent ( 0 - 70 ) | G25: FAS | H25: Normality | AB25: Column1 | AC25: Ag2SO4 | AD25: H2SO4 | AE25: 1,10-phenanthroline monohydrate | AF25: FeSO4 7H2O | AG25: D.Water | AH25: Fe(NH4)2(SO4)2.6H2O | AI25: HgSO4 | AJ25: K2Cr2O7
A26: B | B26: 6.67 | C26: 2.65 | D26: =C26 | E26: 0.78 | H26: =(1.5/$C$26)*$X$72 | I26: =(1.5/$B$26)*$X$73 | J26: =(1.5/$E$26)*$X$76 | K26: العينة | L26: ماء مقطر | AB26: Sulfuric acid reagent | AC26: 5.5 g | AD26: 543.5 ml
A27: S1 | G27: V | H27: 2.5 | K27: 49 | M27: Influent HR | AB27: LR ( 0 - 400 ) 0.5 L | AD27: 83.5 | AG27: To 500 | AI27: 16.65 | AJ27: 2.4515 g
A28: COD | B28: =IF(B27="","",(IFERROR(((B26-B27)*$I$26*8000*$H$29)/$H$27,""))) | C28: =IF(C27="","",(IFERROR(((C26-C27)*$H$26*8000*$I$29)/$H$27,""))) | D28: =IF(D27="","",(IFERROR(((D26-D27)*$H$26*8000*$G$29)/H27,""))) | E28: =IF(E27="","",(IFERROR(((E26-E27)*$J$26*8000*$J$29)/$H$27,""))) | G28: Influent LR | H28: Influent HR | I28: effluent | J28: effluent | K28: 100 | M28: Effluent (0-400) | AB28: HR ( 100 - 900 ) 0.5 L | AD28: 83.5 | AG28: To 500 | AI28: 16.65 | AJ28: 5.108
A29: S2 | G29: =($L$29+$K$29)/$K$29 | H29: =($L$27+$K$27)/$K$27 | I29: =($L$28+$K$28)/$K$28 | J29: =($L$30+$K$30)/$K$30 | K29: 100 | M29: Influent LR | N29: 88.8879 | O29: 49 | P29: 1 | Q29: =N30 | AB29: LR ( 0 - 90 ) 0.5 L | AD29: 83.5 | AG29: To 500 | AI29: 16.65 | AJ29: 0.511
A30: COD | B30: =IF(B29="","",(IFERROR(((B26-B29)*$I$26*8000*$H$29)/$H$27,""))) | C30: =IF(C29="","",(IFERROR(((C26-C29)*$H$26*8000*$I$29)/$H$27,""))) | D30: =IF(D29="","",(IFERROR(((D26-D29)*$H$26*8000*$G$29)/$H$27,""))) | E30: =IF(E29="","",(IFERROR(((E26-E29)*$J$26*8000*$J$29)/$H$27,""))) | K30: 100 | M30: Effluent ( 0 - 70 ) | N30: =N29/O29 | P30: =P29/Q29*1000 | Q30: 1 | AB30: Ferroin indicator stock 100 ml | AE30: 1.485 g | AF30: 0.695 g | AG30: To 100
A31: Average | B31: =IF(B26="","",IF(OR(B30="",B30=0),IF(OR(B28="",B28=0),"",B28),AVERAGE(B28,B30))) | C31: =IF(C26="","",IF(OR(C30="",C30=0),IF(OR(C28="",C28=0),"",C28),AVERAGE(C28,C30))) | D31: =IF(D26="","",IF(OR(D30="",D30=0),IF(OR(D28="",D28=0),"",D28),AVERAGE(D28,D30))) | E31: =IF(E26="","",IF(OR(E30="",E30=0),IF(OR(E28="",E28=0),"",E28),AVERAGE(E28,E30))) | AB31: FAS 0.025 N | AD31: 2 ml | AG31: To 100 | AH31: 3.920 g
A32: STDV | B32: =IFERROR(STDEV(B28,B31),"") | C32: =IFERROR(STDEV(C28,C31),"") | D32: =IFERROR(STDEV(D28,D31),"") | E32: =IFERROR(STDEV(E28,E31),"") | AB32: FAS 0.0125 N | AD32: 2 ml | AG32: To 100 | AH32: 1.96 g
A33: r | B33: =IFERROR(2.8*B32,"") | C33: =IFERROR(2.8*C32,"") | D33: =IFERROR(2.8*D32,"") | E33: =IFERROR(2.8*E32,"") | AB33: FAS 0.025 N | AD33: 10 ml | AG33: To 500 | AH33: 19.6 g
A34: CV | B34: =IFERROR(B32/B31,"") | C34: =IFERROR(C32/C31,"") | D34: =IFERROR(D32/D31,"") | E34: =IFERROR(E32/E31,"") | M34: رجوع | N34: ورقة1!J16 | V34: 425 | W34: 250 | AB34: FAS 0.0125 N | AD34: 10 ml | AG34: To 500 | AH34: 9.8 g
A35: RPD | B35: =IFERROR((ABS(B28-B30))/AVERAGE(B28,B30),"") | C35: =IFERROR((ABS(C28-C30))/AVERAGE(C28,C30),"") | D35: =IFERROR((ABS(D28-D30))/AVERAGE(D28,D30),"") | E35: =IFERROR((ABS(E28-E30))/AVERAGE(E28,E30),"") | M35: ورقة1!J16 | N35: ورقة1!J16 | V35: =V34*W35/W34 | W35: 100 | AD35: =167/2 | AJ35: BACK
A36: RPD | B36: =IFERROR((ABS(B27-B29))/AVERAGE(B27,B29),"") | C36: =IFERROR((ABS(C27-C29))/AVERAGE(C27,C29),"") | D36: =IFERROR((ABS(D27-D29))/AVERAGE(D27,D29),"") | E36: =IFERROR((ABS(E27-E29))/AVERAGE(E27,E29),"") | M36: ورقة1!J16 | N36: ورقة1!J16
B37: Standard | C37: S1 | D37: S1R | E37: S2 | F37: S2R | G37: Mean | H37: STD | I37: r | J37: Precission | M37: ورقة1!J16 | N37: ورقة1!J16
B38: 70 ( 0 - 70 ) | D38: =IF(C38="","",IFERROR((($E$26-C38)*$J$26*8000)/$H$27,"")) | F38: =IF(E38="","",IFERROR((($E$26-E38)*$J$26*8000)/$H$27,"")) | G38: =IFERROR(AVERAGE(D38,F38),"") | H38: =IFERROR(STDEV(D38,F38),"") | I38: =IFERROR(2.8*H38,"") | J38: =IFERROR(H38/G38,"")
A39: Standards | B39: 10 ( 0 - 70 ) | D39: =IF(C39="","",IFERROR((($E$26-C39)*$J$26*8000)/$H$27,"")) | F39: =IF(E39="","",IFERROR((($E$26-E39)*$J$26*8000)/$H$27,"")) | G39: =IFERROR(AVERAGE(D39,F39),"") | H39: =IFERROR(STDEV(D39,F39),"") | I39: =IFERROR(2.8*H39,"") | J39: =IFERROR(H39/G39,"")
B40: 50 ( 50 - 400 ) | D40: =IF(C40="","",IFERROR((($C$26-C40)*$H$26*8000)/$H$27,"")) | F40: =IF(E40="","",IFERROR((($C$26-E40)*$H$26*8000)/$H$27,"")) | G40: =IFERROR(AVERAGE(D40,F40),"") | H40: =IFERROR(STDEV(D40,F40),"") | I40: =IFERROR(2.8*H40,"") | J40: =IFERROR(H40/G40,"")
B41: 90 ( 0 - 70 ) | D41: =IF(C41="","",IFERROR((($E$26-C41)*$J$26*8000)/$H$27,"")) | F41: =IF(E41="","",IFERROR((($E$26-E41)*$J$26*8000)/$H$27,"")) | G41: =IFERROR(AVERAGE(D41,F41),"") | H41: =IFERROR(STDEV(D41,F41),"") | I41: =IFERROR(2.8*H41,"") | J41: =IFERROR(H41/G41,"")
B42: 90 ( 50 - 400 ) | D42: =IF(C42="","",IFERROR((($C$26-C42)*$H$26*8000)/$H$27,"")) | F42: =IF(E42="","",IFERROR((($C$26-E42)*$H$26*8000)/$H$27,"")) | G42: =IFERROR(AVERAGE(D42,F42),"") | H42: =IFERROR(STDEV(D42,F42),"") | I42: =IFERROR(2.8*H42,"") | J42: =IFERROR(H42/G42,"")
B43: 120 ( 50 - 400 ) | D43: =IF(C43="","",IFERROR((($C$26-C43)*$H$26*8000)/$H$27,"")) | F43: =IF(E43="","",IFERROR((($C$26-E43)*$H$26*8000)/$H$27,"")) | G43: =IFERROR(AVERAGE(D43,F43),"") | H43: =IFERROR(STDEV(D43,F43),"") | I43: =IFERROR(2.8*H43,"") | J43: =IFERROR(H43/G43,"") | M43: Spike | N43: LR | O43: Spike | P43: HR | V43: Spike v | W43: 50
...

Sheet Sulfide
A3: Holding Company | G3: الشركة القابضة
A4: Fayoum drinking Water and Sanitation Company | G4: شركة مياه الشرب والصرف الصحى بالفيوم
G5: قطاع المعامل - الادارة العامة لمعامل الصرف الصحى
A6: SULFIDE (S2-) WORK SHEET | D6: PLANT: Kasr Rashwan | F6: FORM ID:
A7: 20th EDITION, of The Standard Method for the Examination of Water and Wastewater | D7: LAB ID: WWL03 | F7: SAMPLE DATE: | G7: =Main!B6
A8: PROCEDURE NUMBER 4500-S2- | D8: ANALYST:Ch/ Mohammad S. Alawamy | F8: ANALYSIS DATE: | G8: =Main!G6
A9: (1) SAMPLE TYPE/ ID | C9: Influent | D9: Effluent
A10: (2) Iodine VOLUME, ml | C10: 10 | D10: 10
A11: (3) SAMPLE VOLUME, ml | C11: 200 | D11: 200
A12: (4) Sodium Thiosulphate VOLUME, ml
A13: (5) Sodium Thiosulphate VOLUME, ml after correction | C13: =IFERROR(HLOOKUP($C$16,Dispenser8[#Data],MATCH(ROUND(C12,0),Dispenser8[[Column1]:[Column1]],0),FALSE)+C12,"") | D13: =IFERROR(HLOOKUP($C$16,Dispenser8[#Data],MATCH(ROUND(D12,0),Dispenser8[[Column1]:[Column1]],0),FALSE)+D12,"") | E13: =IFERROR(HLOOKUP($C$16,Dispenser8[#Data],MATCH(ROUND(E12,0),Dispenser8[[Column1]:[Column1]],0),FALSE)+E12,"") | F13: =IFERROR(HLOOKUP($C$16,Dispenser8[#Data],MATCH(ROUND(F12,0),Dispenser8[[Column1]:[Column1]],0),FALSE)+F12,"") | G13: =IFERROR(HLOOKUP($C$16,Dispenser8[#Data],MATCH(ROUND(G12,0),Dispenser8[[Column1]:[Column1]],0),FALSE)+G12,"") | H13: =IFERROR(HLOOKUP($C$16,Dispenser8[#Data],MATCH(ROUND(H12,0),Dispenser8[[Column1]:[Column1]],0),FALSE)+H12,"")
A14: (6) Sulfide S2- concentration | C14: =IFERROR(IF(C10="","",(C10*$C$23-C13*$D$23)*16000/C11),"") | D14: =IFERROR(IF(D10="","",(D10*$C$23-D13*$D$23)*16000/D11),"") | E14: =IFERROR(IF(E10="","",(E10*$C$23-E13*$D$23)*16000/E11),"") | F14: =IFERROR(IF(F10="","",(F10*$C$23-F13*$D$23)*16000/F11),"") | G14: =IFERROR(IF(G10="","",(G10*$C$23-G13*$D$23)*16000/G11),"") | H14: =IFERROR(IF(H10="","",(H10*$C$23-H13*$D$23)*16000/H11),"")
A16: Digital Burette | C16: 20G33740
A17: Standardization | M17: Solution | N17: Na2S2O3.5H2O | O17: NaOH | P17: I2 | Q17: KI | R17: D.Water | S17: KH(IO3)2 | T17: HCl
A18: Trials | C18: I2 | D18: Na2S2O3 | E18: Trials | M18: Sodium Thiosulfate 0.025 N | N18: 6.205 g | O18: 0.4 g | R18: 1000 ml
A19: Iodine Volume | C19: 10 | D19: 10 | E19: KH(IO3)2
A20: 1st trial with standardized Na2S2O3 | C20: 10 | D20: 10 | E20: 1st trial with KH(IO3)2 | M20: KH(IO3)2 0.0021M | R20: 1000 ml | S20: 0.812 g
A21: 2nd trial with standardized Na2S2O3 | C21: 10 | D21: 10 | E21: 2nd trial with KH(IO3)2 | M21: Iodine 0.025 N | P21: 3.2 g | Q21: 25 g | R21: 1000 ml
A22: 3rd trial with standardized Na2S2O3 | C22: 10 | D22: 10 | E22: 3rd trial with KH(IO3)2 | M22: HCL 6 N | R22: 1000 ml | T22: 500 ml
A23: Iodine Normality | C23: =IFERROR((AVERAGE(C20:C22)+HLOOKUP($C$17,Dispenser[],MATCH(ROUND(AVERAGE(C20:C22),0),Dispenser[Column1],0),FALSE))*(D23/C19),"") | D23: =IFERROR((AVERAGE(D20:D22)+HLOOKUP($C$17,Dispenser[],MATCH(ROUND(AVERAGE(D20:D22),0),Dispenser[Column1],0),FALSE))*0.00025*D19,"") | E23: Na2S2O3 Normality
H24: رجوع

Sheet BOD
P1: الشركة القابضة لمياة الشرب و الصرف الصحى
P2: قطاع المعامل
P3: الأدارة العامة لمعامل الصرف الصحى
A5: FAYOUM WASTWATER TREATMENT PLANT LABORATORY
A6: BOD5 WORK SHEET | H6: SAMPLE DATE: | J6: =IF(ISBLANK(Main!B6),"",Main!B6) | L6: ANALYSIS DATE: | N6: =IFERROR(J6+K7,"")
A7: 18th EDITION, of The Standard Method for the Examination of Water and Wastewater | H7: TIME: | J7: 0.47916667 | K7: 0 | L7: 0 DAY DO DATE: | N7: =N6
A8: PROCEDURE NUMBER 5210 B | H8: TIME: | J8: 0.4375 | L8: 5 DAY DO DATE: | N8: =IFERROR(N7+5,"")
A9: =IF(ISBLANK(J7),"",CONCATENATE(TEXT($J$7,"H:MM:ss AM/PM")& " INCUBATOR TEMPERATURE, DO1 ")) | B9: 19.6 | D9: V | H9: ANALYST: | J9: Mohamad S. Alawamy | R9: PH
A10: =IF(ISBLANK(J8),"",CONCATENATE(TEXT($J$8,"H:MM:ss AM/PM")& " INCUBATOR TEMPERATURE, DO5 ")) | B10: 20.7 | D10: 300 | H10: W seeding | Q10: Influent | R10: =Main!E16
A11: (1) SAMPLE TYPE | B11: BLANK | D11: Influent | F11: Effluent | H11: =IFERROR(IF(P17="","",CONCATENATE($D$11," ","+"," ",$P$17)),"") | J11: =IFERROR(IF(P17="","",CONCATENATE($F$11," ","+"," ",$P$17)),"") | L11: =IFERROR(IF(OR($J$13="",$L$13=""),"",IF($J$13=6,"influent+ Spike 6","influent++ Spike 5")),"") | N11: =IFERROR(IF(OR($J$13="",$N$13=""),"",IF($J$13=6,"Effluent+ Spike 6","Effluent+ Spike 5")),"") | P11: Seeding | Q11: effluent | R11: =Main!E18
A12: (2) BOTTLE NUMBER
A13: (3) SAMPLE VOLUME, ml | Q13: =Q14*T14/U14 | R13: =R14*T14/U14
A14: (4) DILUTION FACTOR = 300 / (3) | D14: =IFERROR($D$10/D13,"") | E14: =IFERROR($D$10/E13,"") | F14: =IFERROR($D$10/F13,"") | G14: =IFERROR($D$10/G13,"") | H14: =IFERROR($D$10/H13,"") | I14: =IFERROR($D$10/I13,"") | J14: =IFERROR($D$10/J13,"") | K14: =IFERROR($D$10/K13,"") | ... O14: =IFERROR($D$10/O13,"") | P14: =IFERROR(300/P13,"") | Q14: 5 | R14: 10 | S14: Inf | T14: 8 | U14: 100
A15: (5) INITIAL DO, mg/l | Q15: 5 | R15: 10 | S15: Eff | T15: 6.5 | U15: 25
A16: (6) 5- DAY DO, mg/l * | P16: V | Q16: =Q15*T15/U15 | R16: =R15*T15/U15
A17: (7) DO DEPLETION, mg/l = (5) - (6) ** | B17: =IFERROR(IF(B16="","",IF(B15<B16,0,B15-B16)),"") | C17: =IFERROR(IF(C16="","",IF(C15<C16,0,C15-C16)),"") | D17: =IFERROR(IF(D16>=1,D15-D16,""),"") | E17: =IFERROR(IF(E16>=1,E15-E16,""),"") | F17: =IFERROR(IF(F16>=1,F15-F16,""),"") | G17: =IFERROR(IF(G16>=1,G15-G16,""),"") | H17: =IFERROR(IF(H16>=1,H15-H16,""),"") | I17: =IFERROR(IF(I16>=1,I15-I16,""),"") | J17: =IFERROR(IF(J16>=1,J15-J16,""),"") | K17: =IFERROR(IF(K16>=1,K15-K16,""),"") | ... O17: =IFERROR(IF(O16>=1,O15-O16,""),"") | P17: 2
A18: (8) BLANK DEPLETION CORRECTION, mg/l = (11) of Blank, mg/l X DW, ml / 300 | D18: =IFERROR(IF(D13>0,IF(OR($B$17>0.2,$C$17>0.2),AVERAGE($B$17:$C$17)*($D$10-D13)/$D$10,"0"),""),"") | E18: =IFERROR(IF(E13>0,IF(OR($B$17>0.2,$C$17>0.2),AVERAGE($B$17:$C$17)*($D$10-E13)/$D$10,"0"),""),"") | F18: =IFERROR(IF(F13>0,IF(OR($B$17>0.2,$C$17>0.2),AVERAGE($B$17:$C$17)*($D$10-F13)/$D$10,"0"),""),"") | G18: =IFERROR(IF(G13>0,IF(OR($B$17>0.2,$C$17>0.2),AVERAGE($B$17:$C$17)*($D$10-G13)/$D$10,"0"),""),"") | H18: =IFERROR(IF(H13>0,IF(OR($B$17>0.2,$C$17>0.2),AVERAGE($B$17:$C$17)*($D$10-H13)/$D$10,"0"),""),"") | I18: =IFERROR(IF(I13>0,IF(OR($B$17>0.2,$C$17>0.2),AVERAGE($B$17:$C$17)*($D$10-I13)/$D$10,"0"),""),"") | J18: =IFERROR(IF(J13>0,IF(OR($B$17>0.2,$C$17>0.2),AVERAGE($B$17:$C$17)*($D$10-J13)/$D$10,"0"),""),"") | K18: =IFERROR(IF(K13>0,IF(OR($B$17>0.2,$C$17>0.2),AVERAGE($B$17:$C$17)*($D$10-K13)/$D$10,"0"),""),"") | ... O18: =IFERROR(IF(O13>0,IF(OR($B$17>0.2,$C$17>0.2),AVERAGE($B$17:$C$17)*($D$10-O13)/$D$10,"0"),""),"") | P18: =$D$10
A19: (9) DO CORRECTION = (7) - (8) | D19: =IFERROR(IF(D12>0,D17-D18,""),"") | E19: =IFERROR(IF(E12>0,E17-E18,""),"") | F19: =IFERROR(IF(F12>0,F17-F18,""),"") | G19: =IFERROR(IF(G12>0,G17-G18,""),"") | H19: =IFERROR(H17-(H18+$P$19),"") | I19: =IFERROR(I17-(I18+$P$19),"") | J19: =IFERROR(J17-(J18+$P$19),"") | K19: =IFERROR(K17-(K18+$P$19),"") | L19: =IFERROR(IF(L12>0,L17-L18,""),"") | M19: =IFERROR(IF(M12>0,M17-M18,""),"") | N19: =IFERROR(IF(N12>0,N17-N18,""),"") | O19: =IFERROR(IF(O12>0,O17-O18,""),"") | P19: =IFERROR((IF(Seeding!D21="",AVERAGE(Seeding!D23:I23)*BOD!P17,Seeding!D21*BOD!P17/BOD!P18)),"")
A20: (10) BOD5, mg/l = (9) X (4) | D20: =IFERROR(IF(D16>0,IF(D19>1.99,D19*D14,""),""),"") | E20: =IFERROR(IF(E16>0,IF(E19>1.99,E19*E14,""),""),"") | F20: =IFERROR(IF(F16>0,IF(F19>1.99,F19*F14,""),""),"") | G20: =IFERROR(IF(G16>0,IF(G19>1.99,G19*G14,""),""),"") | H20: =IFERROR(IF(H16>0,IF(H19>1.99,H19*H14,""),""),"") | I20: =IFERROR(IF(I16>0,IF(I19>1.99,I19*I14,""),""),"") | J20: =IFERROR(IF(J16>0,IF(J19>1.99,J19*J14,""),""),"") | K20: =IFERROR(IF(K16>0,IF(K19>1.99,K19*K14,""),""),"") | ... O20: =IFERROR(IF(O16>0,IF(O19>1.99,O19*O14,""),""),"")
A21: (11) BOD5 AVERAGE | D21: =IFERROR(AVERAGE(D20:E20),"") | F21: =IFERROR(AVERAGE(F20:G20),"") | H21: =IFERROR(AVERAGE(H20:I20),"") | J21: =IFERROR(AVERAGE(J20:K20),"") | L21: =IFERROR(AVERAGE(L20:M20),"") | N21: =IFERROR(AVERAGE(N20:O20),"")
A22: (12) BOD5 Correction | D22: =IFERROR(IF(OR(D17="",D20=""),(IF(D12>0,(D15-D16),""))*D14,""),"") | E22: =IFERROR(IF(OR(E17="",E20=""),(IF(E12>0,(E15-E16),""))*E14,""),"") | F22: =IFERROR(IF(OR(F17="",F20=""),(IF(F12>0,(F15-F16),""))*F14,""),"") | G22: =IFERROR(IF(OR(G17="",G20=""),(IF(G12>0,(G15-G16),""))*G14,""),"") | H22: =IFERROR(IF(OR(H17="",H20=""),(IF(H12>0,(H15-H16)-P19,""))*H14,""),"") | I22: =IFERROR(IF(OR(I17="",I20=""),(IF(I12>0,(I15-I16)-Q19,""))*I14,""),"") | J22: =IFERROR(J19*J14,"") | K22: =IFERROR(K19*K14,"") | L22: =IFERROR(L19*L14,"") | M22: =IFERROR(M19*M14,"") | N22: =IFERROR(N19*N14,"") | O22: =IFERROR(O19*O14,"") | P22: =IFERROR(IF(P16>0,IF(P19>=2,P19*P14,""),""),"")
A23: SPIKE recovery | L23: =IFERROR((L20-IF($D$21="","",$D$21))/((6*IF(AND(167.5<=$J$21,$J$21<=228.5),$J$21,198))/L13),"") | M23: =IFERROR((M20-IF($D$21="","",$D$21))/((6*IF(AND(167.5<=$J$21,$J$21<=228.5),$J$21,198))/M13),"") | N23: =IFERROR((N20-IF($F$21="",$H$21,$F$21))/((6*IF(AND(167.5<=$J$21,$J$21<=228.5),$J$21,198))/N13),"") | O23: =IFERROR((O20-IF($F$21="",$H$21,$F$21))/((6*IF(AND(167.5<=J21,J21<=228.5),J21,198))/O13),"")
A24: RPD | D24: =IFERROR(ABS(D20-E20)/D21,"") | F24: =IFERROR(ABS(F20-G20)/F21,"") | H24: =IFERROR(ABS(H20-I20)/H21,"") | J24: =IFERROR(ABS(J20-K20)/J21,"") | L24: =IFERROR(ABS(L20-M20)/L21,"") | N24: =IFERROR(ABS(N20-O20)/N21,"")
A25: * The residual 5-day-DO must be at least 1mg/l | B25: If less | C25: The BOD is greater than the higest DO
A26: ** 5-day-DO uptake 2 mg/l or greater | B26: If less | C26: The BOD is less than the lowest Dilution | J26: Influent | L26: effluent
A27: *** No depletion correction needed if DO depletion in the blank is less than 0.2 mg/l | J27: =IFERROR(IF($D$21="",$H$21,$D$21),"") | L27: =IFERROR(IF($F$21="",$J$21,$F$21),"")
A28: DW = Dilution Water | I28: Manometric
J29: =IFERROR(IF(AND(D17<2,E17<2,J28=""),"ND",IF(J28="",J27,J28)),"") | L29: =IFERROR(IF(AND(F17<2,G17<2,H17<2,I17<2,L28=""),"ND",IF(L28="",L27,L28)),"")
N30: رجوع
AA36: رجوع

Sheet Seeding
P1: الشركة القابضة لمياة الشرب و الصرف الصحى
P2: قطاع المعامل
P3: الأدارة العامة لمعامل الصرف الصحى
A5: FAYOUM WASTWATER TREATMENT PLANT LABORATORY
A6: BOD5 WORK SHEET | H6: SAMPLE DATE: | J6: =IF(ISBLANK(BOD!$J$6:$K$6),"",BOD!$J$6:$K$6) | L6: ANALYSIS DATE: | N6: =IFERROR(J6+K7,"")
A7: 18th EDITION, of The Standard Method for the Examination of Water and Wastewater | H7: TIME: | J7: =IFERROR(IF(BOD!J7="","",BOD!J7),"") | K7: =BOD!$K$7 | L7: 0 DAY DO DATE: | N7: =N6
A8: PROCEDURE NUMBER 5210 B | H8: TIME: | J8: =IFERROR(IF(BOD!J8="","",BOD!J8),"") | L8: 5 DAY DO DATE: | N8: =IFERROR(N7+5,"")
A9: =IFERROR(BOD!A9,"") | B9: =IFERROR(IF(ISBLANK(BOD!B9),"",BOD!B9),"") | D9: V | H9: ANALYST: | J9: Mohamad S. Alawamy
A10: =IFERROR(BOD!A10,"") | B10: =IFERROR(IF(ISBLANK(BOD!B10),"",BOD!B10),"") | D10: =BOD!D10 | H10: W seeding
A11: (1) SAMPLE TYPE | B11: BLANK | D11: Seeding | J11: Kafr Mahfooz | N11: Effluent spike | P11: Seeding
A12: (2) BOTTLE NUMBER | B12: =IFERROR(IF(BOD!B12="","",BOD!B12),"") | C12: =IFERROR(IF(BOD!C12="","",BOD!C12),"")
A13: (3) SAMPLE VOLUME, ml
A14: (4) DILUTION FACTOR = 300 / (3) | D14: =IFERROR($D$10/D13,"") | E14: =IFERROR($D$10/E13,"") | F14: =IFERROR($D$10/F13,"") | G14: =IFERROR($D$10/G13,"") | H14: =IFERROR($D$10/H13,"") | I14: =IFERROR($D$10/I13,"") | J14: =IFERROR($D$10/J13,"") | K14: =IFERROR($D$10/K13,"") | ... O14: =IFERROR($D$10/O13,"") | P14: =IFERROR(IF($D$21="",($E$22*$K$23/$P$18),($D$21*$K$23/$P$18)),"")
A15: (5) INITIAL DO, mg/l | B15: =IFERROR(IF(BOD!B15="","",BOD!B15),"") | C15: =IFERROR(IF(BOD!C15="","",BOD!C15),"") | P15: =IFERROR(IF($D$21="",($E$22*$L$23/$P$18),($D$21*$L$23/$P$18)),"")
A16: (6) 5- DAY DO, mg/l * | B16: =IFERROR(IF(BOD!B16="","",BOD!B16),"") | C16: =IFERROR(IF(BOD!C16="","",BOD!C16),"") | P16: V
A17: (7) DO DEPLETION, mg/l = (5) - (6) ** | B17: =IFERROR(IF(BOD!B17="","",BOD!B17),"") | C17: =IFERROR(IF(BOD!C17="","",BOD!C17),"") | D17: =IFERROR(IF(D16>=1,D15-D16,""),"") | E17: =IFERROR(IF(E16>=1,E15-E16,""),"") | F17: =IFERROR(IF(F16>=1,F15-F16,""),"") | G17: =IFERROR(IF(G16>=1,G15-G16,""),"") | H17: =IFERROR(IF(H16>=1,H15-H16,""),"") | I17: =IFERROR(IF(I16>=1,I15-I16,""),"") | J17: =IFERROR(IF(J16>=1,J15-J16,""),"") | K17: =IFERROR(IF(K16>=1,K15-K16,""),"") | ... O17: =IFERROR(IF(O16>=1,O15-O16,""),"") | P17: 2
A18: (8) BLANK DEPLETION CORRECTION, mg/l = (11) of Blank, mg/l X DW, ml / 300 | D18: =IFERROR(IF(D13>0,IF($B$17>0.2,AVERAGE($B$17:$C$17)*($D$10-D13)/$D$10,"0"),""),"") | E18: =IFERROR(IF(E13>0,IF($B$17>0.2,AVERAGE($B$17:$C$17)*($D$10-E13)/$D$10,"0"),""),"") | F18: =IFERROR(IF(F13>0,IF($B$17>0.2,AVERAGE($B$17:$C$17)*($D$10-F13)/$D$10,"0"),""),"") | G18: =IFERROR(IF(G13>0,IF($B$17>0.2,AVERAGE($B$17:$C$17)*($D$10-G13)/$D$10,"0"),""),"") | H18: =IFERROR(IF(H13>0,IF($B$17>0.2,AVERAGE($B$17:$C$17)*($D$10-H13)/$D$10,"0"),""),"") | I18: =IFERROR(IF(I13>0,IF($B$17>0.2,AVERAGE($B$17:$C$17)*($D$10-I13)/$D$10,"0"),""),"") | J18: =IFERROR(IF(J13>0,IF($B$17>0.2,AVERAGE($B$17:$C$17)*($D$10-J13)/$D$10,"0"),""),"") | K18: =IFERROR(IF(K13>0,IF($B$17>0.2,AVERAGE($B$17:$C$17)*($D$10-K13)/$D$10,"0"),""),"") | ... O18: =IFERROR(IF(O13>0,IF($B$17>0.2,AVERAGE($B$17:$C$17)*($D$10-O13)/$D$10,"0"),""),"") | P18: =$D$10
A19: (9) DO CORRECTION = (7) - (8) | D19: =IFERROR(IF(D12>0,D17-D18,""),"") | E19: =IFERROR(IF(E12>0,E17-E18,""),"") | F19: =IFERROR(IF(F12>0,F17-F18,""),"") | G19: =IFERROR(IF(G12>0,G17-G18,""),"") | H19: =IFERROR(IF(H12>0,H17-H18,""),"") | I19: =IFERROR(IF(I12>0,I17-I18,""),"") | J19: =IFERROR(IF(J12>0,J17-J18,""),"") | K19: =IFERROR(IF(K12>0,K17-K18,""),"") | ... M19: =IFERROR(IF(M12>0,M17-M18,""),"") | N19: =IFERROR(N17-(N18+$P$21),"") | O19: =IFERROR(O17-(O18+$P$23),"") | P19: =IFERROR(IF($D$21="",($E$22*$P$17/$P$18),($D$21*$P$17/$P$18)),"")
A20: (10) BOD5, mg/l = (9) X (4) | D20: =IFERROR(IF(D16>0,IF(D19>1.99,D19*D14,""),""),"") | E20: =IFERROR(IF(E16>0,IF(E19>1.99,E19*E14,""),""),"") | F20: =IFERROR(IF(F16>0,IF(F19>1.99,F19*F14,""),""),"") | G20: =IFERROR(IF(G16>0,IF(G19>1.99,G19*G14,""),""),"") | H20: =IFERROR(IF(H16>0,IF(H19>1.99,H19*H14,""),""),"") | I20: =IFERROR(IF(I16>0,IF(I19>1.99,I19*I14,""),""),"") | J20: =IFERROR(IF(J16>0,IF(J19>1.99,J19*J14,""),""),"") | K20: =IFERROR(IF(K16>0,IF(K19>1.99,K19*K14,""),""),"") | ... O20: =IFERROR(IF(O16>0,IF(O19>1.99,O19*O14,""),""),"") | P20: =IFERROR(IF($D$21="",($E$22*$M$23/$P$18),($D$21*$M$23/$P$18)),"")
A21: (11) BOD5 AVERAGE | D21: =IFERROR(AVERAGE(D20:I20),"") | J21: =IFERROR(AVERAGE(J20:K20),"") | L21: =IFERROR(AVERAGE(L20:M20),"") | N21: =IFERROR(AVERAGE(N20:O20),"") | P21: =IFERROR(IF($D$21="",($E$22*$N$23/$P$18),($D$21*$N$23/$P$18)),"")
A22: (12) BOD5 Correction | D22: =IFERROR(IF($D$16="","",IF(OR(D17="",D20=""),(IF(D12>0,(D15-D16),""))*D14,"")),"") | E22: =IFERROR(IF($D$16="","",IF(OR(E17="",E20=""),(IF(E12>0,(E15-E16),""))*E14,"")),"") | F22: =IFERROR(IF($D$16="","",IF(OR(F17="",F20=""),(IF(F12>0,(F15-F16),""))*F14,"")),"") | G22: =IFERROR(IF($D$16="","",IF(OR(G17="",G20=""),(IF(G12>0,(G15-G16),""))*G14,"")),"") | H22: =IFERROR(IF($D$16="","",IF(OR(H17="",H20=""),(IF(H12>0,(H15-H16),""))*H14,"")),"") | I22: =IFERROR(IF($D$16="","",IF(OR(I17="",I20=""),(IF(I12>0,(I15-I16),""))*I14,"")),"") | J22: =IFERROR(IF(H16="","",IF(OR(J17="",J20=""),(IF(J12>0,(J15-J16),""))*J14,"")),"") | K22: =IFERROR(IF(I16="","",IF(OR(K17="",K20=""),(IF(K12>0,(K15-K16),""))*K14,"")),"") | L22: =IFERROR(IF(J16="","",IF(OR(L17="",L20=""),(IF(L12>0,(L15-L16),""))*L14,"")),"") | M22: =IFERROR(IF(K16="","",IF(OR(M17="",M20=""),(IF(M12>0,(M15-M16),""))*M14,"")),"") | N22: =IFERROR(IF(L16="","",IF(OR(N17="",N20=""),(IF(N12>0,(N15-N16),""))*N14,"")),"") | O22: =IFERROR(IF(M16="","",IF(OR(O17="",O20=""),(IF(O12>0,(O15-O16),""))*O14,"")),"") | P22: =IFERROR(IF(P16>0,IF(P19>=2,P19*P14,""),""),"")
A23: ( 13 ) Seeding DO depletion/ml | D23: =IFERROR(IF(D19="","",D19/D13),"") | E23: =IFERROR(IF(E19="","",E19/E13),"") | F23: =IFERROR(IF(F19="","",F19/F13),"") | G23: =IFERROR(IF(G19="","",G19/G13),"") | H23: =IFERROR(IF(H19="","",H19/H13),"") | I23: =IFERROR(IF(I19="","",I19/I13),"") | J23: 2 | K23: 3 | L23: 4 | M23: 6 | P23: =IFERROR(IF($D$21="",($E$22*$O$23/$P$18),($D$21*$O$23/$P$18)),"")
A24: (14) LOD ( Limit of Detection ) = 2 mg DO/L X ( 4 ) | D24: =IFERROR(2*D14,"") | E24: =IFERROR(2*E14,"") | F24: =IFERROR(2*F14,"") | G24: =IFERROR(2*G14,"") | H24: =IFERROR(2*H14,"") | I24: =IFERROR(2*I14,"") | J24: =IFERROR(2*J14,"") | K24: =IFERROR(2*K14,"") | ... O24: =IFERROR(2*O14,"") | P24: =IFERROR(IF(P18>0,IF(P21>=2,P21*P16,""),""),"")
A25: RPD | D25: =IFERROR((MAX(D20:I20)-MIN(D20:I20))/D21,"")
A30: رجوع الى BOD | M30: رجوع

Sheet TS
A3: Holding Company | G3: الشركة القابضة
A4: Fayoum drinking Water and Sanitation Company | G4: شركة مياه الشرب والصرف الصحى بالفيوم
G5: قطاع المعامل - الادارة العامة لمعامل الصرف الصحى
A6: TOTAL SUSPENDED SOLIDS ( TS & VS ) WORK SHEET | D6: PLANT: Kasr Rashwan | F6: FORM ID:
A7: 20th EDITION, of The Standard Method for the Examination of Water and Wastewater | D7: LAB ID: WWL03 | F7: SAMPLE DATE: | G7: =Main!$B$6
A8: PROCEDURE NUMBER 2450 B & 2540 G | D8: ANALYST:Ch/ Mohammad S. Alawamy | F8: ANALYSIS DATE: | G8: =Main!G6 | L8: S.N. | M8: WEIGHT 1 | N8: Correcttion 1 | O8: Net weight 1 | P8: WEIGHT2 | Q8: Correcttion2 | R8: Net weight2
A9: (1) SAMPLE TYPE/ ID | C9: Influent | D9: Effluent | E9: Thickenner | F9: Influent | G9: Mix | H9: Mix | N9: =IFERROR(IF(ISBLANK(Table11[[#This Row],[S.N.]]),"",VLOOKUP(ROUND(Table11[[#This Row],[WEIGHT 1]],0),Radwag7[],3,Radwag7[[#This Row],[Weigh]])),"") | O9: =IFERROR(Table11[[#This Row],[WEIGHT 1]]+Table11[[#This Row],[Correcttion 1]],"") | Q9: =IFERROR(IF(ISBLANK(Table11[[#This Row],[WEIGHT2]]),"",VLOOKUP(ROUND(Table11[[#This Row],[WEIGHT2]],0),Radwag7[],3,Radwag7[[#This Row],[Weigh]])),"") | R9: =IFERROR(Table11[[#This Row],[WEIGHT2]]+Table11[[#This Row],[Correcttion2]],"")
A10: (2) CRUCIBLE NUMBER | C10: =IF(ISBLANK($L$9),"",$L$9) | D10: =IF(ISBLANK($L$10),"",$L$10) | E10: =IF(ISBLANK($L$11),"",$L$11) | F10: =IF(ISBLANK($L$12),"",$L$12) | G10: =IF(ISBLANK($L$13),"",$L$13) | H10: =IF(ISBLANK($L$14),"",$L$14) | N10: =IFERROR(IF(ISBLANK(Table11[[#This Row],[S.N.]]),"",VLOOKUP(ROUND(Table11[[#This Row],[WEIGHT 1]],0),Radwag7[],3,Radwag7[[#This Row],[Weigh]])),"") | O10: =IFERROR(Table11[[#This Row],[WEIGHT 1]]+Table11[[#This Row],[Correcttion 1]],"") | Q10: =IFERROR(IF(ISBLANK(Table11[[#This Row],[WEIGHT2]]),"",VLOOKUP(ROUND(Table11[[#This Row],[WEIGHT2]],0),Radwag7[],3,Radwag7[[#This Row],[Weigh]])),"") | R10: =IFERROR(Table11[[#This Row],[WEIGHT2]]+Table11[[#This Row],[Correcttion2]],"")
A11: (3) SAMPLE VOLUME, ml | N11: =IFERROR(IF(ISBLANK(Table11[[#This Row],[S.N.]]),"",VLOOKUP(ROUND(Table11[[#This Row],[WEIGHT 1]],0),Radwag7[],3,Radwag7[[#This Row],[Weigh]])),"") | O11: =IFERROR(Table11[[#This Row],[WEIGHT 1]]+Table11[[#This Row],[Correcttion 1]],"") | Q11: =IFERROR(IF(ISBLANK(Table11[[#This Row],[WEIGHT2]]),"",VLOOKUP(ROUND(Table11[[#This Row],[WEIGHT2]],0),Radwag7[],3,Radwag7[[#This Row],[Weigh]])),"") | R11: =IFERROR(Table11[[#This Row],[WEIGHT2]]+Table11[[#This Row],[Correcttion2]],"")
A12: (4) TARE WT. OF DRY CRUCIBLE /CRUCIBLE g | C12: =IF($C$10="","",IF(ISBLANK($O$9),"",$O$9)) | D12: =IF($D$10="","",IF(ISBLANK($O$10),"",$O$10)) | E12: =IF($E$10="","",IF(ISBLANK($O$11),"",$O$11)) | F12: =IF($F$10="","",IF(ISBLANK($O$12),"",$O$12)) | G12: =IF($G$10="","",IF(ISBLANK($O$13),"",$O$13)) | H12: =IF($H$10="","",IF(ISBLANK($O$14),"",$O$14)) | N12: =IFERROR(IF(ISBLANK(Table11[[#This Row],[S.N.]]),"",VLOOKUP(ROUND(Table11[[#This Row],[WEIGHT 1]],0),Radwag7[],3,Radwag7[[#This Row],[Weigh]])),"") | O12: =IFERROR(Table11[[#This Row],[WEIGHT 1]]+Table11[[#This Row],[Correcttion 1]],"") | Q12: =IFERROR(IF(ISBLANK(Table11[[#This Row],[WEIGHT2]]),"",VLOOKUP(ROUND(Table11[[#This Row],[WEIGHT2]],0),Radwag7[],3,Radwag7[[#This Row],[Weigh]])),"") | R12: =IFERROR(Table11[[#This Row],[WEIGHT2]]+Table11[[#This Row],[Correcttion2]],"")
A13: (5) WT. OF DRY CRUCIBLE / ASH CRUCIBLE g | C13: =IF($C$10="","",IF(ISBLANK($R$9),"",$R$9)) | D13: =IF($D$10="","",IF(ISBLANK($R$10),"",$R$10)) | E13: =IF($E$10="","",IF(ISBLANK($R$11),"",$R$11)) | F13: =IF($F$10="","",IF(ISBLANK($R$12),"",$R$12)) | G13: =IF($G$10="","",IF(ISBLANK($R$13),"",$R$13)) | H13: =IF($H$10="","",IF(ISBLANK($R$14),"",$R$14)) | N13: =IFERROR(IF(ISBLANK(Table11[[#This Row],[S.N.]]),"",VLOOKUP(ROUND(Table11[[#This Row],[WEIGHT 1]],0),Radwag7[],3,Radwag7[[#This Row],[Weigh]])),"") | O13: =IFERROR(Table11[[#This Row],[WEIGHT 1]]+Table11[[#This Row],[Correcttion 1]],"") | Q13: =IFERROR(IF(ISBLANK(Table11[[#This Row],[WEIGHT2]]),"",VLOOKUP(ROUND(Table11[[#This Row],[WEIGHT2]],0),Radwag7[],3,Radwag7[[#This Row],[Weigh]])),"") | R13: =IFERROR(Table11[[#This Row],[WEIGHT2]]+Table11[[#This Row],[Correcttion2]],"")
A14: (6) WT. OF DRY SOLIDS/ VOLATILE SOLIDS, g = (5) - ( 4) | C14: =IFERROR(IF(C13="","",C13-C12),"") | D14: =IFERROR(IF(D13="","",D13-D12),"") | E14: =IFERROR(IF(E13="","",E13-E12),"") | F14: =IFERROR(IF(F10="","",ABS(F13-F12)),"") | G14: =IFERROR(IF(G10="","",ABS(G13-G12)),"") | H14: =IFERROR(IF(H10="","",ABS(H13-H12)),"") | N14: =IFERROR(IF(ISBLANK(Table11[[#This Row],[S.N.]]),"",VLOOKUP(ROUND(Table11[[#This Row],[WEIGHT 1]],0),Radwag7[],3,Radwag7[[#This Row],[Weigh]])),"") | O14: =IFERROR(Table11[[#This Row],[WEIGHT 1]]+Table11[[#This Row],[Correcttion 1]],"") | Q14: =IFERROR(IF(ISBLANK(Table11[[#This Row],[WEIGHT2]]),"",VLOOKUP(ROUND(Table11[[#This Row],[WEIGHT2]],0),Radwag7[],3,Radwag7[[#This Row],[Weigh]])),"") | R14: =IFERROR(Table11[[#This Row],[WEIGHT2]]+Table11[[#This Row],[Correcttion2]],"")
A15: (7) TS / VS = mg/l (6) X 1,000,000 / (3) | C15: =IFERROR(IF(C13="","",C14*1000000/C11),"") | D15: =IFERROR(IF(D13="","",D14*1000000/D11),"") | E15: =IFERROR(IF(E13="","",E14*1000000/E11),"") | F15: =IFERROR(IF(F12<2,"",F14*1000000/F11),"") | G15: =IFERROR(IF(G12<2,"",G14*1000000/G11),"") | H15: =IFERROR(IF(H13="","",H14*1000000/H11),"") | N15: =IFERROR(IF(ISBLANK(Table11[[#This Row],[S.N.]]),"",VLOOKUP(ROUND(Table11[[#This Row],[WEIGHT 1]],0),Radwag7[],3,Radwag7[[#This Row],[Weigh]])),"") | O15: =IFERROR(Table11[[#This Row],[WEIGHT 1]]+Table11[[#This Row],[Correcttion 1]],"") | Q15: =IFERROR(IF(ISBLANK(Table11[[#This Row],[WEIGHT2]]),"",VLOOKUP(ROUND(Table11[[#This Row],[WEIGHT2]],0),Radwag7[],3,Radwag7[[#This Row],[Weigh]])),"") | R15: =IFERROR(Table11[[#This Row],[WEIGHT2]]+Table11[[#This Row],[Correcttion2]],"")
A16: (8) % VOLATILE = VS x 100 / TS | G16: =IFERROR(($G$15/TSS!G27),"") | H16: =IFERROR(($G$15/TSS!H27),"")
D18: Influent | E18: Effluent | F18: Thickenner | G18: Mix | H18: RAS
D19: =IF(C13>0,HLOOKUP(D18,$C$9:$H$15,7,FALSE),"") | E19: =IF(D13>0,HLOOKUP(E18,$C$9:$H$15,7,FALSE),"") | F19: =IF(E13>0,HLOOKUP(F18,$C$9:$H$15,7,FALSE),"") | G19: NO | H19: NO
G20: =IF(TSS!G21="","",IF(0.7<=TSS!G21,"True","False")) | H20: =IF(TSS!H21="","",IF(0.7<=TSS!H21,"True","False"))
D21: =IFERROR(IF(D20>0,D20,D19),"") | E21: =IFERROR(IF(E20>0,E20,E19),"") | F21: =IFERROR(IF(F20>0,F20,F19),"") | G21: =IFERROR(IF(G13="",TSS!G20,IF(G20>0,G20,G20)),"") | H21: =IFERROR(IF(G13="",TSS!H20,IF(H20>0,H20,H20)),"")
H24: رجوع

Sheet TSS
A6: Holding Company | G6: الشركة القابضة
A7: Fayoum drinking Water and Sanitation Company | G7: شركة مياه الشرب والصرف الصحى بالفيوم
G8: قطاع المعامل - الادارة العامة لمعامل الصرف الصحى
A10: WASTWATER TREATMENT PLANT LABORATORY
A11: TOTAL SUSPENDED SOLIDS ( TSS ) WORK SHEET | D11: PLANT: Kasr Rashwan | F11: FORM ID:
A12: 20th EDITION, of The Standard Method for the Examination of Water and Wastewater | D12: LAB ID: WWL03 | F12: SAMPLE DATE: | G12: =Main!B6
A13: PROCEDURE NUMBER 2450 D | D13: ANALYST:Ch/ Mohammad S. Alawamy | F13: ANALYSIS DATE: | G13: =Main!G6
A14: (1) SAMPLE TYPE/ ID | C14: Influent | D14: Effluent | E14: MLSS | G14: =IF(G15="","",D14) | H14: =IF(H15="","",E14)
A15: (2) FILTER NUMBER | G15: =IFERROR(IF(Main!G19="YES",IF(Main!G15="",IF(D15="","",D15),""),""),"") | H15: =IFERROR(IF(Main!H19="YES",IF(Main!H15="",IF(E15="","",E15),""),""),"")
A16: (3) SAMPLE VOLUME, ml | G16: =IFERROR(IF(G15="","",IF(D16="","",D16)),"") | H16: =IFERROR(IF(H15="","",IF(E16="","",E16)),"")
A17: (4) TARE WT. OF FILTER, g | G17: =IFERROR(IF(G15="","",IF(D18="","",D18)),"") | H17: =IFERROR(IF(H15="","",IF(E18="","",E18)),"")
A18: (5) WT. OF DRY FILTER, g
A19: (6) WT. OF DRY SOLIDS, g = (5) - ( 4) | C19: =IFERROR(IF(C18="","",C18-C17),"") | D19: =IFERROR(IF(D18="","",D18-D17),"") | E19: =IFERROR(IF(E18="","",E18-E17),"") | F19: =IFERROR(IF(F18="","",F18-F17),"") | G19: =IFERROR(IF(G15="","",ABS(G18-G17)),"") | H19: =IFERROR(IF(H15="","",ABS(H18-H17)),"")
A20: (7) TSS = mg/l (6) X 1,000,000 / (3) | C20: =IFERROR(IF(C18="","",C19*1000000/C16),"") | D20: =IFERROR(IF(D18="","",D19*1000000/D16),"") | E20: =IFERROR(IF(E18="","",E19*1000000/E16),"") | F20: =IFERROR(IF(F18="","",F19*1000000/F16),"") | G20: =IFERROR(IF(G18="","",G19*1000000/G16),"") | H20: =IFERROR(IF(H18="","",H19*1000000/H16),"")
A21: (8) % VOLATILE = VS x 100 / TS | G21: =IFERROR(($G$20/TSS!F27),"") | H21: =IFERROR(($H$20/TSS!G27),"")
E24: Influent | F24: Effluent | G24: MLSS
E25: =IF(C18>0,C20,"") | F25: =IF(D18>0,D20,"") | G25: =IF(E18>0,E20,"") | H25: =IF(F18>0,F20,"")
E27: =IFERROR(IF(E26>0,E26,E25),"") | F27: =IFERROR(IF(F26>0,F26,F25),"") | G27: =IFERROR(IF(G26>0,G26,G25),"") | H27: =IFERROR(IF(H26>0,H26,H25),"")
H30: رجوع

Sheet Dispenser
AO8: Column1 | AP8: 20E79250 | AQ8: 18B75913 | AR8: 18B75882 | AS8: 20G33697 | AT8: 50109103 | AU8: 20G33740 | AV8: 19C43897 | AW8: 19C43891 | AX8: 19A06196 | AY8: 19C43892 | AZ8: 100820020 | BA8: Column13 | BD8: Weigh | BE8: Error | BF8: Correction
AP9: 20E79250 | AQ9: 18B75913 | AR9: 18B75882 | AS9: 20G33697 | AT9: 50109103 | AU9: 20G33740 | AV9: 19C43897 | AW9: 19C43891 | AX9: 19A06196 | AY9: 19C43892 | AZ9: 100820020 | BA9: Column13 | BD9: 0 | BE9: 0 | BF9: 0
AO10: 0.5 | AP10: 0.03 | AQ10: 0.01 | AR10: 0 | AT10: -0.0155 | AU10: 0.104 | AV10: 0.0032 | AW10: 0.1768 | AX10: 0 | AY10: -0.027 | BD10: 0.01 | BE10: -0.0002 | BF10: 0.0002
AO11: 1 | AP11: 0.03 | AQ11: 0 | AR11: 0 | AT11: -0.016 | AU11: 0.088 | AV11: -0.0001 | AW11: 0.1701 | AX11: 0 | AY11: -0.03 | AZ11: 0.03 | BD11: 0.02 | BE11: -0.000175 | BF11: 0.000175
B12: S.N. | C12: WEIGHT | D12: Correcttion | E12: Net weight | AO12: 1.5 | AP12: 0.01875 | AQ12: -0.005 | AR12: -0.0075 | AT12: -0.0165 | AU12: 0.072 | AV12: -0.0034 | AW12: 0.1634 | AX12: 0 | AY12: -0.033 | BD12: 0.03 | BE12: -0.00015 | BF12: 0.00015
B13: Beaker | D13: =IFERROR(VLOOKUP(ROUND(Weight[[#This Row],[WEIGHT]],0),#REF!,3,#REF!),"") | E13: =IFERROR(Weight[[#This Row],[WEIGHT]]+Weight[[#This Row],[Correcttion]],"") | AO13: 2 | AP13: 0.0075 | AQ13: -0.01 | AR13: -0.015 | AT13: -0.017 | AU13: 0.056 | AV13: -0.0067 | AW13: 0.1567 | AX13: 0 | AY13: -0.036 | AZ13: 0.018 | BD13: 0.04 | BE13: -0.000125 | BF13: 0.000125
B14: 1st | D14: =IFERROR(VLOOKUP(ROUND(Weight[[#This Row],[WEIGHT]],0),#REF!,3,#REF!),"") | E14: =IFERROR(Weight[[#This Row],[WEIGHT]]+Weight[[#This Row],[Correcttion]],"") | AO14: 2.5 | AP14: -0.00375 | AQ14: -0.015 | AR14: -0.0225 | AT14: -0.0175 | AU14: 0.04 | AV14: -0.01 | AW14: 0.15 | AX14: 0 | AY14: -0.039 | AZ14: 0.018 | BD14: 0.05 | BE14: -0.0001 | BF14: 0.0001
B15: 2nd | D15: =IFERROR(VLOOKUP(ROUND(Weight[[#This Row],[WEIGHT]],0),#REF!,3,#REF!),"") | E15: =IFERROR(Weight[[#This Row],[WEIGHT]]+Weight[[#This Row],[Correcttion]],"") | AO15: 3 | AP15: -0.015 | AQ15: -0.02 | AR15: -0.03 | AT15: -0.018 | AU15: 0.024 | AV15: -0.012 | AW15: 0.144 | AX15: 0 | AY15: -0.04 | BD15: 0.06 | BE15: -8e-05 | BF15: 8e-05
B16: 3rd | D16: =IFERROR(VLOOKUP(ROUND(Weight[[#This Row],[WEIGHT]],0),#REF!,3,#REF!),"") | E16: =IFERROR(Weight[[#This Row],[WEIGHT]]+Weight[[#This Row],[Correcttion]],"") | AO16: 3.5 | AP16: -0.02625 | AQ16: -0.025 | AR16: -0.0375 | AT16: -0.0185 | AU16: 0.008 | AV16: -0.014 | AW16: 0.138 | AX16: -0.001 | AY16: -0.04 | BD16: 0.07 | BE16: -6e-05 | BF16: 6e-05
E17: =IFERROR(AVERAGE(E16-E15,E15-E14,E14-E13),"") | AO17: 4 | AP17: -0.0375 | AQ17: -0.03 | AR17: -0.045 | AT17: -0.019 | AU17: -0.008 | AV17: -0.016 | AW17: 0.132 | AX17: -0.034 | AY17: -0.04 | BD17: 0.08 | BE17: -4e-05 | BF17: 4e-05
AO18: 4.5 | AP18: -0.04875 | AQ18: -0.035 | AR18: -0.0525 | AU18: -0.024 | AV18: -0.018 | AW18: 0.126 | AX18: -0.067 | AY18: -0.04 | BD18: 0.09 | BE18: -2e-05 | BF18: 2e-05
AO19: 5 | AP19: -0.06 | AQ19: -0.04 | AR19: -0.06 | AT19: -0.02 | AU19: -0.04 | AV19: -0.02 | AW19: 0.12 | AX19: -0.1 | AY19: -0.04 | AZ19: 0.038 | BD19: 0.1 | BE19: 0 | BF19: 0
AO20: 6 | AP20: -0.064 | AQ20: -0.044 | AR20: -0.064 | AT20: -0.021 | AU20: -0.056 | BD20: 0.2 | BE20: 0 | BF20: 0
AO21: 7 | AP21: -0.068 | AQ21: -0.048 | AR21: -0.068 | AT21: -0.022 | AU21: -0.072 | BD21: 0.3 | BE21: 1.7e-05 | BF21: -1.7e-05
AO22: 8 | AP22: -0.072 | AQ22: -0.052 | AR22: -0.072 | AT22: -0.023 | AU22: -0.088 | BD22: 0.4 | BE22: 3.4e-05 | BF22: -3.4e-05
AO23: 9 | AP23: -0.076 | AQ23: -0.056 | AR23: -0.076 | AT23: -0.024 | AU23: -0.104 | BD23: 0.5 | BE23: 5e-05 | BF23: -5e-05
AO24: 10 | AP24: -0.08 | AQ24: -0.06 | AR24: -0.08 | AT24: -0.025 | AU24: -0.12 | BD24: 0.6 | BE24: 4e-05 | BF24: -4e-05
AO25: 11 | AT25: -0.026 | AU25: -0.127 | BD25: 0.7 | BE25: 3e-05 | BF25: -3e-05
C26: Date | D26: ID | E26: Volume Dispensed | F26: W1 | G26: W2 | H26: W2-W1 | I26: Recovery | J26: Remark | AO26: 12 | AT26: -0.027 | AU26: -0.134 | BD26: 0.8 | BE26: 2e-05 | BF26: -2e-05
F27: =$E$13 | G27: =IFERROR(Table7[[W1 ]]+Table7[W2-W1],"") | H27: =IFERROR(HLOOKUP(Table7[ID],#REF!,MATCH(Table7[Volume Dispensed],#REF!,0),FALSE)+Weight[[#Totals],[Net weight]],"") | I27: =IFERROR(Table7[W2-W1]/Table7[Volume Dispensed],"") | J27: =IFERROR(IF(Table7[Date]="","",IF(OR(Table7[Recovery]<0.9,Table7[Recovery]>1.1),"Rejected","ACC")),"") | AO27: 13 | AT27: -0.028 | AU27: -0.141 | BD27: 0.9 | BE27: 1e-05 | BF27: -1e-05
AO28: 14 | AT28: -0.029 | AU28: -0.148 | BD28: 1 | BE28: 0 | BF28: 0
AO29: 15 | AT29: -0.03 | AU29: -0.155 | BD29: 2 | BE29: 0 | BF29: 0
AO30: 16 | AT30: -0.031 | AU30: -0.162 | BD30: 3 | BE30: 3.4e-05 | BF30: -3.4e-05
AO31: 17 | AT31: -0.032 | AU31: -0.169 | BD31: 4 | BE31: 6.7e-05 | BF31: -6.7e-05
AO32: 18 | AT32: -0.033 | AU32: -0.176 | BD32: 5 | BE32: 0.0001 | BF32: -0.0001
AO33: 19 | AT33: -0.034 | AU33: -0.183 | BD33: 6 | BE33: 0.0001 | BF33: -0.0001
AO34: 20 | AT34: -0.035 | AU34: -0.19 | BD34: 7 | BE34: 0.0001 | BF34: -0.0001
AO35: 21 | AT35: -0.036 | BD35: 8 | BE35: 0.0001 | BF35: -0.0001
AO36: 22 | AT36: -0.037 | BD36: 9 | BE36: 0.0001 | BF36: -0.0001
AO37: 23 | AT37: -0.038 | BD37: 10 | BE37: 0.0001 | BF37: -0.0001
AO38: 24 | AT38: -0.039 | BD38: 11 | BE38: 0.0001 | BF38: -0.0001
AO39: 25 | AT39: -0.04 | BD39: 12 | BE39: 0.0001 | BF39: -0.0001
AO40: 26 | AT40: -0.0412 | BD40: 13 | BE40: 0.0001 | BF40: -0.0001
AO41: 27 | AT41: -0.0424 | BD41: 14 | BE41: 0.0001 | BF41: -0.0001
AO42: 28 | AT42: -0.0436 | BD42: 15 | BE42: 0.0001 | BF42: -0.0001
AO43: 29 | AT43: -0.0448 | BD43: 16 | BE43: 0.0001 | BF43: -0.0001
AO44: 30 | AT44: -0.046 | BD44: 17 | BE44: 0.0001 | BF44: -0.0001
AO45: 31 | AT45: -0.0472 | BD45: 18 | BE45: 0.0001 | BF45: -0.0001
AO46: 32 | AT46: -0.0484 | BD46: 19 | BE46: 0.0001 | BF46: -0.0001
... AO64: 50 | AT64: -0.07 | BD64: 37 | BE64: 0.0001561 | BF64: -0.0001561
...

Sheet O&G
A3: Holding Company | G3: الشركة القابضة
A4: Fayoum drinking Water and Sanitation Company | G4: شركة مياه الشرب والصرف الصحى بالفيوم
G5: قطاع المعامل - الادارة العامة لمعامل الصرف الصحى
A6: Oil and Grease ( O&G ) WORK SHEET | D6: PLANT: Kasr Rashwan | F6: FORM ID:
A7: 20th EDITION, of The Standard Method for the Examination of Water and Wastewater | D7: LAB ID: WWL03 | F7: SAMPLE DATE: | G7: =Main!$B$6
A8: PROCEDURE NUMBER 5220 G | D8: ANALYST:Ch/ Mohammad S. Alawamy | F8: ANALYSIS DATE: | G8: =Main!G6 | L8: S.N. | M8: WEIGHT 1 | N8: Correcttion 1 | O8: Net weight 1 | P8: WEIGHT2 | Q8: Correcttion2 | R8: Net weight2
A9: (1) SAMPLE TYPE/ ID | C9: Influent | D9: Effluent | E9: Thickenner | F9: Influent | G9: Mix | H9: Mix | N9: =IFERROR(IF(ISBLANK(Table114[[#This Row],[WEIGHT 1]]),"",VLOOKUP(ROUND(Table114[[#This Row],[WEIGHT 1]],0),Radwag7[],3,Radwag7[[#This Row],[Weigh]])),"") | Q9: =IFERROR(IF(ISBLANK(Table114[[#This Row],[WEIGHT2]]),"",VLOOKUP(ROUND(Table114[[#This Row],[WEIGHT2]],0),Radwag7[],3,Radwag7[[#This Row],[Weigh]])),"") | R9: =IFERROR(Table114[[#This Row],[WEIGHT2]]+Table114[[#This Row],[Correcttion2]],"")
A10: (2) CRUCIBLE NUMBER | C10: =IF(ISBLANK($L$10),"",$L$10) | D10: =IF(ISBLANK($L$9),"",$L$9) | E10: =IF(ISBLANK($L$11),"",$L$11) | F10: =IF(ISBLANK($L$12),"",$L$12) | G10: =IF(ISBLANK($L$13),"",$L$13) | H10: =IF(ISBLANK($L$14),"",$L$14) | N10: =IFERROR(IF(ISBLANK(Table114[[#This Row],[WEIGHT 1]]),"",VLOOKUP(ROUND(Table114[[#This Row],[WEIGHT 1]],0),Radwag7[],3,Radwag7[[#This Row],[Weigh]])),"") | Q10: =IFERROR(IF(ISBLANK(Table114[[#This Row],[WEIGHT2]]),"",VLOOKUP(ROUND(Table114[[#This Row],[WEIGHT2]],0),Radwag7[],3,Radwag7[[#This Row],[Weigh]])),"") | R10: =IFERROR(Table114[[#This Row],[WEIGHT2]]+Table114[[#This Row],[Correcttion2]],"")
A11: (3) SAMPLE VOLUME, ml | N11: =IFERROR(IF(ISBLANK(Table114[[#This Row],[WEIGHT 1]]),"",VLOOKUP(ROUND(Table114[[#This Row],[WEIGHT 1]],0),Radwag7[],3,Radwag7[[#This Row],[Weigh]])),"") | O11: =IFERROR(Table114[[#This Row],[WEIGHT 1]]+Table114[[#This Row],[Correcttion 1]],"") | Q11: =IFERROR(IF(ISBLANK(Table114[[#This Row],[WEIGHT2]]),"",VLOOKUP(ROUND(Table114[[#This Row],[WEIGHT2]],0),Radwag7[],3,Radwag7[[#This Row],[Weigh]])),"") | R11: =IFERROR(Table114[[#This Row],[WEIGHT2]]+Table114[[#This Row],[Correcttion2]],"")
A12: (4) TARE WT. OF DRY CRUCIBLE /CRUCIBLE g | C12: =IF($C$10="","",IF(ISBLANK($O$10),"",$O$10)) | D12: =IF($D$10="","",IF(ISBLANK($O$9),"",$O$9)) | E12: =IF($E$10="","",IF(ISBLANK($O$11),"",$O$11)) | F12: =IF($F$10="","",IF(ISBLANK($O$12),"",$O$12)) | G12: =IF($G$10="","",IF(ISBLANK($O$13),"",$O$13)) | H12: =IF($H$10="","",IF(ISBLANK($O$14),"",$O$14)) | N12: =IFERROR(IF(ISBLANK(Table114[[#This Row],[WEIGHT 1]]),"",VLOOKUP(ROUND(Table114[[#This Row],[WEIGHT 1]],0),Radwag7[],3,Radwag7[[#This Row],[Weigh]])),"") | O12: =IFERROR(Table114[[#This Row],[WEIGHT 1]]+Table114[[#This Row],[Correcttion 1]],"") | Q12: =IFERROR(IF(ISBLANK(Table114[[#This Row],[WEIGHT2]]),"",VLOOKUP(ROUND(Table114[[#This Row],[WEIGHT2]],0),Radwag7[],3,Radwag7[[#This Row],[Weigh]])),"") | R12: =IFERROR(Table114[[#This Row],[WEIGHT2]]+Table114[[#This Row],[Correcttion2]],"")
A13: (5) WT. OF DRY CRUCIBLE / ASH CRUCIBLE g | C13: =IF($C$10="","",IF(ISBLANK($R$10),"",$R$10)) | D13: =IF($D$10="","",IF(ISBLANK($R$9),"",$R$9)) | E13: =IF($E$10="","",IF(ISBLANK($R$11),"",$R$11)) | F13: =IF($F$10="","",IF(ISBLANK($R$12),"",$R$12)) | G13: =IF($G$10="","",IF(ISBLANK($R$13),"",$R$13)) | H13: =IF($H$10="","",IF(ISBLANK($R$14),"",$R$14)) | N13: =IFERROR(IF(ISBLANK(Table114[[#This Row],[WEIGHT 1]]),"",VLOOKUP(ROUND(Table114[[#This Row],[WEIGHT 1]],0),Radwag7[],3,Radwag7[[#This Row],[Weigh]])),"") | O13: =IFERROR(Table114[[#This Row],[WEIGHT 1]]+Table114[[#This Row],[Correcttion 1]],"") | Q13: =IFERROR(IF(ISBLANK(Table114[[#This Row],[WEIGHT2]]),"",VLOOKUP(ROUND(Table114[[#This Row],[WEIGHT2]],0),Radwag7[],3,Radwag7[[#This Row],[Weigh]])),"") | R13: =IFERROR(Table114[[#This Row],[WEIGHT2]]+Table114[[#This Row],[Correcttion2]],"")
A14: (6) WT. OF DRY SOLIDS/ VOLATILE SOLIDS, g = (5) - ( 4) | C14: =IFERROR(IF(C13="","",C13-C12),"") | D14: =IFERROR(IF(D13="","",D13-D12),"") | E14: =IFERROR(IF(E13="","",E13-E12),"") | F14: =IFERROR(IF(F10="","",ABS(F13-F12)),"") | G14: =IFERROR(IF(G10="","",ABS(G13-G12)),"") | H14: =IFERROR(IF(H10="","",ABS(H13-H12)),"") | N14: =IFERROR(IF(ISBLANK(Table114[[#This Row],[WEIGHT 1]]),"",VLOOKUP(ROUND(Table114[[#This Row],[WEIGHT 1]],0),Radwag7[],3,Radwag7[[#This Row],[Weigh]])),"") | O14: =IFERROR(Table114[[#This Row],[WEIGHT 1]]+Table114[[#This Row],[Correcttion 1]],"") | Q14: =IFERROR(IF(ISBLANK(Table114[[#This Row],[WEIGHT2]]),"",VLOOKUP(ROUND(Table114[[#This Row],[WEIGHT2]],0),Radwag7[],3,Radwag7[[#This Row],[Weigh]])),"") | R14: =IFERROR(Table114[[#This Row],[WEIGHT2]]+Table114[[#This Row],[Correcttion2]],"")
A15: (7) TS / VS = mg/l (6) X 1,000,000 / (3) | C15: =IFERROR(IF(C13="","",C14*1000000/C11),"") | D15: =IFERROR(IF(D13="","",D14*1000000/D11),"") | E15: =IFERROR(IF(E13="","",E14*1000000/E11),"") | F15: =IFERROR(IF(F12<2,"",F14*1000000/F11),"") | G15: =IFERROR(IF(G12<2,"",G14*1000000/G11),"") | H15: =IFERROR(IF(H13="","",H14*1000000/H11),"") | N15: =IFERROR(IF(ISBLANK(Table114[[#This Row],[WEIGHT 1]]),"",VLOOKUP(ROUND(Table114[[#This Row],[WEIGHT 1]],0),Radwag7[],3,Radwag7[[#This Row],[Weigh]])),"") | O15: =IFERROR(Table114[[#This Row],[WEIGHT 1]]+Table114[[#This Row],[Correcttion 1]],"") | Q15: =IFERROR(IF(ISBLANK(Table114[[#This Row],[WEIGHT2]]),"",VLOOKUP(ROUND(Table114[[#This Row],[WEIGHT2]],0),Radwag7[],3,Radwag7[[#This Row],[Weigh]])),"") | R15: =IFERROR(Table114[[#This Row],[WEIGHT2]]+Table114[[#This Row],[Correcttion2]],"")
A16: (8) % VOLATILE = VS x 100 / TS | G16: =IFERROR(($G$15/TSS!G27),"") | H16: =IFERROR(($G$15/TSS!H27),"")
D18: Influent | E18: Effluent | F18: Thickenner | G18: Mix | H18: RAS
D19: =IF(C13>0,HLOOKUP(D18,$C$9:$H$15,7,FALSE),"") | E19: =IF(D13>0,HLOOKUP(E18,$C$9:$H$15,7,FALSE),"") | F19: =IF(E13>0,HLOOKUP(F18,$C$9:$H$15,7,FALSE),"") | G19: NO | H19: NO
D20: NA | E20: NA | G20: =IF(TSS!G21="","",IF(0.7<=TSS!G21,"True","False")) | H20: =IF(TSS!H21="","",IF(0.7<=TSS!H21,"True","False"))
D21: =IFERROR(IF(D20>0,D20,D19),"") | E21: =IFERROR(IF(E20>0,E20,E19),"") | F21: =IFERROR(IF(F20>0,F20,F19),"") | G21: =IFERROR(IF(G13="",TSS!G20,IF(G20>0,G20,G20)),"") | H21: =IFERROR(IF(G13="",TSS!H20,IF(H20>0,H20,H20)),"")
H24: رجوع
