Workbook

Sheet Main
E10: نتائج تحليل الدخول والسيب النهائى لمحطة معالجة صرف الصحى طاميه بالفيوم لشهر
A11: م | B11: التاريخ | C11: TEMP °C | E11: pH | G11: S-- | I11: DO | J11: TDS | L11: TS | N11: TSS | P11: COD | R11: BOD | T11: Oil&Grase | V11: Total | W11: R. Cl
C12: In | D12: Out | E12: In | F12: Out | G12: In | H12: Out | I12: Out | J12: In | K12: Out | L12: In | M12: Out | N12: In | O12: Out | P12: In | Q12: Out | R12: In | S12: Out | T12: In | U12: Out | V12: Coliform | W12: Out
B13: المعايير | C13: 43 | D13: 15-35 | E13: 6-9.5 | F13: 6.5-9 | G13: <10 | H13: <=1 | I13: >=4 | J13: <=2000 | K13: <=2000 | N13: <800 | O13: <50 | P13: <1100 | Q13: <80 | R13: <600 | S13: <60 | T13: <100 | U13: <10 | V13: 5 | W13: ≥ 0.5 mg/l
A14: 1 | B14: =IFERROR(TEXT(DATE($R$10,$Q$10,$A14),"dd/mm/yyyy"),"")
A15: 2 | B15: =IFERROR(TEXT(DATE($R$10,$Q$10,$A15),"dd/mm/yyyy"),"")
A16: 3 | B16: =IFERROR(TEXT(DATE($R$10,$Q$10,$A16),"dd/mm/yyyy"),"")
A17: 4 | B17: =IFERROR(TEXT(DATE($R$10,$Q$10,$A17),"dd/mm/yyyy"),"")
A18: 5 | B18: =IFERROR(TEXT(DATE($R$10,$Q$10,$A18),"dd/mm/yyyy"),"")
A19: 6 | B19: =IFERROR(TEXT(DATE($R$10,$Q$10,$A19),"dd/mm/yyyy"),"")
A20: 7 | B20: =IFERROR(TEXT(DATE($R$10,$Q$10,$A20),"dd/mm/yyyy"),"") | Y20: =IF(OR(OR(I22="",I22="ND"),U22="NA",OR(S22="NA",S22="ND")),"",IF(OR(F22<6.5,F22>9,D22<15,D22>35,H22>1,I22<4,K22>2000,O22>50,Q22>80,S22>60,U22>10),1,"")) | Z20: =IF(I22="","",IF(V22>5000,1,"")) | AA20: =IF(OR(OR(G22="",G22="ND"),OR(R22="NA",R22="ND")),"",IF(OR(E22<6.5,E22>9.5,C22>43,G22>10,J22>2000,N22>800,P22>1100,R22>600,T22>100),1,""))
A21: 8 | B21: =IFERROR(TEXT(DATE($R$10,$Q$10,$A21),"dd/mm/yyyy"),"")
A22: 9 | B22: =IFERROR(TEXT(DATE($R$10,$Q$10,$A22),"dd/mm/yyyy"),"")
A23: 10 | B23: =IFERROR(TEXT(DATE($R$10,$Q$10,$A23),"dd/mm/yyyy"),"")
A24: 11 | B24: =IFERROR(TEXT(DATE($R$10,$Q$10,$A24),"dd/mm/yyyy"),"")
A25: 12 | B25: =IFERROR(TEXT(DATE($R$10,$Q$10,$A25),"dd/mm/yyyy"),"")
A26: 13 | B26: =IFERROR(TEXT(DATE($R$10,$Q$10,$A26),"dd/mm/yyyy"),"") | Y26: =IF(OR(OR(I29="",I29="ND"),U29="NA",OR(S29="NA",S29="ND")),"",IF(OR(F29<6.5,F29>9,D29<15,D29>35,H29>1,I29<4,K29>2000,O29>50,Q29>80,S29>60,U29>10),1,"")) | Z26: =IF(I29="","",IF(V29>5000,1,"")) | AA26: =IF(OR(OR(G29="",G29="ND"),OR(R29="NA",R29="ND")),"",IF(OR(E29<6.5,E29>9.5,C29>43,G29>10,J29>2000,N29>800,P29>1100,R29>600,T29>100),1,""))
A27: 14 | B27: =IFERROR(TEXT(DATE($R$10,$Q$10,$A27),"dd/mm/yyyy"),"") | Y27: =IF(OR(OR(I29="",I29="ND"),U29="NA",OR(S29="NA",S29="ND")),"",IF(OR(F29<6.5,F29>9,D29<15,D29>35,H29>1,I29<4,K29>2000,O29>50,Q29>80,S29>60,U29>10),1,"")) | Z27: =IF(I29="","",IF(V29>5000,1,"")) | AA27: =IF(OR(OR(G29="",G29="ND"),OR(R29="NA",R29="ND")),"",IF(OR(E29<6.5,E29>9.5,C29>43,G29>10,J29>2000,N29>800,P29>1100,R29>600,T29>100),1,""))
A28: 15 | B28: =IFERROR(TEXT(DATE($R$10,$Q$10,$A28),"dd/mm/yyyy"),"")
A29: 16 | B29: =IFERROR(TEXT(DATE($R$10,$Q$10,$A29),"dd/mm/yyyy"),"")
A30: 17 | B30: =IFERROR(TEXT(DATE($R$10,$Q$10,$A30),"dd/mm/yyyy"),"")
A31: 18 | B31: =IFERROR(TEXT(DATE($R$10,$Q$10,$A31),"dd/mm/yyyy"),"") | Y31: =IF(OR(OR(I33="",I33="ND"),U33="NA",OR(S33="NA",S33="ND")),"",IF(OR(F33<6.5,F33>9,D33<15,D33>35,H33>1,I33<4,K33>2000,O33>50,Q33>80,S33>60,U33>10),1,"")) | Z31: =IF(I33="","",IF(V33>5000,1,"")) | AA31: =IF(OR(OR(G33="",G33="ND"),OR(R33="NA",R33="ND")),"",IF(OR(E33<6.5,E33>9.5,C33>43,G33>10,J33>2000,N33>800,P33>1100,R33>600,T33>100),1,""))
A32: 19 | B32: =IFERROR(TEXT(DATE($R$10,$Q$10,$A32),"dd/mm/yyyy"),"")
A33: 20 | B33: =IFERROR(TEXT(DATE($R$10,$Q$10,$A33),"dd/mm/yyyy"),"")
A34: 21 | B34: =IFERROR(TEXT(DATE($R$10,$Q$10,$A34),"dd/mm/yyyy"),"")
A35: 22 | B35: =IFERROR(TEXT(DATE($R$10,$Q$10,$A35),"dd/mm/yyyy"),"")
A36: 23 | B36: =IFERROR(TEXT(DATE($R$10,$Q$10,$A36),"dd/mm/yyyy"),"")
A37: 24 | B37: =IFERROR(TEXT(DATE($R$10,$Q$10,$A37),"dd/mm/yyyy"),"")
A38: 25 | B38: =IFERROR(TEXT(DATE($R$10,$Q$10,$A38),"dd/mm/yyyy"),"") | Y38: =IF(OR(OR(I40="",I40="ND"),U40="NA",OR(S40="NA",S40="ND")),"",IF(OR(F40<6.5,F40>9,D40<15,D40>35,H40>1,I40<4,K40>2000,O40>50,Q40>80,S40>60,U40>10),1,"")) | Z38: =IF(I40="","",IF(V40>5000,1,"")) | AA38: =IF(OR(OR(G40="",G40="ND"),OR(R40="NA",R40="ND")),"",IF(OR(E40<6.5,E40>9.5,C40>43,G40>10,J40>2000,N40>800,P40>1100,R40>600,T40>100),1,""))
A39: 26 | B39: =IFERROR(TEXT(DATE($R$10,$Q$10,$A39),"dd/mm/yyyy"),"") | Y39: =IF(OR(OR(I41="",I41="ND"),U41="NA",OR(S41="NA",S41="ND")),"",IF(OR(F41<6.5,F41>9,D41<15,D41>35,H41>1,I41<4,K41>2000,O41>50,Q41>80,S41>60,U41>10),1,"")) | Z39: =IF(I41="","",IF(V41>5000,1,"")) | AA39: =IF(OR(OR(G41="",G41="ND"),OR(R41="NA",R41="ND")),"",IF(OR(E41<6.5,E41>9.5,C41>43,G41>10,J41>2000,N41>800,P41>1100,R41>600,T41>100),1,""))
A40: 27 | B40: =IFERROR(TEXT(DATE($R$10,$Q$10,$A40),"dd/mm/yyyy"),"") | Y40: =IF(OR(OR(I42="",I42="ND"),U42="NA",OR(S42="NA",S42="ND")),"",IF(OR(F42<6.5,F42>9,D42<15,D42>35,H42>1,I42<4,K42>2000,O42>50,Q42>80,S42>60,U42>10),1,"")) | Z40: =IF(I42="","",IF(V42>5000,1,"")) | AA40: =IF(OR(OR(G42="",G42="ND"),OR(R42="NA",R42="ND")),"",IF(OR(E42<6.5,E42>9.5,C42>43,G42>10,J42>2000,N42>800,P42>1100,R42>600,T42>100),1,""))
A41: 28 | B41: =IFERROR(TEXT(DATE($R$10,$Q$10,$A41),"dd/mm/yyyy"),"")
A42: 29 | B42: =IFERROR(TEXT(DATE($R$10,$Q$10,$A42),"dd/mm/yyyy"),"") | Y42: =IF(OR(OR(I44="",I44="ND"),U44="NA",OR(S44="NA",S44="ND")),"",IF(OR(F44<6.5,F44>9,D44<15,D44>35,H44>1,I44<4,K44>2000,O44>50,Q44>80,S44>60,U44>10),1,"")) | Z42: =IF(I44="","",IF(V44>5000,1,"")) | AA42: =IF(OR(OR(G44="",G44="ND"),OR(R44="NA",R44="ND")),"",IF(OR(E44<6.5,E44>9.5,C44>43,G44>10,J44>2000,N44>800,P44>1100,R44>600,T44>100),1,""))
A43: 30 | B43: =IFERROR(TEXT(DATE($R$10,$Q$10,$A43),"dd/mm/yyyy"),"")
A44: 31 | B44: =IFERROR(TEXT(DATE($R$10,$Q$10,$A44),"dd/mm/yyyy"),"")
B45: Min | C45: =IFERROR(IF(COUNT(Table4[Column3])>0,MIN(C15:C44),""),"") | D45: =IFERROR(IF(COUNT(Table4[Column4])>0,MIN(D15:D44),""),"") | E45: =IFERROR(IF(COUNT(Table4[Column5])>0,MIN(E15:E44),""),"") | F45: =IFERROR(IF(COUNT(Table4[Column6])>0,MIN(F15:F44),""),"") | G45: =IFERROR(IF(COUNT(Table4[Column7])>0,MIN(G15:G44),""),"") | H45: =IFERROR(IF(COUNT(Table4[Column8])>0,MIN(H15:H44),""),"") | I45: =IFERROR(IF(COUNT(Table4[Column9])>0,MIN(I15:I44),""),"") | J45: =IFERROR(IF(COUNT(Table4[Column10])>0,MIN(J15:J44),""),"") | K45: =IFERROR(IF(COUNT(Table4[Column11])>0,MIN(K15:K44),""),"") | L45: =IFERROR(IF(COUNT(Table4[Column12])>0,MIN(L15:L44),""),"") | M45: =IFERROR(IF(COUNT(Table4[Column13])>0,MIN(M15:M44),""),"") | N45: =IFERROR(IF(COUNT(Table4[Column14])>0,MIN(N15:N44),""),"") | O45: =IFERROR(IF(COUNT(Table4[Column15])>0,MIN(O15:O44),""),"") | P45: =IFERROR(IF(COUNT(Table4[Column16])>0,MIN(P15:P44),""),"") | Q45: =IFERROR(IF(COUNT(Table4[Column17])>0,MIN(Q15:Q44),""),"") | R45: =IFERROR(IF(COUNT(Table4[Column18])>0,MIN(R15:R44),""),"") | S45: =IFERROR(IF(COUNT(Table4[Column19])>0,MIN(S15:S44),""),"") | T45: =IFERROR(IF(COUNT(Table4[Column20])>0,MIN(T15:T44),""),"") | U45: =IFERROR(IF(COUNT(Table4[Column21])>0,MIN(U15:U44),""),"") | V45: =IFERROR(IF(COUNT(Table4[Column22])>0,MIN(V15:V44),""),"") | W45: =IFERROR(IF(COUNT(Table4[Column23])>0,MIN(W15:W44),""),"")
B46: Max | C46: =IFERROR(IF(COUNT(Table4[Column3])>0,MAX(C15:C44),""),"") | D46: =IFERROR(IF(COUNT(Table4[Column4])>0,MAX(D15:D44),""),"") | E46: =IFERROR(IF(COUNT(Table4[Column5])>0,MAX(E15:E44),""),"") | F46: =IFERROR(IF(COUNT(Table4[Column6])>0,MAX(F15:F44),""),"") | G46: =IFERROR(IF(COUNT(Table4[Column7])>0,MAX(G15:G44),""),"") | H46: =IFERROR(IF(COUNT(Table4[Column8])>0,MAX(H15:H44),""),"") | I46: =IFERROR(IF(COUNT(Table4[Column9])>0,MAX(I15:I44),""),"") | J46: =IFERROR(IF(COUNT(Table4[Column10])>0,MAX(J15:J44),""),"") | K46: =IFERROR(IF(COUNT(Table4[Column11])>0,MAX(K15:K44),""),"") | L46: =IFERROR(IF(COUNT(Table4[Column12])>0,MAX(L15:L44),""),"") | M46: =IFERROR(IF(COUNT(Table4[Column13])>0,MAX(M15:M44),""),"") | N46: =IFERROR(IF(COUNT(Table4[Column14])>0,MAX(N15:N44),""),"") | O46: =IFERROR(IF(COUNT(Table4[Column15])>0,MAX(O15:O44),""),"") | P46: =IFERROR(IF(COUNT(Table4[Column16])>0,MAX(P15:P44),""),"") | Q46: =IFERROR(IF(COUNT(Table4[Column17])>0,MAX(Q15:Q44),""),"") | R46: =IFERROR(IF(COUNT(Table4[Column18])>0,MAX(R15:R44),""),"") | S46: =IFERROR(IF(COUNT(Table4[Column19])>0,MAX(S15:S44),""),"") | T46: =IFERROR(IF(COUNT(Table4[Column20])>0,MAX(T15:T44),""),"") | U46: =IFERROR(IF(COUNT(Table4[Column21])>0,MAX(U15:U44),""),"") | V46: =IFERROR(IF(COUNT(Table4[Column22])>0,MAX(V15:V44),""),"") | W46: =IFERROR(IF(COUNT(Table4[Column23])>0,MAX(W15:W44),""),"")
B47: Average | C47: =IFERROR(AVERAGEIF(C15:C44,">0"),"") | D47: =IFERROR(AVERAGEIF(D15:D44,">0"),"") | E47: =IFERROR(AVERAGEIF(E15:E44,">0"),"") | F47: =IFERROR(AVERAGEIF(F15:F44,">0"),"") | G47: =IFERROR(AVERAGEIF(G15:G44,">0"),"") | H47: =IFERROR(AVERAGEIF(H15:H44,">0"),"") | I47: =IFERROR(AVERAGEIF(I15:I44,">0"),"") | J47: =IFERROR(AVERAGEIF(J15:J44,">0"),"") | ... U47: =IFERROR(AVERAGEIF(U15:U44,">0"),"") | V47: =IFERROR(IF(COUNT(V14:V44)>0,TEXT(AVERAGE(V14:V44),"0.00 "&" X 10" & CHAR(179)),""),"") | W47: =IFERROR(AVERAGEIF(W15:W44,">0"),"") | Y47: =MAX(T48,R48,P48,N48,J48,G48,E48,C48) -> 0 | Z47: =MAX(U48,S48,Q48,O48,K48,H48,F48,D48) -> 0 | AA47: =V48 -> 0
C48: =COUNT(Table4[Column3])-COUNTIFS(Table4[Column3],">15",Table4[Column3],"<35") -> 0 | D48: =COUNT(Table4[Column4])-COUNTIFS(Table4[Column4],">15",Table4[Column4],"<35") -> 0 | E48: =COUNT(Table4[Column5])-COUNTIFS(Table4[Column5],">6.5",Table4[Column5],"<9") -> 0 | F48: =COUNT(Table4[Column6])-COUNTIFS(Table4[Column6],">6.5",Table4[Column6],"<9") -> 0 | G48: =COUNT(Table4[Column7])-COUNTIF(Table4[Column7],G13) -> 0 | H48: =COUNT(Table4[Column8])-COUNTIF(Table4[Column8],H13) -> 0 | I48: =COUNT(Table4[Column9])-COUNTIF(Table4[Column9],I13) -> 0 | L48: =COUNT(Table4[Column12])-COUNTIF(Table4[Column12],L13) -> 0 | M48: =COUNT(Table4[Column13])-COUNTIF(Table4[Column13],M13) -> 0 | N48: =COUNT(Table4[Column14])-COUNTIF(Table4[Column14],N13) -> 0 | O48: =COUNT(Table4[Column15])-COUNTIF(Table4[Column15],O13) -> 0 | P48: =COUNT(Table4[Column16])-COUNTIF(Table4[Column16],P13) -> 0 | Q48: =COUNT(Table4[Column17])-COUNTIF(Table4[Column17],Q13) -> 0 | R48: =COUNT(Table4[Column18])-COUNTIF(Table4[Column18],R13) -> 0 | S48: =COUNT(Table4[Column19])-COUNTIF(Table4[Column19],S13) -> 0 | T48: =COUNT(Table4[Column20])-COUNTIF(Table4[Column20],T13) -> 0 | U48: =COUNT(Table4[Column21])-COUNTIF(Table4[Column21],U13) -> 0 | V48: =COUNT(Table4[Column22])-COUNTIF(Table4[Column22],"<"&V13) -> 0
A50: م | C50: TEMP °C | E50: pH | G50: S-- | I50: DO | J50: TDS | L50: TS | N50: TSS | P50: COD | R50: BOD | T50: Oil&Grase | V50: Total | W50: R. Cl
...

Sheet الاحصائية
A1: شركة الفيوم لمياه الشرب والصرف الصحى
A2: قطاع المعامل
A3: الادارة العامة لمعامل الصرف الصحي
A5: إحصائية بعدد عينات الدخول والسيب النهائى لمحطة معالجة طامية عن شهر | P5: =Main!Q10 -> 0 | Q5: ='تقرير المواد الصلبة'!J10 -> 0 | S5: =IFERROR(#REF!,"") | T5: =IFERROR(#REF!,"")
G6: عدد عينات الدخول | L6: عدد عينات السيب النهائى
A7: التاريخ | B7: اسم المحطة | D7: نظام المعالجة | E7: الطاقة التصميمية | F7: الطاقة الفعلية | G7: عدد العينات الكيميائية | J7: نسبة المطابقة | L7: عدد العينات الكيميائية | O7: عدد العينات البكتريولوجية | R7: اجمالي عدد العينات | U7: نسبة المطابقة
E8: م3/ يوم | F8: م3/ يوم | G8: العدد | H8: مطابق | I8: غيرمطابق | J8: مطابق% | K8: غير مطابق % | L8: العدد | M8: مطابق | N8: غيرمطابق | O8: العدد | P8: مطابق | Q8: غيرمطابق | R8: العدد | S8: مطابق | T8: غيرمطابق | U8: مطابق% | V8: غير مطابق %
A9: =DATE(Q5,P5+1,) -> 0 | B9: طامية | D9: كروجر | E9: 15000 | F9: 14500 | G9: =IFERROR(COUNT(Main!$C$15:$C$44),"") -> 0 | H9: =IFERROR(G9-I9,"") -> 0 | I9: =IFERROR(Main!$Y$47,"") -> 0 | J9: =IFERROR($H$9/$G$9,"") | K9: =IFERROR($I$9/$G$9,"") | L9: =IFERROR(COUNT(Main!$D$15:$D$44),"") -> 0 | M9: =IFERROR(L9-N9,"") -> 0 | N9: =IFERROR(Main!$Z$47,"") -> 0 | O9: =IFERROR(COUNT(Main!$V$15:$V$44),"") -> 0 | P9: =IFERROR(O9-Q9,"") -> 0 | Q9: =IFERROR(Main!$AA$47,"") -> 0 | R9: =IFERROR($L$9+$O$9,"") -> 0 | S9: =IFERROR($M$9+$P$9,"") -> 0 | T9: =IFERROR($N$9+$Q$9,"") -> 0 | U9: =IFERROR($S$9/$R$9,"") | V9: =IFERROR($T$9/$R$9,"")
A10: =A9 -> 0 | B10: =Main!B52 -> 0 | D10: برك أكسدة | G10: =IFERROR(COUNT(Main!C52),"") -> 0 | H10: =IFERROR(G10-I10,"") -> 0 | I10: =IFERROR(Main!Y56,"") -> 0 | J10: =IFERROR(H10/G10,"") | K10: =IFERROR(I10/G10,"") | L10: =IFERROR(COUNT(Main!D52),"") -> 0 | M10: =IFERROR(L10-N10,"") -> 0 | N10: =IFERROR(Main!Z56,"") -> 0 | O10: =IFERROR(COUNT(Main!V52),"") -> 0 | P10: =IFERROR(O10-Q10,"") -> 0 | Q10: =IFERROR(Main!AA56,"") -> 0 | R10: =IFERROR(L10+O10,"") -> 0 | S10: =IFERROR(M10+P10,"") -> 0 | T10: =IFERROR(N10+Q10,"") -> 0 | U10: =IFERROR(S10/R10,"") | V10: =IFERROR(T10/R10,"")
A11: =A10 -> 0 | B11: =Main!B53 -> 0 | D11: برك أكسدة | G11: =IFERROR(COUNT(Main!C53),"") -> 0 | H11: =IFERROR(G11-I11,"") -> 0 | I11: =IFERROR(Main!Y57,"") -> 0 | J11: =IFERROR(H11/G11,"") | K11: =IFERROR(I11/G11,"") | L11: =IFERROR(COUNT(Main!D53),"") -> 0 | M11: =IFERROR(L11-N11,"") -> 0 | N11: =IFERROR(Main!Z57,"") -> 0 | O11: =IFERROR(COUNT(Main!V53),"") -> 0 | P11: =IFERROR(O11-Q11,"") -> 0 | Q11: =IFERROR(Main!AA57,"") -> 0 | R11: =IFERROR(L11+O11,"") -> 0 | S11: =IFERROR(M11+P11,"") -> 0 | T11: =IFERROR(N11+Q11,"") -> 0 | U11: =IFERROR(S11/R11,"") | V11: =IFERROR(T11/R11,"")
A12: =A11 -> 0 | B12: =Main!B54 -> 0 | D12: برك أكسدة | G12: =IFERROR(COUNT(Main!C54),"") -> 0 | H12: =IFERROR(G12-I12,"") -> 0 | I12: =IFERROR(Main!Y58,"") -> 0 | J12: =IFERROR(H12/G12,"") | K12: =IFERROR(I12/G12,"") | L12: =IFERROR(COUNT(Main!D54),"") -> 0 | M12: =IFERROR(L12-N12,"") -> 0 | N12: =IFERROR(Main!Z58,"") -> 0 | O12: =IFERROR(COUNT(Main!V54),"") -> 0 | P12: =IFERROR(O12-Q12,"") -> 0 | Q12: =IFERROR(Main!AA59,"") -> 0 | R12: =IFERROR(L12+O12,"") -> 0 | S12: =IFERROR(M12+P12,"") -> 0 | T12: =IFERROR(N12+Q12,"") -> 0 | U12: =IFERROR(S12/R12,"") | V12: =IFERROR(T12/R12,"")
A13: =A11 -> 0 | B13: =Main!B55 -> 0 | O13: =IFERROR(COUNT(Main!V55),"") -> 0 | P13: =IFERROR(O13-Q13,"") | Q13: =IFERROR(Main!Z54,"") | R13: =IFERROR(L13+O13,"") -> 0 | S13: =IFERROR(M13+P13,"") | T13: =IFERROR(N13+Q13,"") | U13: =IFERROR(S13/R13,"") | V13: =IFERROR(T13/R13,"")
A14: =A13 -> 0 | B14: =Main!B56 -> 0 | O14: =IFERROR(COUNT(Main!V56),"") -> 0 | P14: =IFERROR(O14-Q14,"") | Q14: =IFERROR(Main!Z55,"") | R14: =IFERROR(L14+O14,"") -> 0 | S14: =IFERROR(M14+P14,"") | T14: =IFERROR(N14+Q14,"") | U14: =IFERROR(S14/R14,"") | V14: =IFERROR(T14/R14,"")
C15: معايير قانون 48 لسنة 1982( قرار 92 لسنة 2013 مادة 52)
B17: TEMP | D17: pH | F17: S-- | H17: DO | I17: TDS | K17: TSS | M17: COD | O17: BOD | Q17: O&G | S17: R. Cl
B18: In | C18: Out | D18: In | E18: Out | F18: In | G18: Out | H18: Out | I18: In | J18: Out | K18: In | L18: Out | M18: In | N18: Out | O18: In | P18: Out | Q18: In | R18: Out | S18: Out
B19: 43 | C19: 15-35 | D19: 6 - 9.5 | E19: 6.5 - 9 | F19: 10 mg/l | G19: 1 mg/l | H19: 4mg/l | I19: 2000 mg/l | J19: 2000 mg/l | K19: 800 mg/l | L19: 50 mg/l | M19: 1100 mg/l | N19: 80 mg/l | O19: 600 mg/l | P19: 60 mg/l | Q19: 100 mg/l | R19: 10 mg/l | S19: 0.5mg/l
O21: Technical Responsible

Sheet الاحصائية (2)
A1: شركة الفيوم لمياه الشرب والصرف الصحى
A2: قطاع المعامل
A3: الادارة العامة لمعامل الصرف الصحي
A5: إحصائية بعدد عينات الدخول والسيب النهائى لمحطة معالجة طامية عن شهر | J5: =Main!Q10 -> 0 | K5: ='تقرير المواد الصلبة'!J10 -> 0
A7: التاريخ | B7: اسم المحطة | D7: نظام المعالجة | E7: الطاقة التصميمية | F7: الطاقة الفعلية | G7: أحواض التهوية | H7: مجمع التهوية | I7: RAS | J7: Thickenner | K7: الحمأة الجافة | L7: اجمالى العينات
E8: م3/ يوم | F8: م3/ يوم | J8: غير مطابق %
A9: =DATE(K5,J5+1,) -> 0 | B9: طامية | D9: كروجر | E9: 15000 | F9: 14500 | G9: =IFERROR(COUNTA(TSS[[column]:[column1]]),"")-(COUNTA(TSS[[column]:[column1]])-2*COUNTA(TSS[SV30])) -> 0 | H9: =COUNT(TSS[SV30]) -> 0 | I9: =COUNT(TSS[RAS]) -> 0 | J9: =COUNT(TSS[Thickner]) -> 0 | K9: =COUNT(TSS[Dry Sludge TS %]) -> 0 | L9: =IFERROR(SUM(G9:K9),"") -> 0
A10: =A9 -> 0 | B10: =Main!B52 -> 0 | D10: برك أكسدة | G10: =IFERROR(IF(Main!C52="","",2),"") | L10: =G10
A11: الاجمالى | L11: =SUM(L9:M10) -> 0
Q14: =11.71-1.61 -> 10.1
L17: Technical Responsible
D24: كتلة الحمأة بالمحطة كجم/ شهر
E26: الدخول | F26: السيب النهائى | G26: WASS | H26: ThickSS
E27: =IFERROR(Main!$N$47*(الاحصائية!$F$9*_xlfn.DAYS(IF(TODAY()>DATE(K5,J5,DAY(TODAY())),EOMONTH(A9,0),TODAY()),EOMONTH(A9,-1)))/1000,"") | F27: =IFERROR(Main!$O$47*(الاحصائية!$F$9*_xlfn.DAYS(IF(TODAY()>DATE(K5,J5,DAY(TODAY())),EOMONTH(A9,0),TODAY()),EOMONTH(A9,-1)))/1000,"") | G27: =IFERROR('تقرير المواد الصلبة'!$H$44*('تقرير المواد الصلبة'!$O$44)*_xlfn.DAYS(IF(TODAY()>DATE(K5,J5,DAY(TODAY())),EOMONTH(A9,0),TODAY()),EOMONTH(A9,-1))/1000,"") | H27: =IFERROR('تقرير المواد الصلبة'!$I$44*('تقرير المواد الصلبة'!$P$44)*_xlfn.DAYS(IF(TODAY()>DATE(K5,J5,DAY(TODAY())),EOMONTH(A9,0), TODAY()),EOMONTH(A9,-1))/1000,"")

Sheet تقرير المواد الصلبة
A10: نتائج مراحل المعالجه لمحطة معالجة صرف صحى طاميه بالفيوم لشهر
A11: م | B11: التاريخ | C11: DO | D11: SV30 | E11: MLSS | F11: SVI | G11: VSS | H11: RAS | I11: Thickner | J11: Dry Sludge TS % | K11: column | L11: column1 | O11: WASS | P11: ThickSS
A12: 1 | B12: =IFERROR(TEXT(DATE($J$10,$I$10,$A12),"dd/mm/yyyy"),"") | F12: =IFERROR(IF((TSS[[#This Row],[MLSS]])>0,TSS[[#This Row],[SV30]]*1000/TSS[[#This Row],[MLSS]],""),"") | K12: 1 | L12: 1
A13: 2 | B13: =IFERROR(TEXT(DATE($J$10,$I$10,$A13),"dd/mm/yyyy"),"") | F13: =IFERROR(IF((TSS[[#This Row],[MLSS]])>0,TSS[[#This Row],[SV30]]*1000/TSS[[#This Row],[MLSS]],""),"") | K13: 1 | L13: 1 | O13: 196.15135 | P13: 1440
A14: 3 | B14: =IFERROR(TEXT(DATE($J$10,$I$10,$A14),"dd/mm/yyyy"),"") | F14: =IFERROR(IF((TSS[[#This Row],[MLSS]])>0,TSS[[#This Row],[SV30]]*1000/TSS[[#This Row],[MLSS]],""),"") | K14: 1 | L14: 1 | O14: 196.15135 | P14: 1440
A15: 4 | B15: =IFERROR(TEXT(DATE($J$10,$I$10,$A15),"dd/mm/yyyy"),"") | F15: =IFERROR(IF((TSS[[#This Row],[MLSS]])>0,TSS[[#This Row],[SV30]]*1000/TSS[[#This Row],[MLSS]],""),"") | K15: 1 | L15: 1 | O15: 196.15135 | P15: 1440
A16: 5 | B16: =IFERROR(TEXT(DATE($J$10,$I$10,$A16),"dd/mm/yyyy"),"") | F16: =IFERROR(IF((TSS[[#This Row],[MLSS]])>0,TSS[[#This Row],[SV30]]*1000/TSS[[#This Row],[MLSS]],""),"") | K16: 1 | L16: 1 | O16: 196.15135 | P16: 2160
A17: 6 | B17: =IFERROR(TEXT(DATE($J$10,$I$10,$A17),"dd/mm/yyyy"),"") | F17: =IFERROR(IF((TSS[[#This Row],[MLSS]])>0,TSS[[#This Row],[SV30]]*1000/TSS[[#This Row],[MLSS]],""),"") | K17: 1 | L17: 1 | O17: 196.15135 | P17: 1440
A18: 7 | B18: =IFERROR(TEXT(DATE($J$10,$I$10,$A18),"dd/mm/yyyy"),"") | F18: =IFERROR(IF((TSS[[#This Row],[MLSS]])>0,TSS[[#This Row],[SV30]]*1000/TSS[[#This Row],[MLSS]],""),"") | K18: 1 | L18: 1 | O18: 196.15135 | P18: 1440
A19: 8 | B19: =IFERROR(TEXT(DATE($J$10,$I$10,$A19),"dd/mm/yyyy"),"") | F19: =IFERROR(IF((TSS[[#This Row],[MLSS]])>0,TSS[[#This Row],[SV30]]*1000/TSS[[#This Row],[MLSS]],""),"") | O19: 196.15135
A20: 9 | B20: =IFERROR(TEXT(DATE($J$10,$I$10,$A20),"dd/mm/yyyy"),"") | F20: =IFERROR(IF((TSS[[#This Row],[MLSS]])>0,TSS[[#This Row],[SV30]]*1000/TSS[[#This Row],[MLSS]],""),"") | K20: 1 | L20: 1 | O20: 196.15135 | P20: 55.741935
A21: 10 | B21: =IFERROR(TEXT(DATE($J$10,$I$10,$A21),"dd/mm/yyyy"),"") | F21: =IFERROR(IF((TSS[[#This Row],[MLSS]])>0,TSS[[#This Row],[SV30]]*1000/TSS[[#This Row],[MLSS]],""),"") | K21: 1 | L21: 1 | O21: 196.15135 | P21: 55.741935
A22: 11 | B22: =IFERROR(TEXT(DATE($J$10,$I$10,$A22),"dd/mm/yyyy"),"") | F22: =IFERROR(IF((TSS[[#This Row],[MLSS]])>0,TSS[[#This Row],[SV30]]*1000/TSS[[#This Row],[MLSS]],""),"") | K22: 1 | L22: 1 | O22: 196.15135 | P22: 55.741935
A23: 12 | B23: =IFERROR(TEXT(DATE($J$10,$I$10,$A23),"dd/mm/yyyy"),"") | F23: =IFERROR(IF((TSS[[#This Row],[MLSS]])>0,TSS[[#This Row],[SV30]]*1000/TSS[[#This Row],[MLSS]],""),"") | K23: 1 | L23: 1 | O23: 196.15135 | P23: 55.741935
A24: 13 | B24: =IFERROR(TEXT(DATE($J$10,$I$10,$A24),"dd/mm/yyyy"),"") | F24: =IFERROR(IF((TSS[[#This Row],[MLSS]])>0,TSS[[#This Row],[SV30]]*1000/TSS[[#This Row],[MLSS]],""),"") | K24: 1 | L24: 1 | O24: 196.15135 | P24: 55.741935
A25: 14 | B25: =IFERROR(TEXT(DATE($J$10,$I$10,$A25),"dd/mm/yyyy"),"") | F25: =IFERROR(IF((TSS[[#This Row],[MLSS]])>0,TSS[[#This Row],[SV30]]*1000/TSS[[#This Row],[MLSS]],""),"") | K25: 1 | L25: 1 | O25: 196.15135 | P25: 55.741935
A26: 15 | B26: =IFERROR(TEXT(DATE($J$10,$I$10,$A26),"dd/mm/yyyy"),"") | F26: =IFERROR(IF((TSS[[#This Row],[MLSS]])>0,TSS[[#This Row],[SV30]]*1000/TSS[[#This Row],[MLSS]],""),"") | K26: 1 | L26: 1
A27: 16 | B27: =IFERROR(TEXT(DATE($J$10,$I$10,$A27),"dd/mm/yyyy"),"") | F27: =IFERROR(IF((TSS[[#This Row],[MLSS]])>0,TSS[[#This Row],[SV30]]*1000/TSS[[#This Row],[MLSS]],""),"") | K27: 1 | L27: 1 | O27: 196.15135 | P27: 55.741935
A28: 17 | B28: =IFERROR(TEXT(DATE($J$10,$I$10,$A28),"dd/mm/yyyy"),"") | F28: =IFERROR(IF((TSS[[#This Row],[MLSS]])>0,TSS[[#This Row],[SV30]]*1000/TSS[[#This Row],[MLSS]],""),"") | K28: 1 | L28: 1
A29: 18 | B29: =IFERROR(TEXT(DATE($J$10,$I$10,$A29),"dd/mm/yyyy"),"") | F29: =IFERROR(IF((TSS[[#This Row],[MLSS]])>0,TSS[[#This Row],[SV30]]*1000/TSS[[#This Row],[MLSS]],""),"") | K29: 1 | L29: 1 | O29: 196.15135 | P29: 1440
A30: 19 | B30: =IFERROR(TEXT(DATE($J$10,$I$10,$A30),"dd/mm/yyyy"),"") | F30: =IFERROR(IF((TSS[[#This Row],[MLSS]])>0,TSS[[#This Row],[SV30]]*1000/TSS[[#This Row],[MLSS]],""),"") | K30: 1 | L30: 1 | O30: 196.15135 | P30: 1440
A31: 20 | B31: =IFERROR(TEXT(DATE($J$10,$I$10,$A31),"dd/mm/yyyy"),"") | F31: =IFERROR(IF((TSS[[#This Row],[MLSS]])>0,TSS[[#This Row],[SV30]]*1000/TSS[[#This Row],[MLSS]],""),"") | K31: 1 | L31: 1 | O31: 196.15135 | P31: 1440
A32: 21 | B32: =IFERROR(TEXT(DATE($J$10,$I$10,$A32),"dd/mm/yyyy"),"") | F32: =IFERROR(IF((TSS[[#This Row],[MLSS]])>0,TSS[[#This Row],[SV30]]*1000/TSS[[#This Row],[MLSS]],""),"") | K32: 1 | L32: 1 | O32: 196.15135 | P32: 1440
A33: 22 | B33: =IFERROR(TEXT(DATE($J$10,$I$10,$A33),"dd/mm/yyyy"),"") | F33: =IFERROR(IF((TSS[[#This Row],[MLSS]])>0,TSS[[#This Row],[SV30]]*1000/TSS[[#This Row],[MLSS]],""),"") | K33: 1 | L33: 1
A34: 23 | B34: =IFERROR(TEXT(DATE($J$10,$I$10,$A34),"dd/mm/yyyy"),"") | F34: =IFERROR(IF((TSS[[#This Row],[MLSS]])>0,TSS[[#This Row],[SV30]]*1000/TSS[[#This Row],[MLSS]],""),"") | K34: 1 | L34: 1
A35: 24 | B35: =IFERROR(TEXT(DATE($J$10,$I$10,$A35),"dd/mm/yyyy"),"") | F35: =IFERROR(IF((TSS[[#This Row],[MLSS]])>0,TSS[[#This Row],[SV30]]*1000/TSS[[#This Row],[MLSS]],""),"") | K35: 1 | L35: 1 | O35: 196.15135 | P35: 1440
A36: 25 | B36: =IFERROR(TEXT(DATE($J$10,$I$10,$A36),"dd/mm/yyyy"),"") | F36: =IFERROR(IF((TSS[[#This Row],[MLSS]])>0,TSS[[#This Row],[SV30]]*1000/TSS[[#This Row],[MLSS]],""),"") | K36: 1 | L36: 1
A37: 26 | B37: =IFERROR(TEXT(DATE($J$10,$I$10,$A37),"dd/mm/yyyy"),"") | F37: =IFERROR(IF((TSS[[#This Row],[MLSS]])>0,TSS[[#This Row],[SV30]]*1000/TSS[[#This Row],[MLSS]],""),"") | K37: 1 | L37: 1
A38: 27 | B38: =IFERROR(TEXT(DATE($J$10,$I$10,$A38),"dd/mm/yyyy"),"") | F38: =IFERROR(IF((TSS[[#This Row],[MLSS]])>0,TSS[[#This Row],[SV30]]*1000/TSS[[#This Row],[MLSS]],""),"") | K38: 1 | L38: 1
A39: 28 | B39: =IFERROR(TEXT(DATE($J$10,$I$10,$A39),"dd/mm/yyyy"),"") | F39: =IFERROR(IF((TSS[[#This Row],[MLSS]])>0,TSS[[#This Row],[SV30]]*1000/TSS[[#This Row],[MLSS]],""),"") | K39: 1 | L39: 1
A40: 29 | B40: =IFERROR(TEXT(DATE($J$10,$I$10,$A40),"dd/mm/yyyy"),"") | F40: =IFERROR(IF((TSS[[#This Row],[MLSS]])>0,TSS[[#This Row],[SV30]]*1000/TSS[[#This Row],[MLSS]],""),"") | K40: 1 | L40: 1
A41: 30 | B41: =IFERROR(TEXT(DATE($J$10,$I$10,$A41),"dd/mm/yyyy"),"") | F41: =IFERROR(IF((TSS[[#This Row],[MLSS]])>0,TSS[[#This Row],[SV30]]*1000/TSS[[#This Row],[MLSS]],""),"") | K41: 1 | L41: 1
B42: MIN | C42: =IFERROR(SUBTOTAL(105,TSS[DO]),"") -> 0 | D42: =IFERROR(SUBTOTAL(105,TSS[SV30]),"") -> 0 | E42: =IFERROR(SUBTOTAL(105,TSS[MLSS]),"") -> 0 | F42: =IFERROR(SUBTOTAL(105,TSS[SVI]),"") -> 0 | G42: =IFERROR(SUBTOTAL(105,TSS[VSS]),"") -> 0 | H42: =IFERROR(SUBTOTAL(105,TSS[RAS]),"") -> 0 | I42: =IFERROR(SUBTOTAL(105,TSS[Thickner]),"") -> 0 | J42: =IFERROR(SUBTOTAL(105,TSS[Dry Sludge TS %]),"") -> 0
B43: MAX | C43: =IFERROR(SUBTOTAL(104,C12:C41),"") -> 0 | D43: =IFERROR(SUBTOTAL(104,D12:D41),"") -> 0 | E43: =IFERROR(SUBTOTAL(104,E12:E41),"") -> 0 | F43: =IFERROR(SUBTOTAL(104,F12:F41),"") -> 0 | G43: =IFERROR(SUBTOTAL(104,G12:G41),"") -> 0 | H43: =IFERROR(SUBTOTAL(104,H12:H41),"") -> 0 | I43: =IFERROR(SUBTOTAL(104,I12:I41),"") -> 0 | J43: =IFERROR(SUBTOTAL(104,J12:J41),"") -> 0
B44: Average | C44: =IFERROR(SUBTOTAL(101,C12:C41),"") | D44: =IFERROR(SUBTOTAL(101,D12:D41),"") | E44: =IFERROR(SUBTOTAL(101,E12:E41),"") | F44: =IFERROR(SUBTOTAL(101,F12:F41),"") | G44: =IFERROR(SUBTOTAL(101,G12:G41),"") | H44: =IFERROR(SUBTOTAL(101,H12:H41),"") | I44: =IFERROR(SUBTOTAL(101,I12:I41),"") | J44: =IFERROR(SUBTOTAL(101,J12:J41),"") | O44: =IFERROR(SUBTOTAL(101,O12:O41),"") -> 196.15135 | P44: =IFERROR(SUBTOTAL(101,P12:P41),"") -> 941.67742
H46: Responsible | I46: Technical
